Workbook

Sheet Case
A1: FRCM-Raft (South Korea)
A2: Feed | B2: 2604.7141
A3: Energy | B3: 6882.9123
A4: Infrastructure | B4: 1215.0178
A5: Equipment | B5: 0.075840311
A6: Transport | B6: 418.73569
A8: CF (no seaweed) | B8: =SUM(B2:B7) -> 11121.456
B10: CF | C10: Input
A11: 电力 | B11: =B3 -> 6882.9123 | C11: =B11/'Elec str'!G3 -> 6972.6281
A12: 除电力外 | B12: =B8-B11 -> 4238.5434
A13: 基建 | B13: =B4 -> 1215.0178
A14: 除基建外 | B14: =B8-B13 -> 9906.4379
A15: 除电力+基建外 | B15: =B8-B11-B13 -> 3023.5256
A17: 饲料 | B17: =B2 -> 2604.7141
A18: 除饲料外 | B18: =B8-B17 -> 8516.7415
A19: 除饲料+电力+基建外 | B19: =B8-B2-B4-B3 -> 418.81153

Sheet Temperature
B1: 皱纹盘鲍 | I1: 新增冷却用电量 | K1: 新增冷却用电碳足迹（不考虑电力结构） | L1: 新增冷却用电碳足迹（考虑电力结构）
A2: 2020 | B2: 1 | D2: =(B32-B2)/($A$32-$A$2) -> -0.0033333333 | F2: 维持时间 | H2: 2020 | I2: 0 | J2: =(I32-I2)/(H32-H2) -> 159.04762 | K2: =I2*'Elec str'!$G$3 -> 0 | L2: =I2*'Elec str'!G3 -> 0
A3: 2021 | B3: =B2+D$2 -> 0.99666667 | F3: day | G3: hour | H3: 2021 | I3: =I2+$J$2 -> 159.04762 | K3: =I3*'Elec str'!$G$3 -> 157.00118 | L3: =I3*'Elec str'!G4 -> 155.21635
A4: 2022 | B4: =B3+D$2 -> 0.99333333 | F4: 100 | G4: 2400 | H4: 2022 | I4: =I3+$J$2 -> 318.09524 | K4: =I4*'Elec str'!$G$3 -> 314.00235 | L4: =I4*'Elec str'!G5 -> 306.86307
A5: 2023 | B5: =B4+D$2 -> 0.99 | H5: 2023 | I5: =I4+$J$2 -> 477.14286 | K5: =I5*'Elec str'!$G$3 -> 471.00353 | L5: =I5*'Elec str'!G6 -> 454.94014
A6: 2024 | B6: =B5+D$2 -> 0.98666667 | E6: kwh | H6: 2024 | I6: =I5+$J$2 -> 636.19048 | K6: =I6*'Elec str'!$G$3 -> 628.0047 | L6: =I6*'Elec str'!G7 -> 599.44757
A7: 2025 | B7: =B6+D$2 -> 0.98333333 | E7: 功率 | F7: 制冷机 | G7: 空调 | H7: 2025 | I7: =I6+$J$2 -> 795.2381 | K7: =I7*'Elec str'!$G$3 -> 785.00588 | L7: =I7*'Elec str'!G8 -> 740.38535
A8: 2026 | B8: =B7+D$2 -> 0.98 | E8: 原来 | F8: 2.25 | G8: 3.75 | H8: 2026 | I8: =I7+$J$2 -> 954.28571 | K8: =I8*'Elec str'!$G$3 -> 942.00705 | L8: =I8*'Elec str'!G9 -> 877.7535
A9: 2027 | B9: =B8+D$2 -> 0.97666667 | E9: 增加值 | F9: 0.045 | G9: 0.7 | H9: 2027 | I9: =I8+$J$2 -> 1113.3333 | K9: =I9*'Elec str'!$G$3 -> 1099.0082 | L9: =I9*'Elec str'!G10 -> 1011.552
A10: 2028 | B10: =B9+D$2 -> 0.97333333 | H10: 2028 | I10: =I9+$J$2 -> 1272.381 | K10: =I10*'Elec str'!$G$3 -> 1256.0094 | L10: =I10*'Elec str'!G11 -> 1141.7809
A11: 2029 | B11: =B10+D$2 -> 0.97 | E11: 一个房间 | F11: 池子数 | G11: 3 | H11: 2029 | I11: =I10+$J$2 -> 1431.4286 | K11: =I11*'Elec str'!$G$3 -> 1413.0106 | L11: =I11*'Elec str'!G12 -> 1268.4401
A12: 2030 | B12: =B11+D$2 -> 0.96666667 | F12: 空调数 | G12: 1 | H12: 2030 | I12: =I11+$J$2 -> 1590.4762 | K12: =I12*'Elec str'!$G$3 -> 1570.0118 | L12: =I12*'Elec str'!G13 -> 1391.5297
A13: 2031 | B13: =B12+D$2 -> 0.96333333 | H13: 2031 | I13: =I12+$J$2 -> 1749.5238 | K13: =I13*'Elec str'!$G$3 -> 1727.0129 | L13: =I13*'Elec str'!G14 -> 1499.1414
A14: 2032 | B14: =B13+D$2 -> 0.96 | E14: 每小时总增加值 | F14: =3*F9+G12*G9 -> 0.835 | H14: 2032 | I14: =I13+$J$2 -> 1908.5714 | K14: =I14*'Elec str'!$G$3 -> 1884.0141 | L14: =I14*'Elec str'!G15 -> 1601.0184
A15: 2033 | B15: =B14+D$2 -> 0.95666667 | H15: 2033 | I15: =I14+$J$2 -> 2067.619 | K15: =I15*'Elec str'!$G$3 -> 2041.0153 | L15: =I15*'Elec str'!G16 -> 1697.1606
A16: 2034 | B16: =B15+D$2 -> 0.95333333 | H16: 2034 | I16: =I15+$J$2 -> 2226.6667 | K16: =I16*'Elec str'!$G$3 -> 2198.0165 | L16: =I16*'Elec str'!G17 -> 1787.568
A17: 2035 | B17: =B16+D$2 -> 0.95 | E17: 养殖周期总增加值 | F17: =F14*G4 -> 2004 | H17: 2035 | I17: =I16+$J$2 -> 2385.7143 | K17: =I17*'Elec str'!$G$3 -> 2355.0176 | L17: =I17*'Elec str'!G18 -> 1872.2407
A18: 2036 | B18: =B17+D$2 -> 0.94666667 | E18: 产量（吨） | F18: 0.42 | H18: 2036 | I18: =I17+$J$2 -> 2544.7619 | K18: =I18*'Elec str'!$G$3 -> 2512.0188 | L18: =I18*'Elec str'!G19 -> 1951.1786
A19: 2037 | B19: =B18+D$2 -> 0.94333333 | E19: 折算到每吨 | F19: =F17/F18 -> 4771.4286 | H19: 2037 | I19: =I18+$J$2 -> 2703.8095 | K19: =I19*'Elec str'!$G$3 -> 2669.02 | L19: =I19*'Elec str'!G20 -> 2024.3817
A20: 2038 | B20: =B19+D$2 -> 0.94 | H20: 2038 | I20: =I19+$J$2 -> 2862.8571 | K20: =I20*'Elec str'!$G$3 -> 2826.0212 | L20: =I20*'Elec str'!G21 -> 2091.8501
A21: 2039 | B21: =B20+D$2 -> 0.93666667 | H21: 2039 | I21: =I20+$J$2 -> 3021.9048 | K21: =I21*'Elec str'!$G$3 -> 2983.0223 | L21: =I21*'Elec str'!G22 -> 2153.5837
A22: 2040 | B22: =B21+D$2 -> 0.93333333 | H22: 2040 | I22: =I21+$J$2 -> 3180.9524 | K22: =I22*'Elec str'!$G$3 -> 3140.0235 | L22: =I22*'Elec str'!G23 -> 2209.5825
A23: 2041 | B23: =B22+D$2 -> 0.93 | H23: 2041 | I23: =I22+$J$2 -> 3340 | K23: =I23*'Elec str'!$G$3 -> 3297.0247 | L23: =I23*'Elec str'!G24 -> 2228.5606
A24: 2042 | B24: =B23+D$2 -> 0.92666667 | H24: 2042 | I24: =I23+$J$2 -> 3499.0476 | K24: =I24*'Elec str'!$G$3 -> 3454.0259 | L24: =I24*'Elec str'!G25 -> 2238.8244
A25: 2043 | B25: =B24+D$2 -> 0.92333333 | H25: 2043 | I25: =I24+$J$2 -> 3658.0952 | K25: =I25*'Elec str'!$G$3 -> 3611.027 | L25: =I25*'Elec str'!G26 -> 2240.3738
A26: 2044 | B26: =B25+D$2 -> 0.92 | H26: 2044 | I26: =I25+$J$2 -> 3817.1429 | K26: =I26*'Elec str'!$G$3 -> 3768.0282 | L26: =I26*'Elec str'!G27 -> 2233.2088
A27: 2045 | B27: =B26+D$2 -> 0.91666667 | H27: 2045 | I27: =I26+$J$2 -> 3976.1905 | K27: =I27*'Elec str'!$G$3 -> 3925.0294 | L27: =I27*'Elec str'!G28 -> 2217.3295
A28: 2046 | B28: =B27+D$2 -> 0.91333333 | H28: 2046 | I28: =I27+$J$2 -> 4135.2381 | K28: =I28*'Elec str'!$G$3 -> 4082.0306 | L28: =I28*'Elec str'!G29 -> 2192.7357
A29: 2047 | B29: =B28+D$2 -> 0.91 | H29: 2047 | I29: =I28+$J$2 -> 4294.2857 | K29: =I29*'Elec str'!$G$3 -> 4239.0317 | L29: =I29*'Elec str'!G30 -> 2159.4276
A30: 2048 | B30: =B29+D$2 -> 0.90666667 | H30: 2048 | I30: =I29+$J$2 -> 4453.3333 | K30: =I30*'Elec str'!$G$3 -> 4396.0329 | L30: =I30*'Elec str'!G31 -> 2117.4051
A31: 2049 | B31: =B30+D$2 -> 0.90333333 | H31: 2049 | I31: =I30+$J$2 -> 4612.381 | K31: =I31*'Elec str'!$G$3 -> 4553.0341 | L31: =I31*'Elec str'!G32 -> 2066.6682
A32: 2050 | B32: 0.9 | H32: 2050 | I32: =F19 -> 4771.4286 | K32: =I32*'Elec str'!$G$3 -> 4710.0353 | L32: =I32*'Elec str'!G33 -> 2007.217

Sheet Baseline
A1: 加温度 | B1: 1t鲍鱼碳足迹
B2: mean | C2: max | D2: min
A3: 2020 | B3: =Case!$B$8/Temperature!B2 -> 11121.456
A4: 2021 | B4: =Case!$B$8/Temperature!B3 -> 11158.651
A5: 2022 | B5: =Case!$B$8/Temperature!B4 -> 11196.096
A6: 2023 | B6: =Case!$B$8/Temperature!B5 -> 11233.794
A7: 2024 | B7: =Case!$B$8/Temperature!B6 -> 11271.746
A8: 2025 | B8: =Case!$B$8/Temperature!B7 -> 11309.955
A9: 2026 | B9: =Case!$B$8/Temperature!B8 -> 11348.424
A10: 2027 | B10: =Case!$B$8/Temperature!B9 -> 11387.156
A11: 2028 | B11: =Case!$B$8/Temperature!B10 -> 11426.153
A12: 2029 | B12: =Case!$B$8/Temperature!B11 -> 11465.418
A13: 2030 | B13: =Case!$B$8/Temperature!B12 -> 11504.954
A14: 2031 | B14: =Case!$B$8/Temperature!B13 -> 11544.764
... A33: 2050 | B33: =Case!$B$8/Temperature!B32 -> 12357.173

Sheet Elec str
B1: 0.00676 | C1: 0.09391 | D1: 0.02915 | E1: 1.11547 | F1: 0.37599
B2: 核能 | C2: 光伏 | D2: 风力 | E2: 煤电 | F2: 燃气 | G2: 1kwh排放
A3: 2020 | B3: =T45 -> 0.056044924 | C3: =U45 -> 0.019489099 | D3: =V45 -> 0.04261176 | E3: =W45 -> 0.88185422 | F3: =X45 -> 0 | G3: =B3*$B$1+C3*$C$1+D3*$D$1+E3*$E$1+F3*$F$1 -> 0.98713314 | H3: 核电 | I3: 光伏 | J3: 风电 | K3: 煤电 | L3: 燃气
A4: 2021 | B4: =B3+H$4 -> 0.055005577 | C4: =C3+I$4 -> 0.022616275 | D4: =D3+J$4 -> 0.0488693 | E4: =E3+K$4 -> 0.8702877 | F4: =F3+L$4 -> 0.0032211485 | G4: =B4*$B$1+C4*$C$1+D4*$D$1+E4*$E$1+F4*$F$1 -> 0.97591121 | H4: =(B13-B3)/($A$13-$A$3) -> -0.0010393475 | I4: =(C13-C3)/($A$13-$A$3) -> 0.0031271758 | J4: =(D13-D3)/($A$13-$A$3) -> 0.00625754 | K4: =(E13-E3)/($A$13-$A$3) -> -0.011566517 | L4: =(F13-F3)/($A$13-$A$3) -> 0.0032211485
A5: 2022 | B5: =B4+H$4 -> 0.053966229 | C5: =C4+I$4 -> 0.025743451 | D5: =D4+J$4 -> 0.05512684 | E5: =E4+K$4 -> 0.85872118 | F5: =F4+L$4 -> 0.006442297 | G5: =B5*$B$1+C5*$C$1+D5*$D$1+E5*$E$1+F5*$F$1 -> 0.96468928
A6: 2023 | B6: =B5+H$4 -> 0.052926882 | C6: =C5+I$4 -> 0.028870627 | D6: =D5+J$4 -> 0.06138438 | E6: =E5+K$4 -> 0.84715467 | F6: =F5+L$4 -> 0.0096634455 | G6: =B6*$B$1+C6*$C$1+D6*$D$1+E6*$E$1+F6*$F$1 -> 0.95346736
A7: 2024 | B7: =B6+H$4 -> 0.051887534 | C7: =C6+I$4 -> 0.031997803 | D7: =D6+J$4 -> 0.06764192 | E7: =E6+K$4 -> 0.83558815 | F7: =F6+L$4 -> 0.012884594 | G7: =B7*$B$1+C7*$C$1+D7*$D$1+E7*$E$1+F7*$F$1 -> 0.94224543
A8: 2025 | B8: =B7+H$4 -> 0.050848187 | C8: =C7+I$4 -> 0.035124978 | D8: =D7+J$4 -> 0.07389946 | E8: =E7+K$4 -> 0.82402163 | F8: =F7+L$4 -> 0.016105743 | G8: =B8*$B$1+C8*$C$1+D8*$D$1+E8*$E$1+F8*$F$1 -> 0.9310235
A9: 2026 | B9: =B8+H$4 -> 0.049808839 | C9: =C8+I$4 -> 0.038252154 | D9: =D8+J$4 -> 0.080157 | E9: =E8+K$4 -> 0.81245512 | F9: =F8+L$4 -> 0.019326891 | G9: =B9*$B$1+C9*$C$1+D9*$D$1+E9*$E$1+F9*$F$1 -> 0.91980157
A10: 2027 | B10: =B9+H$4 -> 0.048769492 | C10: =C9+I$4 -> 0.04137933 | D10: =D9+J$4 -> 0.08641454 | E10: =E9+K$4 -> 0.8008886 | F10: =F9+L$4 -> 0.02254804 | G10: =B10*$B$1+C10*$C$1+D10*$D$1+E10*$E$1+F10*$F$1 -> 0.90857964
A11: 2028 | B11: =B10+H$4 -> 0.047730144 | C11: =C10+I$4 -> 0.044506506 | D11: =D10+J$4 -> 0.09267208 | E11: =E10+K$4 -> 0.78932208 | F11: =F10+L$4 -> 0.025769188 | G11: =B11*$B$1+C11*$C$1+D11*$D$1+E11*$E$1+F11*$F$1 -> 0.89735771
A12: 2029 | B12: =B11+H$4 -> 0.046690797 | C12: =C11+I$4 -> 0.047633682 | D12: =D11+J$4 -> 0.09892962 | E12: =E11+K$4 -> 0.77775556 | F12: =F11+L$4 -> 0.028990337 | G12: =B12*$B$1+C12*$C$1+D12*$D$1+E12*$E$1+F12*$F$1 -> 0.88613578
A13: 2030 | B13: =T46 -> 0.04565145 | C13: =U46 -> 0.050760857 | D13: =V46 -> 0.10518716 | E13: =W46 -> 0.76618905 | F13: =X46 -> 0.032211485 | G13: =B13*$B$1+C13*$C$1+D13*$D$1+E13*$E$1+F13*$F$1 -> 0.87491386
A14: 2031 | B14: =B13+H$14 -> 0.049703561 | C14: =C13+I$14 -> 0.052576365 | D14: =D13+J$14 -> 0.10785428 | E14: =E13+K$14 -> 0.7457759 | F14: =F13+L$14 -> 0.044089894 | G14: =B14*$B$1+C14*$C$1+D14*$D$1+E14*$E$1+F14*$F$1 -> 0.85688539 | H14: =(B23-B13)/($A$23-$A$13) -> 0.0040521117 | I14: =(C23-C13)/($A$23-$A$13) -> 0.0018155072 | J14: =(D23-D13)/($A$23-$A$13) -> 0.0026671247 | K14: =(E23-E13)/($A$23-$A$13) -> -0.020413153 | L14: =(F23-F13)/($A$23-$A$13) -> 0.011878409
A15: 2032 | B15: =B14+H$14 -> 0.053755673 | C15: =C14+I$14 -> 0.054391872 | D15: =D14+J$14 -> 0.11052141 | E15: =E14+K$14 -> 0.72536274 | F15: =F14+L$14 -> 0.055968303 | G15: =B15*$B$1+C15*$C$1+D15*$D$1+E15*$E$1+F15*$F$1 -> 0.83885693
A16: 2033 | B16: =B15+H$14 -> 0.057807785 | C16: =C15+I$14 -> 0.056207379 | D16: =D15+J$14 -> 0.11318853 | E16: =E15+K$14 -> 0.70494959 | F16: =F15+L$14 -> 0.067846712 | G16: =B16*$B$1+C16*$C$1+D16*$D$1+E16*$E$1+F16*$F$1 -> 0.82082847
A17: 2034 | B17: =B16+H$14 -> 0.061859896 | C17: =C16+I$14 -> 0.058022886 | D17: =D16+J$14 -> 0.11585566 | E17: =E16+K$14 -> 0.68453644 | F17: =F16+L$14 -> 0.079725121 | G17: =B17*$B$1+C17*$C$1+D17*$D$1+E17*$E$1+F17*$F$1 -> 0.8028
A18: 2035 | B18: =B17+H$14 -> 0.065912008 | C18: =C17+I$14 -> 0.059838393 | D18: =D17+J$14 -> 0.11852278 | E18: =E17+K$14 -> 0.66412329 | F18: =F17+L$14 -> 0.09160353 | G18: =B18*$B$1+C18*$C$1+D18*$D$1+E18*$E$1+F18*$F$1 -> 0.78477154
A19: 2036 | B19: =B18+H$14 -> 0.06996412 | C19: =C18+I$14 -> 0.061653901 | D19: =D18+J$14 -> 0.12118991 | E19: =E18+K$14 -> 0.64371013 | F19: =F18+L$14 -> 0.10348194 | G19: =B19*$B$1+C19*$C$1+D19*$D$1+E19*$E$1+F19*$F$1 -> 0.76674308
A20: 2037 | B20: =B19+H$14 -> 0.074016231 | C20: =C19+I$14 -> 0.063469408 | D20: =D19+J$14 -> 0.12385703 | E20: =E19+K$14 -> 0.62329698 | F20: =F19+L$14 -> 0.11536035 | G20: =B20*$B$1+C20*$C$1+D20*$D$1+E20*$E$1+F20*$F$1 -> 0.74871461
A21: 2038 | B21: =B20+H$14 -> 0.078068343 | C21: =C20+I$14 -> 0.065284915 | D21: =D20+J$14 -> 0.12652416 | E21: =E20+K$14 -> 0.60288383 | F21: =F20+L$14 -> 0.12723876 | G21: =B21*$B$1+C21*$C$1+D21*$D$1+E21*$E$1+F21*$F$1 -> 0.73068615
A22: 2039 | B22: =B21+H$14 -> 0.082120455 | C22: =C21+I$14 -> 0.067100422 | D22: =D21+J$14 -> 0.12919128 | E22: =E21+K$14 -> 0.58247067 | F22: =F21+L$14 -> 0.13911717 | G22: =B22*$B$1+C22*$C$1+D22*$D$1+E22*$E$1+F22*$F$1 -> 0.71265769
A23: 2040 | B23: =T47 -> 0.086172566 | C23: =U47 -> 0.068915929 | D23: =V47 -> 0.13185841 | E23: =W47 -> 0.56205752 | F23: =X47 -> 0.15099558 | G23: =B23*$B$1+C23*$C$1+D23*$D$1+E23*$E$1+F23*$F$1 -> 0.69462922
A24: 2041 | B24: =B23+H$24 -> 0.10975143 | C24: =C23+I$24 -> 0.069051479 | D24: =D23+J$24 -> 0.13808036 | E24: =E23+K$24 -> 0.53975371 | F24: =F23+L$24 -> 0.14336303 | G24: =B24*$B$1+C24*$C$1+D24*$D$1+E24*$E$1+F24*$F$1 -> 0.66723372 | H24: =(B33-B23)/($A$33-$A$23) -> 0.02357886 | I24: =(C33-C23)/($A$33-$A$23) -> 0.00013555009 | J24: =(D33-D23)/($A$33-$A$23) -> 0.0062219482 | K24: =(E33-E23)/($A$33-$A$23) -> -0.02230381 | L24: =(F33-F23)/($A$33-$A$23) -> -0.0076325475
A25: 2042 | B25: =B24+H$24 -> 0.13333029 | C25: =C24+I$24 -> 0.069187029 | D25: =D24+J$24 -> 0.1443023 | E25: =E24+K$24 -> 0.5174499 | F25: =F24+L$24 -> 0.13573048 | G25: =B25*$B$1+C25*$C$1+D25*$D$1+E25*$E$1+F25*$F$1 -> 0.63983822
A26: 2043 | B26: =B25+H$24 -> 0.15690915 | C26: =C25+I$24 -> 0.069322579 | D26: =D25+J$24 -> 0.15052425 | E26: =E25+K$24 -> 0.49514609 | F26: =F25+L$24 -> 0.12809793 | G26: =B26*$B$1+C26*$C$1+D26*$D$1+E26*$E$1+F26*$F$1 -> 0.61244272
A27: 2044 | B27: =B26+H$24 -> 0.18048801 | C27: =C26+I$24 -> 0.06945813 | D27: =D26+J$24 -> 0.1567462 | E27: =E26+K$24 -> 0.47284228 | F27: =F26+L$24 -> 0.12046539 | G27: =B27*$B$1+C27*$C$1+D27*$D$1+E27*$E$1+F27*$F$1 -> 0.58504722
A28: 2045 | B28: =B27+H$24 -> 0.20406686 | C28: =C27+I$24 -> 0.06959368 | D28: =D27+J$24 -> 0.16296815 | E28: =E27+K$24 -> 0.45053847 | F28: =F27+L$24 -> 0.11283284 | G28: =B28*$B$1+C28*$C$1+D28*$D$1+E28*$E$1+F28*$F$1 -> 0.55765172
A29: 2046 | B29: =B28+H$24 -> 0.22764572 | C29: =C28+I$24 -> 0.06972923 | D29: =D28+J$24 -> 0.1691901 | E29: =E28+K$24 -> 0.42823466 | F29: =F28+L$24 -> 0.10520029 | G29: =B29*$B$1+C29*$C$1+D29*$D$1+E29*$E$1+F29*$F$1 -> 0.53025622
A30: 2047 | B30: =B29+H$24 -> 0.25122458 | C30: =C29+I$24 -> 0.06986478 | D30: =D29+J$24 -> 0.17541204 | E30: =E29+K$24 -> 0.40593085 | F30: =F29+L$24 -> 0.097567742 | G30: =B30*$B$1+C30*$C$1+D30*$D$1+E30*$E$1+F30*$F$1 -> 0.50286072
A31: 2048 | B31: =B30+H$24 -> 0.27480344 | C31: =C30+I$24 -> 0.07000033 | D31: =D30+J$24 -> 0.18163399 | E31: =E30+K$24 -> 0.38362704 | F31: =F30+L$24 -> 0.089935195 | G31: =B31*$B$1+C31*$C$1+D31*$D$1+E31*$E$1+F31*$F$1 -> 0.47546522 | I31: 来自：https://cer.org.za/wp-content/uploads/2006/08/IRP-assumptions-base-case-results-and-observations-october-2016_20161125-GGN-40445-01431.pdf
A32: 2049 | B32: =B31+H$24 -> 0.2983823 | C32: =C31+I$24 -> 0.07013588 | D32: =D31+J$24 -> 0.18785594 | E32: =E31+K$24 -> 0.36132323 | F32: =F31+L$24 -> 0.082302647 | G32: =B32*$B$1+C32*$C$1+D32*$D$1+E32*$E$1+F32*$F$1 -> 0.44806972
A33: 2050 | B33: =T48 -> 0.32196116 | C33: =U48 -> 0.07027143 | D33: =V48 -> 0.19407789 | E33: =W48 -> 0.33901942 | F33: =X48 -> 0.0746701 | G33: =B33*$B$1+C33*$C$1+D33*$D$1+E33*$E$1+F33*$F$1 -> 0.42067422
J34: 年份 | K34: 煤电 | L34: 核电 | M34: 燃气发电 | N34: 光伏发电 | O34: 风电 | R34: 年份 | S34: 煤电 | T34: 核电 | U34: 燃气发电 | V34: 光伏发电 | W34: 风电
J35: 2016 | K35: 0.8178 | L35: 0.0551 | M35: 0.0137 | N35: 0.0096 | O35: 0.0184 | P35: =SUM(K35:O35) -> 0.9146 | R35: 2016 | S35: =K35/$P35 -> 0.89416138 | T35: =L35/$P35 -> 0.060244916 | U35: =M35/$P35 -> 0.014979226 | V35: =N35/$P35 -> 0.010496392 | W35: =O35/$P35 -> 0.020118084
J36: 2020 | K36: 0.8009 | L36: 0.0509 | M36: 0 | N36: 0.0177 | O36: 0.0387 | P36: =SUM(K36:O36) -> 0.9082 | R36: 2020 | S36: =K36/$P36 -> 0.88185422 | T36: =L36/$P36 -> 0.056044924 | U36: =M36/$P36 -> 0 | V36: =N36/$P36 -> 0.019489099 | W36: =O36/$P36 -> 0.04261176
J37: 2030 | K37: 0.6898 | L37: 0.0411 | M37: 0.029 | N37: 0.0457 | O37: 0.0947 | P37: =SUM(K37:O37) -> 0.9003 | R37: 2030 | S37: =K37/$P37 -> 0.76618905 | T37: =L37/$P37 -> 0.04565145 | U37: =M37/$P37 -> 0.032211485 | V37: =N37/$P37 -> 0.050760857 | W37: =O37/$P37 -> 0.10518716
B38: 一吨鲍鱼碳足迹 | G38: 加温度 | J38: 2040 | K38: 0.5081 | L38: 0.0779 | M38: 0.1365 | N38: 0.0623 | O38: 0.1192 | P38: =SUM(K38:O38) -> 0.904 | R38: 2040 | S38: =K38/$P38 -> 0.56205752 | T38: =L38/$P38 -> 0.086172566 | U38: =M38/$P38 -> 0.15099558 | V38: =N38/$P38 -> 0.068915929 | W38: =O38/$P38 -> 0.13185841
B39: mean | G39: mean | J39: 2050 | K39: 0.316 | L39: 0.3001 | M39: 0.0696 | N39: 0.0655 | O39: 0.1809 | P39: =SUM(K39:O39) -> 0.9321 | R39: 2050 | S39: =K39/$P39 -> 0.33901942 | T39: =L39/$P39 -> 0.32196116 | U39: =M39/$P39 -> 0.0746701 | V39: =N39/$P39 -> 0.07027143 | W39: =O39/$P39 -> 0.19407789
A40: 2020 | B40: =G3*Case!$C$11+Case!$B$12 -> 11121.456 | F40: 2020 | G40: =B40/Temperature!B2 -> 11121.456
...

Sheet Speed
K1: 加温度
F2: mean | K2: mean
A3: 2020 | B3: 1 | C3: =(B13-B3)/(A13-A3) -> 0.02 | E3: 2020 | F3: =Case!$B$8/Speed!B3 -> 11121.456 | J3: 2020 | K3: =Speed!F3/Temperature!B2 -> 11121.456
A4: 2021 | B4: =B3+$C$3 -> 1.02 | E4: 2021 | F4: =Case!$B$8/Speed!B4 -> 10903.388 | J4: 2021 | K4: =Speed!F4/Temperature!B3 -> 10939.854
A5: 2022 | B5: =B4+$C$3 -> 1.04 | E5: 2022 | F5: =Case!$B$8/Speed!B5 -> 10693.707 | J5: 2022 | K5: =Speed!F5/Temperature!B4 -> 10765.477
A6: 2023 | B6: =B5+$C$3 -> 1.06 | E6: 2023 | F6: =Case!$B$8/Speed!B6 -> 10491.939 | J6: 2023 | K6: =Speed!F6/Temperature!B5 -> 10597.918
A7: 2024 | B7: =B6+$C$3 -> 1.08 | E7: 2024 | F7: =Case!$B$8/Speed!B7 -> 10297.644 | J7: 2024 | K7: =Speed!F7/Temperature!B6 -> 10436.801
A8: 2025 | B8: =B7+$C$3 -> 1.1 | E8: 2025 | F8: =Case!$B$8/Speed!B8 -> 10110.414 | J8: 2025 | K8: =Speed!F8/Temperature!B7 -> 10281.777
A9: 2026 | B9: =B8+$C$3 -> 1.12 | E9: 2026 | F9: =Case!$B$8/Speed!B9 -> 9929.8711 | J9: 2026 | K9: =Speed!F9/Temperature!B8 -> 10132.522
A10: 2027 | B10: =B9+$C$3 -> 1.14 | E10: 2027 | F10: =Case!$B$8/Speed!B10 -> 9755.6628 | J10: 2027 | K10: =Speed!F10/Temperature!B9 -> 9988.7333
A11: 2028 | B11: =B10+$C$3 -> 1.16 | E11: 2028 | F11: =Case!$B$8/Speed!B11 -> 9587.4618 | J11: 2028 | K11: =Speed!F11/Temperature!B10 -> 9850.1319
A12: 2029 | B12: =B11+$C$3 -> 1.18 | E12: 2029 | F12: =Case!$B$8/Speed!B12 -> 9424.9624 | J12: 2029 | K12: =Speed!F12/Temperature!B11 -> 9716.4561
A13: 2030 | B13: 1.2 | E13: 2030 | F13: =Case!$B$8/Speed!B13 -> 9267.8797 | J13: 2030 | K13: =Speed!F13/Temperature!B12 -> 9587.4618
A14: 2031 | B14: =B13+$C$3 -> 1.22 | E14: 2031 | F14: =Case!$B$8/Speed!B14 -> 9115.9472 | J14: 2031 | K14: =Speed!F14/Temperature!B13 -> 9462.921
A15: 2032 | B15: =B14+$C$3 -> 1.24 | E15: 2032 | F15: =Case!$B$8/Speed!B15 -> 8968.9158 | J15: 2032 | K15: =Speed!F15/Temperature!B14 -> 9342.6207
A16: 2033 | B16: =B15+$C$3 -> 1.26 | E16: 2033 | F16: =Case!$B$8/Speed!B16 -> 8826.5521 | J16: 2033 | K16: =Speed!F16/Temperature!B15 -> 9226.3611
A17: 2034 | B17: =B16+$C$3 -> 1.28 | E17: 2034 | F17: =Case!$B$8/Speed!B17 -> 8688.6372 | J17: 2034 | K17: =Speed!F17/Temperature!B16 -> 9113.9551
A18: 2035 | B18: =B17+$C$3 -> 1.3 | E18: 2035 | F18: =Case!$B$8/Speed!B18 -> 8554.9659 | J18: 2035 | K18: =Speed!F18/Temperature!B17 -> 9005.2272
A19: 2036 | B19: =B18+$C$3 -> 1.32 | E19: 2036 | F19: =Case!$B$8/Speed!B19 -> 8425.3452 | J19: 2036 | K19: =Speed!F19/Temperature!B18 -> 8900.0125
A20: 2037 | B20: =B19+$C$3 -> 1.34 | E20: 2037 | F20: =Case!$B$8/Speed!B20 -> 8299.5938 | J20: 2037 | K20: =Speed!F20/Temperature!B19 -> 8798.1559
A21: 2038 | B21: =B20+$C$3 -> 1.36 | E21: 2038 | F21: =Case!$B$8/Speed!B21 -> 8177.5409 | J21: 2038 | K21: =Speed!F21/Temperature!B20 -> 8699.5116
A22: 2039 | B22: =B21+$C$3 -> 1.38 | E22: 2039 | F22: =Case!$B$8/Speed!B22 -> 8059.0258 | J22: 2039 | K22: =Speed!F22/Temperature!B21 -> 8603.9422
A23: 2040 | B23: =B22+$C$3 -> 1.4 | E23: 2040 | F23: =Case!$B$8/Speed!B23 -> 7943.8969 | J23: 2040 | K23: =Speed!F23/Temperature!B22 -> 8511.3181
A24: 2041 | B24: =B23+$C$3 -> 1.42 | E24: 2041 | F24: =Case!$B$8/Speed!B24 -> 7832.011 | J24: 2041 | K24: =Speed!F24/Temperature!B23 -> 8421.5172
A25: 2042 | B25: =B24+$C$3 -> 1.44 | E25: 2042 | F25: =Case!$B$8/Speed!B25 -> 7723.2331 | J25: 2042 | K25: =Speed!F25/Temperature!B24 -> 8334.4242
... A33: 2050 | B33: =B32+$C$3 -> 1.6 | E33: 2050 | F33: =Case!$B$8/Speed!B33 -> 6950.9098 | J33: 2050 | K33: =Speed!F33/Temperature!B32 -> 7723.2331

Sheet Infrastructure
I2: 带温度
B3: 基建排放比例 | E3: mean | I3: mean
A4: 2020 | B4: 1 | C4: =(B34-B4)/(A34-A4) -> 0.016666667 | E4: =Case!$B$13/Infrastructure!B4+Case!$B$14 -> 11121.456 | I4: =E4/Temperature!B2 -> 11121.456
A5: 2021 | B5: =B4+$C$4 -> 1.0166667 | E5: =Case!$B$13/Infrastructure!B5+Case!$B$14 -> 11101.537 | I5: =E5/Temperature!B3 -> 11138.666
A6: 2022 | B6: =B5+$C$4 -> 1.0333333 | E6: =Case!$B$13/Infrastructure!B6+Case!$B$14 -> 11082.262 | I6: =E6/Temperature!B4 -> 11156.639
A7: 2023 | B7: =B6+$C$4 -> 1.05 | E7: =Case!$B$13/Infrastructure!B7+Case!$B$14 -> 11063.598 | I7: =E7/Temperature!B5 -> 11175.351
A8: 2024 | B8: =B7+$C$4 -> 1.0666667 | E8: =Case!$B$13/Infrastructure!B8+Case!$B$14 -> 11045.517 | I8: =E8/Temperature!B6 -> 11194.781
A9: 2025 | B9: =B8+$C$4 -> 1.0833333 | E9: =Case!$B$13/Infrastructure!B9+Case!$B$14 -> 11027.993 | I9: =E9/Temperature!B7 -> 11214.908
A10: 2026 | B10: =B9+$C$4 -> 1.1 | E10: =Case!$B$13/Infrastructure!B10+Case!$B$14 -> 11010.999 | I10: =E10/Temperature!B8 -> 11235.714
A11: 2027 | B11: =B10+$C$4 -> 1.1166667 | E11: =Case!$B$13/Infrastructure!B11+Case!$B$14 -> 10994.513 | I11: =E11/Temperature!B9 -> 11257.181
A12: 2028 | B12: =B11+$C$4 -> 1.1333333 | E12: =Case!$B$13/Infrastructure!B12+Case!$B$14 -> 10978.512 | I12: =E12/Temperature!B10 -> 11279.294
A13: 2029 | B13: =B12+$C$4 -> 1.15 | E13: =Case!$B$13/Infrastructure!B13+Case!$B$14 -> 10962.975 | I13: =E13/Temperature!B11 -> 11302.036
A14: 2030 | B14: =B13+$C$4 -> 1.1666667 | E14: =Case!$B$13/Infrastructure!B14+Case!$B$14 -> 10947.882 | I14: =E14/Temperature!B12 -> 11325.395
A15: 2031 | B15: =B14+$C$4 -> 1.1833333 | E15: =Case!$B$13/Infrastructure!B15+Case!$B$14 -> 10933.213 | I15: =E15/Temperature!B13 -> 11349.357
A16: 2032 | B16: =B15+$C$4 -> 1.2 | E16: =Case!$B$13/Infrastructure!B16+Case!$B$14 -> 10918.953 | I16: =E16/Temperature!B14 -> 11373.909
... A33: 2049 | B33: =B32+$C$4 -> 1.4833333 | E33: =Case!$B$13/Infrastructure!B33+Case!$B$14 -> 10725.551 | I33: =E33/Temperature!B31 -> 11873.304
A34: 2050 | B34: 1.5 | E34: =Case!$B$13/Infrastructure!B34+Case!$B$14 -> 10716.45 | I34: =E34/Temperature!B32 -> 11907.166

Sheet Feed
B1: 配合饲料 | C1: 海藻 | H1: Both | J1: CF | L1: 带温度
A2: 2020 | B2: 1 | C2: 0 | D2: =(B32-B2)/(A32-A2) -> -0.016666667 | E2: =(C32-C2)/(A32-A2) -> 0.016666667 | G2: 2020 | H2: =Case!$B$17*Feed!B2+Feed!C2*$E$8+$J$37*C2 -> 2604.7141 | J2: =H2+Case!$B$18 -> 11121.456 | L2: 2020 | M2: =J2/Temperature!B2 -> 11121.456
A3: 2021 | B3: =B2+D$2 -> 0.98333333 | C3: =C2+E$2 -> 0.016666667 | G3: 2021 | H3: =Case!$B$17*Feed!B3+Feed!C3*$E$8+$J$37*C3 -> 2544.5521 | J3: =H3+Case!$B$18 -> 11061.294 | L3: 2021 | M3: =J3/Temperature!B3 -> 11098.288
A4: 2022 | B4: =B3+D$2 -> 0.96666667 | C4: =C3+E$2 -> 0.033333333 | G4: 2022 | H4: =Case!$B$17*Feed!B4+Feed!C4*$E$8+$J$37*C4 -> 2484.3901 | J4: =H4+Case!$B$18 -> 11001.132 | L4: 2022 | M4: =J4/Temperature!B4 -> 11074.965
A5: 2023 | B5: =B4+D$2 -> 0.95 | C5: =C4+E$2 -> 0.05 | G5: 2023 | H5: =Case!$B$17*Feed!B5+Feed!C5*$E$8+$J$37*C5 -> 2424.2282 | J5: =H5+Case!$B$18 -> 10940.97 | L5: 2023 | M5: =J5/Temperature!B5 -> 11051.485
A6: 2024 | B6: =B5+D$2 -> 0.93333333 | C6: =C5+E$2 -> 0.066666667 | G6: 2024 | H6: =Case!$B$17*Feed!B6+Feed!C6*$E$8+$J$37*C6 -> 2364.0662 | J6: =H6+Case!$B$18 -> 10880.808 | L6: 2024 | M6: =J6/Temperature!B6 -> 11027.846
A7: 2025 | B7: =B6+D$2 -> 0.91666667 | C7: =C6+E$2 -> 0.083333333 | E7: 海藻 | G7: 2025 | H7: =Case!$B$17*Feed!B7+Feed!C7*$E$8+$J$37*C7 -> 2303.9042 | J7: =H7+Case!$B$18 -> 10820.646 | L7: 2025 | M7: =J7/Temperature!B7 -> 11004.047
A8: 2026 | B8: =B7+D$2 -> 0.9 | C8: =C7+E$2 -> 0.1 | E8: -1137.8611 | F8: 20t | G8: 2026 | H8: =Case!$B$17*Feed!B8+Feed!C8*$E$8+$J$37*C8 -> 2243.7422 | J8: =H8+Case!$B$18 -> 10760.484 | L8: 2026 | M8: =J8/Temperature!B8 -> 10980.085
A9: 2027 | B9: =B8+D$2 -> 0.88333333 | C9: =C8+E$2 -> 0.11666667 | G9: 2027 | H9: =Case!$B$17*Feed!B9+Feed!C9*$E$8+$J$37*C9 -> 2183.5803 | J9: =H9+Case!$B$18 -> 10700.322 | L9: 2027 | M9: =J9/Temperature!B9 -> 10955.961
A10: 2028 | B10: =B9+D$2 -> 0.86666667 | C10: =C9+E$2 -> 0.13333333 | G10: 2028 | H10: =Case!$B$17*Feed!B10+Feed!C10*$E$8+$J$37*C10 -> 2123.4183 | J10: =H10+Case!$B$18 -> 10640.16 | L10: 2028 | M10: =J10/Temperature!B10 -> 10931.671
A11: 2029 | B11: =B10+D$2 -> 0.85 | C11: =C10+E$2 -> 0.15 | G11: 2029 | H11: =Case!$B$17*Feed!B11+Feed!C11*$E$8+$J$37*C11 -> 2063.2563 | J11: =H11+Case!$B$18 -> 10579.998 | L11: 2029 | M11: =J11/Temperature!B11 -> 10907.214
A12: 2030 | B12: =B11+D$2 -> 0.83333333 | C12: =C11+E$2 -> 0.16666667 | G12: 2030 | H12: =Case!$B$17*Feed!B12+Feed!C12*$E$8+$J$37*C12 -> 2003.0943 | J12: =H12+Case!$B$18 -> 10519.836 | L12: 2030 | M12: =J12/Temperature!B12 -> 10882.589
A13: 2031 | B13: =B12+D$2 -> 0.81666667 | C13: =C12+E$2 -> 0.18333333 | G13: 2031 | H13: =Case!$B$17*Feed!B13+Feed!C13*$E$8+$J$37*C13 -> 1942.9324 | J13: =H13+Case!$B$18 -> 10459.674 | L13: 2031 | M13: =J13/Temperature!B13 -> 10857.793
A14: 2032 | B14: =B13+D$2 -> 0.8 | C14: =C13+E$2 -> 0.2 | G14: 2032 | H14: =Case!$B$17*Feed!B14+Feed!C14*$E$8+$J$37*C14 -> 1882.7704 | J14: =H14+Case!$B$18 -> 10399.512 | L14: 2032 | M14: =J14/Temperature!B14 -> 10832.825
A15: 2033 | B15: =B14+D$2 -> 0.78333333 | C15: =C14+E$2 -> 0.21666667 | G15: 2033 | H15: =Case!$B$17*Feed!B15+Feed!C15*$E$8+$J$37*C15 -> 1822.6084 | J15: =H15+Case!$B$18 -> 10339.35 | L15: 2033 | M15: =J15/Temperature!B15 -> 10807.683
A16: 2034 | B16: =B15+D$2 -> 0.76666667 | C16: =C15+E$2 -> 0.23333333 | G16: 2034 | H16: =Case!$B$17*Feed!B16+Feed!C16*$E$8+$J$37*C16 -> 1762.4464 | J16: =H16+Case!$B$18 -> 10279.188 | L16: 2034 | M16: =J16/Temperature!B16 -> 10782.365
A17: 2035 | B17: =B16+D$2 -> 0.75 | C17: =C16+E$2 -> 0.25 | G17: 2035 | H17: =Case!$B$17*Feed!B17+Feed!C17*$E$8+$J$37*C17 -> 1702.2845 | J17: =H17+Case!$B$18 -> 10219.026 | L17: 2035 | M17: =J17/Temperature!B17 -> 10756.869
A18: 2036 | B18: =B17+D$2 -> 0.73333333 | C18: =C17+E$2 -> 0.26666667 | G18: 2036 | H18: =Case!$B$17*Feed!B18+Feed!C18*$E$8+$J$37*C18 -> 1642.1225 | J18: =H18+Case!$B$18 -> 10158.864 | L18: 2036 | M18: =J18/Temperature!B18 -> 10731.194
A19: 2037 | B19: =B18+D$2 -> 0.71666667 | C19: =C18+E$2 -> 0.28333333 | G19: 2037 | H19: =Case!$B$17*Feed!B19+Feed!C19*$E$8+$J$37*C19 -> 1581.9605 | J19: =H19+Case!$B$18 -> 10098.702 | L19: 2037 | M19: =J19/Temperature!B19 -> 10705.338
A20: 2038 | B20: =B19+D$2 -> 0.7 | C20: =C19+E$2 -> 0.3 | G20: 2038 | H20: =Case!$B$17*Feed!B20+Feed!C20*$E$8+$J$37*C20 -> 1521.7985 | J20: =H20+Case!$B$18 -> 10038.54 | L20: 2038 | M20: =J20/Temperature!B20 -> 10679.298
... A31: 2049 | B31: =B30+D$2 -> 0.51666667 | C31: =C30+E$2 -> 0.48333333 | G31: 2049 | H31: =Case!$B$17*Feed!B31+Feed!C31*$E$8+$J$37*C31 -> 860.01681 | J31: =H31+Case!$B$18 -> 9376.7584 | L31: 2049 | M31: =J31/Temperature!B31 -> 10380.175
A32: 2050 | B32: 0.5 | C32: 0.5 | G32: 2050 | H32: =Case!$B$17*Feed!B32+Feed!C32*$E$8+$J$37*C32 -> 799.85483 | J32: =H32+Case!$B$18 -> 9316.5964 | L32: 2050 | M32: =J32/Temperature!B32 -> 10351.774
J36: 龙须菜工业过程
J37: 132.85667

Sheet Best
B4: 电力 | C4: 基建 | D4: Feed | E4: 总 | F4: 加生长速度和温度 | G4: mean | H4: 不带温度
A5: 2020 | B5: =Case!$C$11*'Elec str'!G3 -> 6882.9123 | C5: =Case!$B$13/Infrastructure!B4 -> 1215.0178 | D5: =Feed!H2 -> 2604.7141 | E5: =B5+C5+D5+Case!$B$19 -> 11121.456 | F5: 2020 | G5: =E5/Speed!B3/Temperature!B2 -> 11121.456 | H5: =G5*Temperature!B2 -> 11121.456
A6: 2021 | B6: =Case!$C$11*'Elec str'!G4 -> 6804.6659 | C6: =Case!$B$13/Infrastructure!B5 -> 1195.0994 | D6: =Feed!H3 -> 2544.5521 | E6: =B6+C6+D6+Case!$B$19 -> 10963.129 | F6: 2021 | G6: =E6/Speed!B4/Temperature!B3 -> 10784.113 | H6: =G6*Temperature!B3 -> 10748.166
A7: 2022 | B7: =Case!$C$11*'Elec str'!G5 -> 6726.4196 | C7: =Case!$B$13/Infrastructure!B6 -> 1175.8236 | D7: =Feed!H4 -> 2484.3901 | E7: =B7+C7+D7+Case!$B$19 -> 10805.445 | F7: 2022 | G7: =E7/Speed!B5/Temperature!B4 -> 10459.581 | H7: =G7*Temperature!B4 -> 10389.851
A8: 2023 | B8: =Case!$C$11*'Elec str'!G6 -> 6648.1733 | C8: =Case!$B$13/Infrastructure!B7 -> 1157.1598 | D8: =Feed!H5 -> 2424.2282 | E8: =B8+C8+D8+Case!$B$19 -> 10648.373 | F8: 2023 | G8: =E8/Speed!B6/Temperature!B5 -> 10147.106 | H8: =G8*Temperature!B5 -> 10045.635
A9: 2024 | B9: =Case!$C$11*'Elec str'!G7 -> 6569.9269 | C9: =Case!$B$13/Infrastructure!B8 -> 1139.0791 | D9: =Feed!H6 -> 2364.0662 | E9: =B9+C9+D9+Case!$B$19 -> 10491.884 | F9: 2024 | G9: =E9/Speed!B7/Temperature!B6 -> 9845.987 | H9: =G9*Temperature!B6 -> 9714.7072
A10: 2025 | B10: =Case!$C$11*'Elec str'!G8 -> 6491.6806 | C10: =Case!$B$13/Infrastructure!B9 -> 1121.5548 | D10: =Feed!H7 -> 2303.9042 | E10: =B10+C10+D10+Case!$B$19 -> 10335.951 | F10: 2025 | G10: =E10/Speed!B8/Temperature!B7 -> 9555.5789 | H10: =G10*Temperature!B7 -> 9396.3193
A11: 2026 | B11: =Case!$C$11*'Elec str'!G9 -> 6413.4343 | C11: =Case!$B$13/Infrastructure!B10 -> 1104.5616 | D11: =Feed!H8 -> 2243.7422 | E11: =B11+C11+D11+Case!$B$19 -> 10180.55 | F11: 2026 | G11: =E11/Speed!B9/Temperature!B8 -> 9275.2821 | H11: =G11*Temperature!B8 -> 9089.7764
A12: 2027 | B12: =Case!$C$11*'Elec str'!G10 -> 6335.1879 | C12: =Case!$B$13/Infrastructure!B11 -> 1088.0756 | D12: =Feed!H9 -> 2183.5803 | E12: =B12+C12+D12+Case!$B$19 -> 10025.655 | F12: 2027 | G12: =E12/Speed!B10/Temperature!B9 -> 9004.5404 | H12: =G12*Temperature!B9 -> 8794.4345
A13: 2028 | B13: =Case!$C$11*'Elec str'!G11 -> 6256.9416 | C13: =Case!$B$13/Infrastructure!B12 -> 1072.0745 | D13: =Feed!H10 -> 2123.4183 | E13: =B13+C13+D13+Case!$B$19 -> 9871.2459 | F13: 2028 | G13: =E13/Speed!B11/Temperature!B10 -> 8742.8371 | H13: =G13*Temperature!B10 -> 8509.6947
A14: 2029 | B14: =Case!$C$11*'Elec str'!G12 -> 6178.6953 | C14: =Case!$B$13/Infrastructure!B13 -> 1056.5372 | D14: =Feed!H11 -> 2063.2563 | E14: =B14+C14+D14+Case!$B$19 -> 9717.3003 | F14: 2029 | G14: =E14/Speed!B12/Temperature!B11 -> 8489.691 | H14: =G14*Temperature!B11 -> 8235.0002
A15: 2030 | B15: =Case!$C$11*'Elec str'!G13 -> 6100.4489 | C15: =Case!$B$13/Infrastructure!B14 -> 1041.4438 | D15: =Feed!H12 -> 2003.0943 | E15: =B15+C15+D15+Case!$B$19 -> 9563.7986 | F15: 2030 | G15: =E15/Speed!B13/Temperature!B12 -> 8244.6539 | H15: =G15*Temperature!B12 -> 7969.8321
A16: 2031 | B16: =Case!$C$11*'Elec str'!G14 -> 5974.7431 | C16: =Case!$B$13/Infrastructure!B15 -> 1026.7756 | D16: =Feed!H13 -> 1942.9324 | E16: =B16+C16+D16+Case!$B$19 -> 9363.2626 | F16: 2031 | G16: =E16/Speed!B14/Temperature!B13 -> 7966.926 | H16: =G16*Temperature!B13 -> 7674.8054
... A23: 2038 | B23: =Case!$C$11*'Elec str'!G21 -> 5094.8028 | C23: =Case!$B$13/Infrastructure!B22 -> 934.62904 | D23: =Feed!H20 -> 1521.7985 | E23: =B23+C23+D23+Case!$B$19 -> 7970.0419 | F23: 2038 | G23: =E23/Speed!B21/Temperature!B20 -> 6234.3882 | H23: =G23*Temperature!B20 -> 5860.3249
A24: 2039 | B24: =Case!$C$11*'Elec str'!G22 -> 4969.097 | C24: =Case!$B$13/Infrastructure!B23 -> 922.79829 | D24: =Feed!H21 -> 1461.6366 | E24: =B24+C24+D24+Case!$B$19 -> 7772.3434 | F24: 2039 | G24: =E24/Speed!B22/Temperature!B21 -> 6012.9533 | H24: =G24*Temperature!B21 -> 5632.1329 | K24: =Case!A2 -> Feed | L24: =Case!B2 -> 2604.7141
A25: 2040 | B25: =Case!$C$11*'Elec str'!G23 -> 4843.3912 | C25: =Case!$B$13/Infrastructure!B24 -> 911.26331 | D25: =Feed!H22 -> 1401.4746 | E25: =B25+C25+D25+Case!$B$19 -> 7574.9407 | F25: 2040 | G25: =E25/Speed!B23/Temperature!B22 -> 5797.1485 | H25: =G25*Temperature!B22 -> 5410.6719 | K25: =Case!A3 -> Energy | L25: =Case!B3 -> 6882.9123
A26: 2041 | B26: =Case!$C$11*'Elec str'!G24 -> 4652.3726 | C26: =Case!$B$13/Infrastructure!B25 -> 900.01315 | D26: =Feed!H23 -> 1341.3126 | E26: =B26+C26+D26+Case!$B$19 -> 7312.5099 | F26: 2041 | G26: =E26/Speed!B24/Temperature!B23 -> 5537.2633 | H26: =G26*Temperature!B23 -> 5149.6549 | K26: =Case!A4 -> Infrastructure | L26: =Case!B4 -> 1215.0178
A27: 2042 | B27: =Case!$C$11*'Elec str'!G25 -> 4461.354 | C27: =Case!$B$13/Infrastructure!B26 -> 889.03738 | D27: =Feed!H24 -> 1281.1506 | E27: =B27+C27+D27+Case!$B$19 -> 7050.3535 | F27: 2042 | G27: =E27/Speed!B25/Temperature!B24 -> 5283.5383 | H27: =G27*Temperature!B24 -> 4896.0788 | K27: =Case!A5 -> Equipment | L27: =Case!B5 -> 0.075840311 | M27: =L27/L31 -> 0.00018108458
A28: 2043 | B28: =Case!$C$11*'Elec str'!G26 -> 4270.3353 | C28: =Case!$B$13/Infrastructure!B27 -> 878.32608 | D28: =Feed!H25 -> 1220.9887 | E28: =B28+C28+D28+Case!$B$19 -> 6788.4616 | F28: 2043 | G28: =E28/Speed!B26/Temperature!B25 -> 5035.7017 | H28: =G28*Temperature!B25 -> 4649.6312 | K28: =Case!A6 -> Transport | L28: =Case!B6 -> 418.73569 | M28: =L28/L31 -> 0.99981892
A29: 2044 | B29: =Case!$C$11*'Elec str'!G27 -> 4079.3167 | C29: =Case!$B$13/Infrastructure!B28 -> 867.86982 | D29: =Feed!H26 -> 1160.8267 | E29: =B29+C29+D29+Case!$B$19 -> 6526.8247 | F29: 2044 | G29: =E29/Speed!B27/Temperature!B26 -> 4793.4964 | H29: =G29*Temperature!B26 -> 4410.0167 | K29: =Case!A8 -> CF (no seaweed) | L29: =SUM(L24:L28) -> 11121.456
A30: 2045 | B30: =Case!$C$11*'Elec str'!G28 -> 3888.2981 | C30: =Case!$B$13/Infrastructure!B29 -> 857.65959 | D30: =Feed!H27 -> 1100.6647 | E30: =B30+C30+D30+Case!$B$19 -> 6265.4339 | F30: 2045 | G30: =E30/Speed!B28/Temperature!B27 -> 4556.6792 | H30: =G30*Temperature!B27 -> 4176.9559
A31: 2046 | B31: =Case!$C$11*'Elec str'!G29 -> 3697.2794 | C31: =Case!$B$13/Infrastructure!B30 -> 847.6868 | D31: =Feed!H28 -> 1040.5027 | E31: =B31+C31+D31+Case!$B$19 -> 6004.2805 | F31: 2046 | G31: =E31/Speed!B29/Temperature!B28 -> 4325.0196 | H31: =G31*Temperature!B28 -> 3950.1845 | K31: CF除基建、电力、饲料、自然外 | L31: =L27+L28 -> 418.81153
A32: 2047 | B32: =Case!$C$11*'Elec str'!G30 -> 3506.2608 | C32: =Case!$B$13/Infrastructure!B31 -> 837.94328 | D32: =Feed!H29 -> 980.34076 | E32: =B32+C32+D32+Case!$B$19 -> 5743.3563 | F32: 2047 | G32: =E32/Speed!B30/Temperature!B29 -> 4098.2991 | H32: =G32*Temperature!B29 -> 3729.4522
A33: 2048 | B33: =Case!$C$11*'Elec str'!G31 -> 3315.2421 | C33: =Case!$B$13/Infrastructure!B32 -> 828.42119 | D33: =Feed!H30 -> 920.17878 | E33: =B33+C33+D33+Case!$B$19 -> 5482.6537 | F33: 2048 | G33: =E33/Speed!B31/Temperature!B30 -> 3876.3106 | H33: =G33*Temperature!B30 -> 3514.5216
A34: 2049 | B34: =Case!$C$11*'Elec str'!G32 -> 3124.2235 | C34: =Case!$B$13/Infrastructure!B33 -> 819.11309 | D34: =Feed!H31 -> 860.01681 | E34: =B34+C34+D34+Case!$B$19 -> 5222.1649 | F34: 2049 | G34: =E34/Speed!B32/Temperature!B31 -> 3658.8572 | H34: =G34*Temperature!B31 -> 3305.1677
A35: 2050 | B35: =Case!$C$11*'Elec str'!G33 -> 2933.2049 | C35: =Case!$B$13/Infrastructure!B34 -> 810.01183 | D35: =Feed!H32 -> 799.85483 | E35: =B35+C35+D35+Case!$B$19 -> 4961.8831 | F35: 2050 | G35: =E35/Speed!B33/Temperature!B32 -> 3445.7521 | H35: =G35*Temperature!B32 -> 3101.1769
A40: 转化后 | B40: 电力 | C40: 基建 | D40: 饲料 | E40: 其他
A41: 2020 | B41: =B5/Speed!$B3/Temperature!$B2 -> 6882.9123 | C41: =C5/Speed!$B3/Temperature!$B2 -> 1215.0178 | D41: =D5/Speed!$B3/Temperature!$B2 -> 2604.7141 | E41: =G5-B41-C41-D41 -> 418.81153
A42: 2021 | B42: =B6/Speed!$B4/Temperature!$B3 -> 6693.5529 | C42: =C6/Speed!$B4/Temperature!$B3 -> 1175.5847 | D42: =D6/Speed!$B4/Temperature!$B3 -> 2503.0023 | E42: =G6-B42-C42-D42 -> 411.97278
A43: 2022 | B43: =B7/Speed!$B5/Temperature!$B4 -> 6511.1186 | C43: =C7/Speed!$B5/Temperature!$B4 -> 1138.1876 | D43: =D7/Speed!$B5/Temperature!$B4 -> 2404.8691 | E43: =G7-B43-C43-D43 -> 405.4061
A44: 2023 | B44: =B8/Speed!$B6/Temperature!$B5 -> 6335.2137 | C44: =C8/Speed!$B6/Temperature!$B5 -> 1102.687 | D44: =D8/Speed!$B6/Temperature!$B5 -> 2310.1088 | E44: =G8-B44-C44-D44 -> 399.09618 | F44: 贡献分解 | G44: 2020 | H44: 2025 | I44: 2030 | J44: 2035 | K44: 2040 | L44: 2045 | M44: 2050
A45: 2024 | B45: =B9/Speed!$B7/Temperature!$B6 -> 6165.472 | C45: =C9/Speed!$B7/Temperature!$B6 -> 1068.9557 | D45: =D9/Speed!$B7/Temperature!$B6 -> 2218.5306 | E45: =G9-B45-C45-D45 -> 393.02884 | F45: Energy | G45: =B41 -> 6882.9123 | H45: =B46 -> 6001.5537 | I45: =B51 -> 5259.0077 | J45: =B56 -> 4430.7045 | K45: =B61 -> 3706.677 | L45: =B66 -> 2827.8531 | M45: =B71 -> 2036.9478
A46: 2025 | B46: =B10/Speed!$B8/Temperature!$B7 -> 6001.5537 | C46: =C10/Speed!$B8/Temperature!$B7 -> 1036.8766 | D46: =D10/Speed!$B8/Temperature!$B7 -> 2129.9577 | E46: =G10-B46-C46-D46 -> 387.19094 | F46: Infra.&Equip | G46: =C41+E41*M27 -> 1215.0936 | H46: =C46+E46*M27 -> 1036.9467 | I46: =C51+E51*M27 -> 897.86175 | J46: =C56+E56*M27 -> 787.11744 | K46: =C61+E61*M27 -> 697.45343 | L46: =C66+E66*M27 -> 623.80758 | M46: =C71+E71*M27 -> 562.56088
A47: 2026 | B47: =B11/Speed!$B9/Temperature!$B8 -> 5843.1435 | C47: =C11/Speed!$B9/Temperature!$B8 -> 1006.3426 | D47: =D11/Speed!$B9/Temperature!$B8 -> 2044.2258 | E47: =G11-B47-C47-D47 -> 381.57027 | F47: Transport | G47: =E41*M28 -> 418.73569 | H47: =E46*M28 -> 387.12082 | I47: =E51*M28 -> 360.97904 | J47: =E56*M28 -> 339.05724 | K47: =E61*M28 -> 320.46099 | L47: =E66*M28 -> 304.53505 | M47: =E71*M28 -> 290.78867
A48: 2027 | B48: =B12/Speed!$B10/Temperature!$B9 -> 5689.9478 | C48: =C12/Speed!$B10/Temperature!$B9 -> 977.25489 | D48: =D12/Speed!$B10/Temperature!$B9 -> 1961.1822 | E48: =G12-B48-C48-D48 -> 376.1555 | F48: Feed | G48: =D41 -> 2604.7141 | H48: =D46 -> 2129.9577 | I48: =D51 -> 1726.8055 | J48: =D56 -> 1378.368 | K48: =D61 -> 1072.5571 | L48: =D66 -> 800.48342 | M48: =D71 -> 555.45475
A49: 2028 | B49: =B13/Speed!$B11/Temperature!$B10 -> 5541.6937 | C49: =C13/Speed!$B11/Temperature!$B10 -> 949.52275 | D49: =D13/Speed!$B11/Temperature!$B10 -> 1880.6846 | E49: =G13-B49-C49-D49 -> 370.93605 | O49: 自然
A50: 2029 | B50: =B14/Speed!$B12/Temperature!$B11 -> 5398.1262 | C50: =C14/Speed!$B12/Temperature!$B11 -> 923.06236 | D50: =D14/Speed!$B12/Temperature!$B11 -> 1802.6003 | E50: =G14-B50-C50-D50 -> 365.90209 | G50: =SUM(G45:G48) -> 11121.456 | H50: =SUM(H45:H48) -> 9555.5789 | I50: =SUM(I45:I48) -> 8244.6539 | J50: =SUM(J45:J48) -> 6935.2472 | K50: =SUM(K45:K48) -> 5797.1485 | L50: =SUM(L45:L48) -> 4556.6792 | M50: =SUM(M45:M48) -> 3445.7521 | O50: -23.87
A51: 2030 | B51: =B15/Speed!$B13/Temperature!$B12 -> 5259.0077 | C51: =C15/Speed!$B13/Temperature!$B12 -> 897.79637 | D51: =D15/Speed!$B13/Temperature!$B12 -> 1726.8055 | E51: =G15-B51-C51-D51 -> 361.04442
A52: 2031 | B52: =B16/Speed!$B14/Temperature!$B13 -> 5083.734 | C52: =C16/Speed!$B14/Temperature!$B13 -> 873.65327 | D52: =D16/Speed!$B14/Temperature!$B13 -> 1653.1843 | E52: =G16-B52-C52-D52 -> 356.35447
A53: 2032 | B53: =B17/Speed!$B15/Temperature!$B14 -> 4913.5059 | C53: =C17/Speed!$B15/Temperature!$B14 -> 850.56686 | D53: =D17/Speed!$B15/Temperature!$B14 -> 1581.6284 | E53: =G17-B53-C53-D53 -> 351.8242 | F53: 贡献分解（加自然） | G53: 2020 | H53: 2025 | I53: 2030 | J53: 2035 | K53: 2040 | L53: 2045 | M53: 2050 | O53: 新增冷却电力
...

Sheet 单位碳足迹
A1: 注：基准考虑温度，其他不考虑 | B1: 基准情景单位产量碳足迹 | C1: 能源改进单位产量碳足迹 | D1: 品种优化 | E1: 基建改进 | F1: 饲料替代 | G1: 最优 (with BG) | H1: 最优 (without BG) | L1: 基准情景单位产量碳足迹 | M1: 能源改进单位产量碳足迹 | N1: 品种优化 | O1: 基建改进 | P1: 饲料替代 | Q1: 最优 (with BG) | R1: 最优 (without BG)
A2: 参考sheet Temprature | B2: 参考sheet Baseline | C2: 参考sheet Elec str | D2: 参考sheet Speed | E2: 参考sheet Infrastructure | F2: 参考sheet Feed | G2: 参考sheet Best | H2: 参考sheet Best | L2: 参考sheet Baseline | M2: 参考sheet Elec str | N2: 参考sheet Speed | O2: 参考sheet Infrastructure | P2: 参考sheet Feed | Q2: 参考sheet Best | R2: 参考sheet Best
A3: 年份 | B3: mean | C3: mean | D3: mean | E3: mean | F3: mean | G3: mean | H3: mean | J3: 自然 | L3: mean | M3: mean | N3: mean | O3: mean | P3: mean | Q3: mean | R3: mean
A4: 2020 | B4: =Case!$B$8/Temperature!B2+Temperature!K2 -> 11121.456 | C4: ='Elec str'!B40 -> 11121.456 | D4: =Speed!F3 -> 11121.456 | E4: =Infrastructure!E4 -> 11121.456 | F4: =Feed!J2 -> 11121.456 | G4: =Best!G5+Temperature!L2 -> 11121.456 | H4: =Best!H5 -> 11121.456 | J4: -23.87 | L4: =B4+$J$4 -> 11097.586 | M4: =C4+$J$4 -> 11097.586 | N4: =D4+$J$4 -> 11097.586 | O4: =E4+$J$4 -> 11097.586 | P4: =F4+$J$4 -> 11097.586 | Q4: =G4+$J$4 -> 11097.586 | R4: =H4+$J$4 -> 11097.586
A5: 2021 | B5: =Case!$B$8/Temperature!B3+Temperature!K3 -> 11315.652 | C5: ='Elec str'!B41 -> 11043.209 | D5: =Speed!F4 -> 10903.388 | E5: =Infrastructure!E5 -> 11101.537 | F5: =Feed!J3 -> 11061.294 | G5: =Best!G6+Temperature!L3 -> 10939.329 | H5: =Best!H6 -> 10748.166 | L5: =B5+$J$4 -> 11291.782 | M5: =C5+$J$4 -> 11019.339 | N5: =D5+$J$4 -> 10879.518 | O5: =E5+$J$4 -> 11077.667 | P5: =F5+$J$4 -> 11037.424 | Q5: =G5+$J$4 -> 10915.459 | R5: =H5+$J$4 -> 10724.296
A6: 2022 | B6: =Case!$B$8/Temperature!B4+Temperature!K4 -> 11510.099 | C6: ='Elec str'!B42 -> 10964.963 | D6: =Speed!F5 -> 10693.707 | E6: =Infrastructure!E6 -> 11082.262 | F6: =Feed!J4 -> 11001.132 | G6: =Best!G7+Temperature!L4 -> 10766.444 | H6: =Best!H7 -> 10389.851 | L6: =B6+$J$4 -> 11486.229 | M6: =C6+$J$4 -> 10941.093 | N6: =D6+$J$4 -> 10669.837 | O6: =E6+$J$4 -> 11058.392 | P6: =F6+$J$4 -> 10977.262 | Q6: =G6+$J$4 -> 10742.574 | R6: =H6+$J$4 -> 10365.981
A7: 2023 | B7: =Case!$B$8/Temperature!B5+Temperature!K5 -> 11704.797 | C7: ='Elec str'!B43 -> 10886.717 | D7: =Speed!F6 -> 10491.939 | E7: =Infrastructure!E7 -> 11063.598 | F7: =Feed!J5 -> 10940.97 | G7: =Best!G8+Temperature!L5 -> 10602.046 | H7: =Best!H8 -> 10045.635 | L7: =B7+$J$4 -> 11680.927 | M7: =C7+$J$4 -> 10862.847 | N7: =D7+$J$4 -> 10468.069 | O7: =E7+$J$4 -> 11039.728 | P7: =F7+$J$4 -> 10917.1 | Q7: =G7+$J$4 -> 10578.176 | R7: =H7+$J$4 -> 10021.765
A8: 2024 | B8: =Case!$B$8/Temperature!B6+Temperature!K6 -> 11899.75 | C8: ='Elec str'!B44 -> 10808.47 | D8: =Speed!F7 -> 10297.644 | E8: =Infrastructure!E8 -> 11045.517 | F8: =Feed!J6 -> 10880.808 | G8: =Best!G9+Temperature!L6 -> 10445.435 | H8: =Best!H9 -> 9714.7072 | L8: =B8+$J$4 -> 11875.88 | M8: =C8+$J$4 -> 10784.6 | N8: =D8+$J$4 -> 10273.774 | O8: =E8+$J$4 -> 11021.647 | P8: =F8+$J$4 -> 10856.938 | Q8: =G8+$J$4 -> 10421.565 | R8: =H8+$J$4 -> 9690.8372
A9: 2025 | B9: =Case!$B$8/Temperature!B7+Temperature!K7 -> 12094.961 | C9: ='Elec str'!B45 -> 10730.224 | D9: =Speed!F8 -> 10110.414 | E9: =Infrastructure!E9 -> 11027.993 | F9: =Feed!J7 -> 10820.646 | G9: =Best!G10+Temperature!L7 -> 10295.964 | H9: =Best!H10 -> 9396.3193 | L9: =B9+$J$4 -> 12071.091 | M9: =C9+$J$4 -> 10706.354 | N9: =D9+$J$4 -> 10086.544 | O9: =E9+$J$4 -> 11004.123 | P9: =F9+$J$4 -> 10796.776 | Q9: =G9+$J$4 -> 10272.094 | R9: =H9+$J$4 -> 9372.4493
A10: 2026 | B10: =Case!$B$8/Temperature!B8+Temperature!K8 -> 12290.431 | C10: ='Elec str'!B46 -> 10651.978 | D10: =Speed!F9 -> 9929.8711 | E10: =Infrastructure!E10 -> 11010.999 | F10: =Feed!J8 -> 10760.484 | G10: =Best!G11+Temperature!L8 -> 10153.036 | H10: =Best!H11 -> 9089.7764 | L10: =B10+$J$4 -> 12266.561 | M10: =C10+$J$4 -> 10628.108 | N10: =D10+$J$4 -> 9906.0011 | O10: =E10+$J$4 -> 10987.129 | P10: =F10+$J$4 -> 10736.614 | Q10: =G10+$J$4 -> 10129.166 | R10: =H10+$J$4 -> 9065.9064
A11: 2027 | B11: =Case!$B$8/Temperature!B9+Temperature!K9 -> 12486.164 | C11: ='Elec str'!B47 -> 10573.731 | D11: =Speed!F10 -> 9755.6628 | E11: =Infrastructure!E11 -> 10994.513 | F11: =Feed!J9 -> 10700.322 | G11: =Best!G12+Temperature!L9 -> 10016.092 | H11: =Best!H12 -> 8794.4345 | L11: =B11+$J$4 -> 12462.294 | M11: =C11+$J$4 -> 10549.861 | N11: =D11+$J$4 -> 9731.7928 | O11: =E11+$J$4 -> 10970.643 | P11: =F11+$J$4 -> 10676.452 | Q11: =G11+$J$4 -> 9992.2224 | R11: =H11+$J$4 -> 8770.5645
A12: 2028 | B12: =Case!$B$8/Temperature!B10+Temperature!K10 -> 12682.162 | C12: ='Elec str'!B48 -> 10495.485 | D12: =Speed!F11 -> 9587.4618 | E12: =Infrastructure!E12 -> 10978.512 | F12: =Feed!J10 -> 10640.16 | G12: =Best!G13+Temperature!L10 -> 9884.6179 | H12: =Best!H13 -> 8509.6947 | L12: =B12+$J$4 -> 12658.292 | M12: =C12+$J$4 -> 10471.615 | N12: =D12+$J$4 -> 9563.5918 | O12: =E12+$J$4 -> 10954.642 | P12: =F12+$J$4 -> 10616.29 | Q12: =G12+$J$4 -> 9860.7479 | R12: =H12+$J$4 -> 8485.8247
A13: 2029 | B13: =Case!$B$8/Temperature!B11+Temperature!K11 -> 12878.429 | C13: ='Elec str'!B49 -> 10417.239 | D13: =Speed!F12 -> 9424.9624 | E13: =Infrastructure!E13 -> 10962.975 | F13: =Feed!J11 -> 10579.998 | G13: =Best!G14+Temperature!L11 -> 9758.131 | H13: =Best!H14 -> 8235.0002 | L13: =B13+$J$4 -> 12854.559 | M13: =C13+$J$4 -> 10393.369 | N13: =D13+$J$4 -> 9401.0924 | O13: =E13+$J$4 -> 10939.105 | P13: =F13+$J$4 -> 10556.128 | Q13: =G13+$J$4 -> 9734.261 | R13: =H13+$J$4 -> 8211.1302
A14: 2030 | B14: =Case!$B$8/Temperature!B12+Temperature!K12 -> 13074.966 | C14: ='Elec str'!B50 -> 10338.992 | D14: =Speed!F13 -> 9267.8797 | E14: =Infrastructure!E14 -> 10947.882 | F14: =Feed!J12 -> 10519.836 | G14: =Best!G15+Temperature!L12 -> 9636.1836 | H14: =Best!H15 -> 7969.8321 | L14: =B14+$J$4 -> 13051.096 | M14: =C14+$J$4 -> 10315.122 | N14: =D14+$J$4 -> 9244.0097 | O14: =E14+$J$4 -> 10924.012 | P14: =F14+$J$4 -> 10495.966 | Q14: =G14+$J$4 -> 9612.3136 | R14: =H14+$J$4 -> 7945.9621
A15: 2031 | B15: =Case!$B$8/Temperature!B13+Temperature!K13 -> 13271.777 | C15: ='Elec str'!B51 -> 10213.287 | D15: =Speed!F14 -> 9115.9472 | E15: =Infrastructure!E15 -> 10933.213 | F15: =Feed!J13 -> 10459.674 | G15: =Best!G16+Temperature!L13 -> 9466.0674 | H15: =Best!H16 -> 7674.8054 | L15: =B15+$J$4 -> 13247.907 | M15: =C15+$J$4 -> 10189.417 | N15: =D15+$J$4 -> 9092.0772 | O15: =E15+$J$4 -> 10909.343 | P15: =F15+$J$4 -> 10435.804 | Q15: =G15+$J$4 -> 9442.1974 | R15: =H15+$J$4 -> 7650.9354
A16: 2032 | B16: =Case!$B$8/Temperature!B14+Temperature!K14 -> 13468.864 | C16: ='Elec str'!B52 -> 10087.581 | D16: =Speed!F15 -> 8968.9158 | E16: =Infrastructure!E16 -> 10918.953 | F16: =Feed!J14 -> 10399.512 | G16: =Best!G17+Temperature!L14 -> 9298.5436 | H16: =Best!H17 -> 7389.6243 | L16: =B16+$J$4 -> 13444.994 | M16: =C16+$J$4 -> 10063.711 | N16: =D16+$J$4 -> 8945.0458 | O16: =E16+$J$4 -> 10895.083 | P16: =F16+$J$4 -> 10375.642 | Q16: =G16+$J$4 -> 9274.6736 | R16: =H16+$J$4 -> 7365.7543
... A34: 2050 | B34: =Case!$B$8/Temperature!B32+Temperature!K32 -> 17067.208 | C34: ='Elec str'!B70 -> 7171.7482 | D34: =Speed!F33 -> 6950.9098 | E34: =Infrastructure!E34 -> 10716.45 | F34: =Feed!J32 -> 9316.5964 | G34: =Best!G35+Temperature!L32 -> 5452.9691 | H34: =Best!H35 -> 3101.1769 | L34: =B34+$J$4 -> 17043.338 | M34: =C34+$J$4 -> 7147.8782 | N34: =D34+$J$4 -> 6927.0398 | O34: =E34+$J$4 -> 10692.58 | P34: =F34+$J$4 -> 9292.7264 | Q34: =G34+$J$4 -> 5429.0991 | R34: =H34+$J$4 -> 3077.3069
C38: error

Sheet Production
G1: 时间 | H1: 鲍鱼（万吨）
A2: 年份 | B2: 南非未来鲍鱼总产量（吨） | G2: 2000 | H2: 0.0181
A3: 2020 | B3: =H22*10000 -> 1976.6 | G3: 2001 | H3: 0.0373
A4: 2021 | B4: =H23*10000 -> 2463.3 | G4: 2002 | H4: 0.0429
A5: 2022 | B5: =H24*10000 -> 2254.7 | G5: 2003 | H5: 0.0515
A6: 2023 | B6: =H25*10000 -> 2356.3486 | G6: 2004 | H6: 0.076
A7: 2024 | B7: =H26*10000 -> 2501.2232 | G7: 2005 | H7: 0.083
A8: 2025 | B8: =H27*10000 -> 2653.3056 | G8: 2006 | H8: 0.0833
A9: 2026 | B9: =H28*10000 -> 2812.9497 | G9: 2007 | H9: 0.0783
A10: 2027 | B10: =H29*10000 -> 2980.5267 | G10: 2008 | H10: 0.1037
A11: 2028 | B11: =H30*10000 -> 3156.4254 | G11: 2009 | H11: 0.0914
A12: 2029 | B12: =H31*10000 -> 3341.0536 | G12: 2010 | H12: 0.1015
A13: 2030 | B13: =H32*10000 -> 3534.8387 | G13: 2011 | H13: 0.1036
A14: 2031 | B14: =H33*10000 -> 3738.2288 | G14: 2012 | H14: 0.11114
... A33: 2050 | B33: =H52*10000 -> 10211.304 | G33: 2031 | H33: 0.37382288
G34: 2032 | H34: 0.39516932
G35: 2033 | H35: 0.41757241
G36: 2034 | H36: 0.44108372
G37: 2035 | H37: 0.46575727
G38: 2036 | H38: 0.49164971
G39: 2037 | H39: 0.51882036
G40: 2038 | H40: 0.54733138
G41: 2039 | H41: 0.57724791
G42: 2040 | H42: 0.60863818
G43: 2041 | H43: 0.64157366
G44: 2042 | H44: 0.67612921
G45: 2043 | H45: 0.71238327
... G52: 2050 | H52: 1.0211304
H53: 1.0742784
H54: 1.1300195

Sheet Error
A1: year | B1: error
A2: 2020 | B2: 4295.7438
A3: 2021 | B3: 4575.6325
A4: 2022 | B4: 4855.5212
A5: 2023 | B5: 5135.4099
A6: 2024 | B6: 5415.2986
A7: 2025 | B7: 5695.1873
A8: 2026 | B8: 6065.8259
A9: 2027 | B9: 6436.4646
A10: 2028 | B10: 6807.1032
A11: 2029 | B11: 7177.7418
A12: 2030 | B12: 7548.3805
A13: 2031 | B13: 7946.9364
... A32: 2050 | B32: 15151.851

Sheet 产业碳足迹
B1: 基准情景 | E1: 能源改进 | H1: 品种优化 | K1: 基建改进 | N1: 饲料替代 | Q1: 最优 (with BG) | T1: 最优 (without BG)
B2: mean | C2: max | D2: min | E2: mean | F2: max | G2: min | H2: mean | I2: max | J2: min | K2: mean | L2: max | M2: min | N2: mean | O2: max | P2: min | Q2: mean | R2: max | S2: min | T2: mean | U2: max | V2: min
A3: 2020 | B3: =单位碳足迹!L4*Production!$B3/1000 -> 21935.488 | C3: =$B3+Error!$B2 -> 26231.232 | D3: =$B3-Error!$B2 -> 17639.744 | E3: =单位碳足迹!M4*Production!$B3/1000 -> 21935.488 | F3: =$E3+Error!$B2 -> 26231.232 | G3: =$E3-Error!$B2 -> 17639.744 | H3: =单位碳足迹!N4*Production!$B3/1000 -> 21935.488 | I3: =$H3+Error!$B2 -> 26231.232 | J3: =$H3-Error!$B2 -> 17639.744 | K3: =单位碳足迹!O4*Production!$B3/1000 -> 21935.488 | L3: =$K3+Error!$B2 -> 26231.232 | M3: =$K3-Error!$B2 -> 17639.744 | N3: =单位碳足迹!P4*Production!$B3/1000 -> 21935.488 | O3: =$N3+Error!$B2 -> 26231.232 | P3: =$N3-Error!$B2 -> 17639.744 | Q3: =单位碳足迹!Q4*Production!$B3/1000 -> 21935.488 | R3: =$Q3+Error!$B2 -> 26231.232 | S3: =$Q3-Error!$B2 -> 17639.744 | T3: =单位碳足迹!R4*Production!$B3/1000 -> 21935.488 | U3: =$T3+Error!$B2 -> 26231.232 | V3: =$T3-Error!$B2 -> 17639.744
A4: 2021 | B4: =单位碳足迹!L5*Production!$B4/1000 -> 27815.047 | C4: =$B4+Error!$B3 -> 32390.68 | D4: =$B4-Error!$B3 -> 23239.415 | E4: =单位碳足迹!M5*Production!$B4/1000 -> 27143.938 | F4: =$E4+Error!$B3 -> 31719.571 | G4: =$E4-Error!$B3 -> 22568.306 | H4: =单位碳足迹!N5*Production!$B4/1000 -> 26799.516 | I4: =$H4+Error!$B3 -> 31375.149 | J4: =$H4-Error!$B3 -> 22223.884 | K4: =单位碳足迹!O5*Production!$B4/1000 -> 27287.618 | L4: =$K4+Error!$B3 -> 31863.25 | M4: =$K4-Error!$B3 -> 22711.985 | N4: =单位碳足迹!P5*Production!$B4/1000 -> 27188.486 | O4: =$N4+Error!$B3 -> 31764.118 | P4: =$N4-Error!$B3 -> 22612.853 | Q4: =单位碳足迹!Q5*Production!$B4/1000 -> 26888.05 | R4: =$Q4+Error!$B3 -> 31463.683 | S4: =$Q4-Error!$B3 -> 22312.418 | T4: =单位碳足迹!R5*Production!$B4/1000 -> 26417.158 | U4: =$T4+Error!$B3 -> 30992.79 | V4: =$T4-Error!$B3 -> 21841.525
A5: 2022 | B5: =单位碳足迹!L6*Production!$B5/1000 -> 25898 | C5: =$B5+Error!$B4 -> 30753.521 | D5: =$B5-Error!$B4 -> 21042.478 | E5: =单位碳足迹!M6*Production!$B5/1000 -> 24668.882 | F5: =$E5+Error!$B4 -> 29524.404 | G5: =$E5-Error!$B4 -> 19813.361 | H5: =单位碳足迹!N6*Production!$B5/1000 -> 24057.282 | I5: =$H5+Error!$B4 -> 28912.803 | J5: =$H5-Error!$B4 -> 19201.761 | K5: =单位碳足迹!O6*Production!$B5/1000 -> 24933.355 | L5: =$K5+Error!$B4 -> 29788.877 | M5: =$K5-Error!$B4 -> 20077.834 | N5: =单位碳足迹!P6*Production!$B5/1000 -> 24750.432 | O5: =$N5+Error!$B4 -> 29605.953 | P5: =$N5-Error!$B4 -> 19894.911 | Q5: =单位碳足迹!Q6*Production!$B5/1000 -> 24221.283 | R5: =$Q5+Error!$B4 -> 29076.804 | S5: =$Q5-Error!$B4 -> 19365.761 | T5: =单位碳足迹!R6*Production!$B5/1000 -> 23372.177 | U5: =$T5+Error!$B4 -> 28227.698 | V5: =$T5-Error!$B4 -> 18516.656
A6: 2023 | B6: =单位碳足迹!L7*Production!$B6/1000 -> 27524.337 | C6: =$B6+Error!$B5 -> 32659.746 | D6: =$B6-Error!$B5 -> 22388.927 | E6: =单位碳足迹!M7*Production!$B6/1000 -> 25596.654 | F6: =$E6+Error!$B5 -> 30732.064 | G6: =$E6-Error!$B5 -> 20461.244 | H6: =单位碳足迹!N7*Production!$B6/1000 -> 24666.421 | I6: =$H6+Error!$B5 -> 29801.831 | J6: =$H6-Error!$B5 -> 19531.011 | K6: =单位碳足迹!O7*Production!$B6/1000 -> 26013.447 | L6: =$K6+Error!$B5 -> 31148.857 | M6: =$K6-Error!$B5 -> 20878.037 | N6: =单位碳足迹!P7*Production!$B6/1000 -> 25724.493 | O6: =$N6+Error!$B5 -> 30859.903 | P6: =$N6-Error!$B5 -> 20589.083 | Q6: =单位碳足迹!Q7*Production!$B6/1000 -> 24925.87 | R6: =$Q6+Error!$B5 -> 30061.28 | S6: =$Q6-Error!$B5 -> 19790.46 | T6: =单位碳足迹!R7*Production!$B6/1000 -> 23614.771 | U6: =$T6+Error!$B5 -> 28750.181 | V6: =$T6-Error!$B5 -> 18479.361
A7: 2024 | B7: =单位碳足迹!L8*Production!$B7/1000 -> 29704.228 | C7: =$B7+Error!$B6 -> 35119.526 | D7: =$B7-Error!$B6 -> 24288.929 | E7: =单位碳足迹!M8*Production!$B7/1000 -> 26974.693 | F7: =$E7+Error!$B6 -> 32389.991 | G7: =$E7-Error!$B6 -> 21559.394 | H7: =单位碳足迹!N8*Production!$B7/1000 -> 25697.002 | I7: =$H7+Error!$B6 -> 31112.301 | J7: =$H7-Error!$B6 -> 20281.704 | K7: =单位碳足迹!O8*Production!$B7/1000 -> 27567.6 | L7: =$K7+Error!$B6 -> 32982.898 | M7: =$K7-Error!$B6 -> 22152.301 | N7: =单位碳足迹!P8*Production!$B7/1000 -> 27155.625 | O7: =$N7+Error!$B6 -> 32570.923 | P7: =$N7-Error!$B6 -> 21740.326 | Q7: =单位碳足迹!Q8*Production!$B7/1000 -> 26066.659 | R7: =$Q7+Error!$B6 -> 31481.958 | S7: =$Q7-Error!$B6 -> 20651.361 | T7: =单位碳足迹!R8*Production!$B7/1000 -> 24238.947 | U7: =$T7+Error!$B6 -> 29654.246 | V7: =$T7-Error!$B6 -> 18823.648
A8: 2025 | B8: =单位碳足迹!L9*Production!$B8/1000 -> 32028.293 | C8: =$B8+Error!$B7 -> 37723.48 | D8: =$B8-Error!$B7 -> 26333.106 | E8: =单位碳足迹!M9*Production!$B8/1000 -> 28407.229 | F8: =$E8+Error!$B7 -> 34102.416 | G8: =$E8-Error!$B7 -> 22712.042 | H8: =单位碳足迹!N9*Production!$B8/1000 -> 26762.684 | I8: =$H8+Error!$B7 -> 32457.872 | J8: =$H8-Error!$B7 -> 21067.497 | K8: =单位碳足迹!O9*Production!$B8/1000 -> 29197.301 | L8: =$K8+Error!$B7 -> 34892.488 | M8: =$K8-Error!$B7 -> 23502.113 | N8: =单位碳足迹!P9*Production!$B8/1000 -> 28647.146 | O8: =$N8+Error!$B7 -> 34342.333 | P8: =$N8-Error!$B7 -> 22951.958 | Q8: =单位碳足迹!Q9*Production!$B8/1000 -> 27255.005 | R8: =$Q8+Error!$B7 -> 32950.193 | S8: =$Q8-Error!$B7 -> 21559.818 | T8: =单位碳足迹!R9*Production!$B8/1000 -> 24867.972 | U8: =$T8+Error!$B7 -> 30563.16 | V8: =$T8-Error!$B7 -> 19172.785
A9: 2026 | B9: =单位碳足迹!L10*Production!$B9/1000 -> 34505.22 | C9: =$B9+Error!$B8 -> 40571.046 | D9: =$B9-Error!$B8 -> 28439.394 | E9: =单位碳足迹!M10*Production!$B9/1000 -> 29896.333 | F9: =$E9+Error!$B8 -> 35962.158 | G9: =$E9-Error!$B8 -> 23830.507 | H9: =单位碳足迹!N10*Production!$B9/1000 -> 27865.083 | I9: =$H9+Error!$B8 -> 33930.909 | J9: =$H9-Error!$B8 -> 21799.257 | K9: =单位碳足迹!O10*Production!$B9/1000 -> 30906.243 | L9: =$K9+Error!$B8 -> 36972.069 | M9: =$K9-Error!$B8 -> 24840.417 | N9: =单位碳足迹!P10*Production!$B9/1000 -> 30201.555 | O9: =$N9+Error!$B8 -> 36267.381 | P9: =$N9-Error!$B8 -> 24135.729 | Q9: =单位碳足迹!Q10*Production!$B9/1000 -> 28492.834 | R9: =$Q9+Error!$B8 -> 34558.66 | S9: =$Q9-Error!$B8 -> 22427.008 | T9: =单位碳足迹!R10*Production!$B9/1000 -> 25501.939 | U9: =$T9+Error!$B8 -> 31567.765 | V9: =$T9-Error!$B8 -> 19436.113
A10: 2027 | B10: =单位碳足迹!L11*Production!$B10/1000 -> 37144.2 | C10: =$B10+Error!$B9 -> 43580.665 | D10: =$B10-Error!$B9 -> 30707.735 | E10: =单位碳足迹!M11*Production!$B10/1000 -> 31444.143 | F10: =$E10+Error!$B9 -> 37880.607 | G10: =$E10-Error!$B9 -> 25007.678 | H10: =单位碳足迹!N11*Production!$B10/1000 -> 29005.868 | I10: =$H10+Error!$B9 -> 35442.333 | J10: =$H10-Error!$B9 -> 22569.403 | K10: =单位碳足迹!O11*Production!$B10/1000 -> 32698.295 | L10: =$K10+Error!$B9 -> 39134.76 | M10: =$K10-Error!$B9 -> 26261.831 | N10: =单位碳足迹!P11*Production!$B10/1000 -> 31821.449 | O10: =$N10+Error!$B9 -> 38257.914 | P10: =$N10-Error!$B9 -> 25384.985 | Q10: =单位碳足迹!Q11*Production!$B10/1000 -> 29782.085 | R10: =$Q10+Error!$B9 -> 36218.55 | S10: =$Q10-Error!$B9 -> 23345.621 | T10: =单位碳足迹!R11*Production!$B10/1000 -> 26140.901 | U10: =$T10+Error!$B9 -> 32577.366 | V10: =$T10-Error!$B9 -> 19704.437
A11: 2028 | B11: =单位碳足迹!L12*Production!$B11/1000 -> 39954.955 | C11: =$B11+Error!$B10 -> 46762.059 | D11: =$B11-Error!$B10 -> 33147.852 | E11: =单位碳足迹!M12*Production!$B11/1000 -> 33052.871 | F11: =$E11+Error!$B10 -> 39859.974 | G11: =$E11-Error!$B10 -> 26245.768 | H11: =单位碳足迹!N12*Production!$B11/1000 -> 30186.764 | I11: =$H11+Error!$B10 -> 36993.867 | J11: =$H11-Error!$B10 -> 23379.66 | K11: =单位碳足迹!O12*Production!$B11/1000 -> 34577.511 | L11: =$K11+Error!$B10 -> 41384.614 | M11: =$K11-Error!$B10 -> 27770.408 | N11: =单位碳足迹!P12*Production!$B11/1000 -> 33509.527 | O11: =$N11+Error!$B10 -> 40316.63 | P11: =$N11-Error!$B10 -> 26702.423 | Q11: =单位碳足迹!Q12*Production!$B11/1000 -> 31124.715 | R11: =$Q11+Error!$B10 -> 37931.818 | S11: =$Q11-Error!$B10 -> 24317.612 | T11: =单位碳足迹!R12*Production!$B11/1000 -> 26784.872 | U11: =$T11+Error!$B10 -> 33591.976 | V11: =$T11-Error!$B10 -> 19977.769
A12: 2029 | B12: =单位碳足迹!L13*Production!$B12/1000 -> 42947.77 | C12: =$B12+Error!$B11 -> 50125.512 | D12: =$B12-Error!$B11 -> 35770.028 | E12: =单位碳足迹!M13*Production!$B12/1000 -> 34724.802 | F12: =$E12+Error!$B11 -> 41902.543 | G12: =$E12-Error!$B11 -> 27547.06 | H12: =单位碳足迹!N13*Production!$B12/1000 -> 31409.554 | I12: =$H12+Error!$B11 -> 38587.295 | J12: =$H12-Error!$B11 -> 24231.812 | K12: =单位碳足迹!O13*Production!$B12/1000 -> 36548.136 | L12: =$K12+Error!$B11 -> 43725.878 | M12: =$K12-Error!$B11 -> 29370.394 | N12: =单位碳足迹!P13*Production!$B12/1000 -> 35268.589 | O12: =$N12+Error!$B11 -> 42446.331 | P12: =$N12-Error!$B11 -> 28090.847 | Q12: =单位碳足迹!Q13*Production!$B12/1000 -> 32522.688 | R12: =$Q12+Error!$B11 -> 39700.43 | S12: =$Q12-Error!$B11 -> 25344.946 | T12: =单位碳足迹!R13*Production!$B12/1000 -> 27433.826 | U12: =$T12+Error!$B11 -> 34611.568 | V12: =$T12-Error!$B11 -> 20256.084
A13: 2030 | B13: =单位碳足迹!L14*Production!$B13/1000 -> 46133.519 | C13: =$B13+Error!$B12 -> 53681.9 | D13: =$B13-Error!$B12 -> 38585.139 | E13: =单位碳足迹!M14*Production!$B13/1000 -> 36462.294 | F13: =$E13+Error!$B12 -> 44010.674 | G13: =$E13-Error!$B12 -> 28913.913 | H13: =单位碳足迹!N14*Production!$B13/1000 -> 32676.084 | I13: =$H13+Error!$B12 -> 40224.464 | J13: =$H13-Error!$B12 -> 25127.703 | K13: =单位碳足迹!O14*Production!$B13/1000 -> 38614.62 | L13: =$K13+Error!$B12 -> 46163 | M13: =$K13-Error!$B12 -> 31066.239 | N13: =单位碳足迹!P14*Production!$B13/1000 -> 37101.547 | O13: =$N13+Error!$B12 -> 44649.927 | P13: =$N13-Error!$B12 -> 29553.166 | Q13: =单位碳足迹!Q14*Production!$B13/1000 -> 33977.978 | R13: =$Q13+Error!$B12 -> 41526.359 | S13: =$Q13-Error!$B12 -> 26429.598 | T13: =单位碳足迹!R14*Production!$B13/1000 -> 28087.695 | U13: =$T13+Error!$B12 -> 35636.075 | V13: =$T13-Error!$B12 -> 20539.314
A14: 2031 | B14: =单位碳足迹!L15*Production!$B14/1000 -> 49523.705 | C14: =$B14+Error!$B13 -> 57470.642 | D14: =$B14-Error!$B13 -> 41576.769 | E14: =单位碳足迹!M15*Production!$B14/1000 -> 38090.37 | F14: =$E14+Error!$B13 -> 46037.306 | G14: =$E14-Error!$B13 -> 30143.434 | H14: =单位碳足迹!N15*Production!$B14/1000 -> 33988.265 | I14: =$H14+Error!$B13 -> 41935.201 | J14: =$H14-Error!$B13 -> 26041.328 | K14: =单位碳足迹!O15*Production!$B14/1000 -> 40781.622 | L14: =$K14+Error!$B13 -> 48728.558 | M14: =$K14-Error!$B13 -> 32834.685 | N14: =单位碳足迹!P15*Production!$B14/1000 -> 39011.422 | O14: =$N14+Error!$B13 -> 46958.359 | P14: =$N14-Error!$B13 -> 31064.486 | Q14: =单位碳足迹!Q15*Production!$B14/1000 -> 35297.094 | R14: =$Q14+Error!$B13 -> 43244.03 | S14: =$Q14-Error!$B13 -> 27350.158 | T14: =单位碳足迹!R15*Production!$B14/1000 -> 28600.947 | U14: =$T14+Error!$B13 -> 36547.883 | V14: =$T14-Error!$B13 -> 20654.01
... A33: 2050 | B33: =单位碳足迹!L34*Production!$B33/1000 -> 174034.71 | C33: =$B33+Error!$B32 -> 189186.56 | D33: =$B33-Error!$B32 -> 158882.86 | E33: =单位碳足迹!M34*Production!$B33/1000 -> 72989.159 | F33: =$E33+Error!$B32 -> 88141.011 | G33: =$E33-Error!$B32 -> 57837.308 | H33: =单位碳足迹!N34*Production!$B33/1000 -> 70734.11 | I33: =$H33+Error!$B32 -> 85885.962 | J33: =$H33-Error!$B32 -> 55582.259 | K33: =单位碳足迹!O34*Production!$B33/1000 -> 109185.18 | L33: =$K33+Error!$B32 -> 124337.04 | M33: =$K33-Error!$B32 -> 94033.333 | N33: =单位碳足迹!P34*Production!$B33/1000 -> 94890.856 | O33: =$N33+Error!$B32 -> 110042.71 | P33: =$N33-Error!$B32 -> 79739.005 | Q33: =单位碳足迹!Q34*Production!$B33/1000 -> 55438.183 | R33: =$Q33+Error!$B32 -> 70590.034 | S33: =$Q33-Error!$B32 -> 40286.331 | T33: =单位碳足迹!R34*Production!$B33/1000 -> 31423.317 | U33: =$T33+Error!$B32 -> 46575.168 | V33: =$T33-Error!$B32 -> 16271.466

Sheet Fig 4c1
B1: BAU | E1: P1 | H1: P3 | K1: P4 | N1: P5 | Q1: Best (with BG) | T1: Best (without BG)
B2: mean | C2: max | D2: min | E2: mean | F2: max | G2: min | H2: mean | I2: max | J2: min | K2: mean | L2: max | M2: min | N2: mean | O2: max | P2: min | Q2: mean | R2: max | S2: min | T2: mean | U2: max | V2: min
A3: 2020 | B3: =产业碳足迹!B3 -> 21935.488 | C3: =产业碳足迹!C3 -> 26231.232 | D3: =产业碳足迹!D3 -> 17639.744 | E3: =产业碳足迹!E3 -> 21935.488 | F3: =产业碳足迹!F3 -> 26231.232 | G3: =产业碳足迹!G3 -> 17639.744 | H3: =产业碳足迹!H3 -> 21935.488 | I3: =产业碳足迹!I3 -> 26231.232 | ... V3: =产业碳足迹!V3 -> 17639.744
