Workbook

Sheet Case
A1: Ext-1 (South Korea)
A2: Feed | B2: =G2+G3 -> 312.00852 | E2: Feed | F2: Compound feed | G2: 179.14852
A3: Energy | B3: 523.05345 | F3: Seaweed | G3: 132.86
A4: Infrastructure | B4: 428.36624
A5: Equipment | B5: 10.110046
A6: Transport | B6: 92.45
A8: CF (without macroalgae) | B8: =SUM(B2:B7) -> 1365.9883
B10: CF | C10: Input
A11: Electricity | B11: =B3 -> 523.05345 | C11: =B11/'Elec str'!H3 -> 833.2517
A12: Apart from electricity | B12: =B8-B11 -> 842.93481
A13: Infrastructure | B13: =B4 -> 428.36624
A14: Apart from infrastructure | B14: =B8-B13 -> 937.62202
A15: Apart from electricity & infrastructure | B15: =B8-B11-B13 -> 414.56857

Sheet Temperature
B1: Non-genetically improved
A2: 2020 | B2: 1 | D2: =(B32-B2)/($A$32-$A$2) -> -0.0033333333
A3: 2021 | B3: =B2+D$2 -> 0.99666667
A4: 2022 | B4: =B3+D$2 -> 0.99333333
A5: 2023 | B5: =B4+D$2 -> 0.99
A6: 2024 | B6: =B5+D$2 -> 0.98666667
A7: 2025 | B7: =B6+D$2 -> 0.98333333
A8: 2026 | B8: =B7+D$2 -> 0.98
A9: 2027 | B9: =B8+D$2 -> 0.97666667
A10: 2028 | B10: =B9+D$2 -> 0.97333333
A11: 2029 | B11: =B10+D$2 -> 0.97
A12: 2030 | B12: =B11+D$2 -> 0.96666667
A13: 2031 | B13: =B12+D$2 -> 0.96333333
A14: 2032 | B14: =B13+D$2 -> 0.96
... A31: 2049 | B31: =B30+D$2 -> 0.90333333
A32: 2050 | B32: 0.9

Sheet Baseline
A1: With CC | B1: CF of 1t abalone (LW)
B2: mean | C2: max | D2: min
A3: 2020 | B3: =Case!$B$8/Temperature!B2 -> 1365.9883
A4: 2021 | B4: =Case!$B$8/Temperature!B3 -> 1370.5568
A5: 2022 | B5: =Case!$B$8/Temperature!B4 -> 1375.156
A6: 2023 | B6: =Case!$B$8/Temperature!B5 -> 1379.7861
A7: 2024 | B7: =Case!$B$8/Temperature!B6 -> 1384.4476
A8: 2025 | B8: =Case!$B$8/Temperature!B7 -> 1389.1406
A9: 2026 | B9: =Case!$B$8/Temperature!B8 -> 1393.8656
A10: 2027 | B10: =Case!$B$8/Temperature!B9 -> 1398.6228
A11: 2028 | B11: =Case!$B$8/Temperature!B10 -> 1403.4126
A12: 2029 | B12: =Case!$B$8/Temperature!B11 -> 1408.2353
A13: 2030 | B13: =Case!$B$8/Temperature!B12 -> 1413.0913
A14: 2031 | B14: =Case!$B$8/Temperature!B13 -> 1417.9809
... A33: 2050 | B33: =Case!$B$8/Temperature!B32 -> 1517.7647

Sheet Elec str
B1: 0.00619 | C1: 0.09633 | D1: 0.02669 | E1: 0.00437 | F1: 1.14634 | G1: 0.69835
B2: Nuclear | C2: Photovoltaic | D2: Wind | E2: Hydro | F2: Fossil | G2: Gasoline | H2: CF of 1 kwh
A3: 2020 | B3: 0.29 | C3: 0.032 | D3: 0.006 | E3: 0.012 | F3: 0.361 | G3: 0.299 | H3: =B3*$B$1+C3*$C$1+D3*$D$1+E3*$E$1+F3*$F$1+G3*$G$1 -> 0.62772563 | I3: Nuclear | J3: Photovoltaic | K3: Wind | L3: Hydro | M3: Fossil | N3: Gasoline
A4: 2021 | B4: =B3+I$4 -> 0.29033333 | C4: =C3+J$4 -> 0.0426 | D4: =D3+K$4 -> 0.014133333 | E4: =E3+L$4 -> 0.012433333 | F4: =F3+M$4 -> 0.34896667 | G4: =G3+N$4 -> 0.29153333 | H4: =B4*$B$1+C4*$C$1+D4*$D$1+E4*$E$1+F4*$F$1+G4*$G$1 -> 0.60995913 | I4: =(B33-B3)/($A$33-$A$3) -> 0.00033333333 | J4: =(C33-C3)/($A$33-$A$3) -> 0.0106 | K4: =(D33-D3)/($A$33-$A$3) -> 0.0081333333 | L4: =(E33-E3)/($A$33-$A$3) -> 0.00043333333 | M4: =(F33-F3)/($A$33-$A$3) -> -0.012033333 | N4: =(G33-G3)/($A$33-$A$3) -> -0.0074666667
A5: 2022 | B5: =B4+I$4 -> 0.29066667 | C5: =C4+J$4 -> 0.0532 | D5: =D4+K$4 -> 0.022266667 | E5: =E4+L$4 -> 0.012866667 | F5: =F4+M$4 -> 0.33693333 | G5: =G4+N$4 -> 0.28406667 | H5: =B5*$B$1+C5*$C$1+D5*$D$1+E5*$E$1+F5*$F$1+G5*$G$1 -> 0.59219262
A6: 2023 | B6: =B5+I$4 -> 0.291 | C6: =C5+J$4 -> 0.0638 | D6: =D5+K$4 -> 0.0304 | E6: =E5+L$4 -> 0.0133 | F6: =F5+M$4 -> 0.3249 | G6: =G5+N$4 -> 0.2766 | H6: =B6*$B$1+C6*$C$1+D6*$D$1+E6*$E$1+F6*$F$1+G6*$G$1 -> 0.57442612
A7: 2024 | B7: =B6+I$4 -> 0.29133333 | C7: =C6+J$4 -> 0.0744 | D7: =D6+K$4 -> 0.038533333 | E7: =E6+L$4 -> 0.013733333 | F7: =F6+M$4 -> 0.31286667 | G7: =G6+N$4 -> 0.26913333 | H7: =B7*$B$1+C7*$C$1+D7*$D$1+E7*$E$1+F7*$F$1+G7*$G$1 -> 0.55665961
A8: 2025 | B8: =B7+I$4 -> 0.29166667 | C8: =C7+J$4 -> 0.085 | D8: =D7+K$4 -> 0.046666667 | E8: =E7+L$4 -> 0.014166667 | F8: =F7+M$4 -> 0.30083333 | G8: =G7+N$4 -> 0.26166667 | H8: =B8*$B$1+C8*$C$1+D8*$D$1+E8*$E$1+F8*$F$1+G8*$G$1 -> 0.53889311
A9: 2026 | B9: =B8+I$4 -> 0.292 | C9: =C8+J$4 -> 0.0956 | D9: =D8+K$4 -> 0.0548 | E9: =E8+L$4 -> 0.0146 | F9: =F8+M$4 -> 0.2888 | G9: =G8+N$4 -> 0.2542 | H9: =B9*$B$1+C9*$C$1+D9*$D$1+E9*$E$1+F9*$F$1+G9*$G$1 -> 0.5211266
A10: 2027 | B10: =B9+I$4 -> 0.29233333 | C10: =C9+J$4 -> 0.1062 | D10: =D9+K$4 -> 0.062933333 | E10: =E9+L$4 -> 0.015033333 | F10: =F9+M$4 -> 0.27676667 | G10: =G9+N$4 -> 0.24673333 | H10: =B10*$B$1+C10*$C$1+D10*$D$1+E10*$E$1+F10*$F$1+G10*$G$1 -> 0.5033601 | K10: South Korea
A11: 2028 | B11: =B10+I$4 -> 0.29266667 | C11: =C10+J$4 -> 0.1168 | D11: =D10+K$4 -> 0.071066667 | E11: =E10+L$4 -> 0.015466667 | F11: =F10+M$4 -> 0.26473333 | G11: =G10+N$4 -> 0.23926667 | H11: =B11*$B$1+C11*$C$1+D11*$D$1+E11*$E$1+F11*$F$1+G11*$G$1 -> 0.4855936 | K11: Nuclear | L11: Photovoltaic | M11: Wind | N11: Hydro | O11: Fossil | P11: Gasoline
A12: 2029 | B12: =B11+I$4 -> 0.293 | C12: =C11+J$4 -> 0.1274 | D12: =D11+K$4 -> 0.0792 | E12: =E11+L$4 -> 0.0159 | F12: =F11+M$4 -> 0.2527 | G12: =G11+N$4 -> 0.2318 | H12: =B12*$B$1+C12*$C$1+D12*$D$1+E12*$E$1+F12*$F$1+G12*$G$1 -> 0.46782709 | J12: 2020 | K12: 0.29 | L12: 0.032 | M12: 0.006 | N12: 0.012 | O12: 0.361 | P12: 0.299
A13: 2030 | B13: =B12+I$4 -> 0.29333333 | C13: =C12+J$4 -> 0.138 | D13: =D12+K$4 -> 0.087333333 | E13: =E12+L$4 -> 0.016333333 | F13: =F12+M$4 -> 0.24066667 | G13: =G12+N$4 -> 0.22433333 | H13: =B13*$B$1+C13*$C$1+D13*$D$1+E13*$E$1+F13*$F$1+G13*$G$1 -> 0.45006059 | J13: 2050 | K13: 0.3 | L13: 0.35 | M13: 0.25 | N13: 0.025 | O13: 0 | P13: 0.075
A14: 2031 | B14: =B13+I$4 -> 0.29366667 | C14: =C13+J$4 -> 0.1486 | D14: =D13+K$4 -> 0.095466667 | E14: =E13+L$4 -> 0.016766667 | F14: =F13+M$4 -> 0.22863333 | G14: =G13+N$4 -> 0.21686667 | H14: =B14*$B$1+C14*$C$1+D14*$D$1+E14*$E$1+F14*$F$1+G14*$G$1 -> 0.43229408
A15: 2032 | B15: =B14+I$4 -> 0.294 | C15: =C14+J$4 -> 0.1592 | D15: =D14+K$4 -> 0.1036 | E15: =E14+L$4 -> 0.0172 | F15: =F14+M$4 -> 0.2166 | G15: =G14+N$4 -> 0.2094 | H15: =B15*$B$1+C15*$C$1+D15*$D$1+E15*$E$1+F15*$F$1+G15*$G$1 -> 0.41452758
A16: 2033 | B16: =B15+I$4 -> 0.29433333 | C16: =C15+J$4 -> 0.1698 | D16: =D15+K$4 -> 0.11173333 | E16: =E15+L$4 -> 0.017633333 | F16: =F15+M$4 -> 0.20456667 | G16: =G15+N$4 -> 0.20193333 | H16: =B16*$B$1+C16*$C$1+D16*$D$1+E16*$E$1+F16*$F$1+G16*$G$1 -> 0.39676107
A17: 2034 | B17: =B16+I$4 -> 0.29466667 | C17: =C16+J$4 -> 0.1804 | D17: =D16+K$4 -> 0.11986667 | E17: =E16+L$4 -> 0.018066667 | F17: =F16+M$4 -> 0.19253333 | G17: =G16+N$4 -> 0.19446667 | H17: =B17*$B$1+C17*$C$1+D17*$D$1+E17*$E$1+F17*$F$1+G17*$G$1 -> 0.37899457
A18: 2035 | B18: =B17+I$4 -> 0.295 | C18: =C17+J$4 -> 0.191 | D18: =D17+K$4 -> 0.128 | E18: =E17+L$4 -> 0.0185 | F18: =F17+M$4 -> 0.1805 | G18: =G17+N$4 -> 0.187 | H18: =B18*$B$1+C18*$C$1+D18*$D$1+E18*$E$1+F18*$F$1+G18*$G$1 -> 0.36122806
A19: 2036 | B19: =B18+I$4 -> 0.29533333 | C19: =C18+J$4 -> 0.2016 | D19: =D18+K$4 -> 0.13613333 | E19: =E18+L$4 -> 0.018933333 | F19: =F18+M$4 -> 0.16846667 | G19: =G18+N$4 -> 0.17953333 | H19: =B19*$B$1+C19*$C$1+D19*$D$1+E19*$E$1+F19*$F$1+G19*$G$1 -> 0.34346156
A20: 2037 | B20: =B19+I$4 -> 0.29566667 | C20: =C19+J$4 -> 0.2122 | D20: =D19+K$4 -> 0.14426667 | E20: =E19+L$4 -> 0.019366667 | F20: =F19+M$4 -> 0.15643333 | G20: =G19+N$4 -> 0.17206667 | H20: =B20*$B$1+C20*$C$1+D20*$D$1+E20*$E$1+F20*$F$1+G20*$G$1 -> 0.32569506
A21: 2038 | B21: =B20+I$4 -> 0.296 | C21: =C20+J$4 -> 0.2228 | D21: =D20+K$4 -> 0.1524 | E21: =E20+L$4 -> 0.0198 | F21: =F20+M$4 -> 0.1444 | G21: =G20+N$4 -> 0.1646 | H21: =B21*$B$1+C21*$C$1+D21*$D$1+E21*$E$1+F21*$F$1+G21*$G$1 -> 0.30792855
A22: 2039 | B22: =B21+I$4 -> 0.29633333 | C22: =C21+J$4 -> 0.2334 | D22: =D21+K$4 -> 0.16053333 | E22: =E21+L$4 -> 0.020233333 | F22: =F21+M$4 -> 0.13236667 | G22: =G21+N$4 -> 0.15713333 | H22: =B22*$B$1+C22*$C$1+D22*$D$1+E22*$E$1+F22*$F$1+G22*$G$1 -> 0.29016205
A23: 2040 | B23: =B22+I$4 -> 0.29666667 | C23: =C22+J$4 -> 0.244 | D23: =D22+K$4 -> 0.16866667 | E23: =E22+L$4 -> 0.020666667 | F23: =F22+M$4 -> 0.12033333 | G23: =G22+N$4 -> 0.14966667 | H23: =B23*$B$1+C23*$C$1+D23*$D$1+E23*$E$1+F23*$F$1+G23*$G$1 -> 0.27239554
A24: 2041 | B24: =B23+I$4 -> 0.297 | C24: =C23+J$4 -> 0.2546 | D24: =D23+K$4 -> 0.1768 | E24: =E23+L$4 -> 0.0211 | F24: =F23+M$4 -> 0.1083 | G24: =G23+N$4 -> 0.1422 | H24: =B24*$B$1+C24*$C$1+D24*$D$1+E24*$E$1+F24*$F$1+G24*$G$1 -> 0.25462904
A25: 2042 | B25: =B24+I$4 -> 0.29733333 | C25: =C24+J$4 -> 0.2652 | D25: =D24+K$4 -> 0.18493333 | E25: =E24+L$4 -> 0.021533333 | F25: =F24+M$4 -> 0.096266667 | G25: =G24+N$4 -> 0.13473333 | H25: =B25*$B$1+C25*$C$1+D25*$D$1+E25*$E$1+F25*$F$1+G25*$G$1 -> 0.23686253
... A32: 2049 | B32: =B31+I$4 -> 0.29966667 | C32: =C31+J$4 -> 0.3394 | D32: =D31+K$4 -> 0.24186667 | E32: =E31+L$4 -> 0.024566667 | F32: =F31+M$4 -> 0.012033333 | G32: =G31+N$4 -> 0.082466667 | H32: =B32*$B$1+C32*$C$1+D32*$D$1+E32*$E$1+F32*$F$1+G32*$G$1 -> 0.112497
A33: 2050 | B33: 0.3 | C33: 0.35 | D33: 0.25 | E33: 0.025 | F33: 0 | G33: 0.075 | H33: =B33*$B$1+C33*$C$1+D33*$D$1+E33*$E$1+F33*$F$1+G33*$G$1 -> 0.0947305
B38: CF of 1t abalone (LW) | G38: With CC
B39: mean | G39: mean
A40: 2020 | B40: =H3*Case!$C$11+Case!$B$12 -> 1365.9883 | F40: 2020 | G40: =B40/Temperature!B2 -> 1365.9883
A41: 2021 | B41: =H4*Case!$C$11+Case!$B$12 -> 1351.1843 | F41: 2021 | G41: =B41/Temperature!B3 -> 1355.7033
A42: 2022 | B42: =H5*Case!$C$11+Case!$B$12 -> 1336.3803 | F42: 2022 | G42: =B42/Temperature!B4 -> 1345.3493
A43: 2023 | B43: =H6*Case!$C$11+Case!$B$12 -> 1321.5763 | F43: 2023 | G43: =B43/Temperature!B5 -> 1334.9256
A44: 2024 | B44: =H7*Case!$C$11+Case!$B$12 -> 1306.7724 | F44: 2024 | G44: =B44/Temperature!B6 -> 1324.4315
A45: 2025 | B45: =H8*Case!$C$11+Case!$B$12 -> 1291.9684 | F45: 2025 | G45: =B45/Temperature!B7 -> 1313.8662
A46: 2026 | B46: =H9*Case!$C$11+Case!$B$12 -> 1277.1644 | F46: 2026 | G46: =B46/Temperature!B8 -> 1303.229
A47: 2027 | B47: =H10*Case!$C$11+Case!$B$12 -> 1262.3605 | F47: 2027 | G47: =B47/Temperature!B9 -> 1292.5192
A48: 2028 | B48: =H11*Case!$C$11+Case!$B$12 -> 1247.5565 | F48: 2028 | G48: =B48/Temperature!B10 -> 1281.7361
A49: 2029 | B49: =H12*Case!$C$11+Case!$B$12 -> 1232.7525 | F49: 2029 | G49: =B49/Temperature!B11 -> 1270.8789
A50: 2030 | B50: =H13*Case!$C$11+Case!$B$12 -> 1217.9486 | F50: 2030 | G50: =B50/Temperature!B12 -> 1259.9468
...

Sheet Speed
K1: With CC
F2: mean | K2: mean
A3: 2020 | B3: 1 | C3: =(B13-B3)/(A13-A3) -> 0.02 | E3: 2020 | F3: =Case!$B$8/Speed!B3 -> 1365.9883 | J3: 2020 | K3: =Speed!F3/Temperature!B2 -> 1365.9883
A4: 2021 | B4: =B3+$C$3 -> 1.02 | E4: 2021 | F4: =Case!$B$8/Speed!B4 -> 1339.2042 | J4: 2021 | K4: =Speed!F4/Temperature!B3 -> 1343.6831
A5: 2022 | B5: =B4+$C$3 -> 1.04 | E5: 2022 | F5: =Case!$B$8/Speed!B5 -> 1313.4502 | J5: 2022 | K5: =Speed!F5/Temperature!B4 -> 1322.2653
A6: 2023 | B6: =B5+$C$3 -> 1.06 | E6: 2023 | F6: =Case!$B$8/Speed!B6 -> 1288.6682 | J6: 2023 | K6: =Speed!F6/Temperature!B5 -> 1301.685
A7: 2024 | B7: =B6+$C$3 -> 1.08 | E7: 2024 | F7: =Case!$B$8/Speed!B7 -> 1264.8039 | J7: 2024 | K7: =Speed!F7/Temperature!B6 -> 1281.8959
A8: 2025 | B8: =B7+$C$3 -> 1.1 | E8: 2025 | F8: =Case!$B$8/Speed!B8 -> 1241.8075 | J8: 2025 | K8: =Speed!F8/Temperature!B7 -> 1262.8551
A9: 2026 | B9: =B8+$C$3 -> 1.12 | E9: 2026 | F9: =Case!$B$8/Speed!B9 -> 1219.6324 | J9: 2026 | K9: =Speed!F9/Temperature!B8 -> 1244.5228
A10: 2027 | B10: =B9+$C$3 -> 1.14 | E10: 2027 | F10: =Case!$B$8/Speed!B10 -> 1198.2353 | J10: 2027 | K10: =Speed!F10/Temperature!B9 -> 1226.8621
A11: 2028 | B11: =B10+$C$3 -> 1.16 | E11: 2028 | F11: =Case!$B$8/Speed!B11 -> 1177.5761 | J11: 2028 | K11: =Speed!F11/Temperature!B10 -> 1209.8384
A12: 2029 | B12: =B11+$C$3 -> 1.18 | E12: 2029 | F12: =Case!$B$8/Speed!B12 -> 1157.6172 | J12: 2029 | K12: =Speed!F12/Temperature!B11 -> 1193.4198
A13: 2030 | B13: 1.2 | E13: 2030 | F13: =Case!$B$8/Speed!B13 -> 1138.3235 | J13: 2030 | K13: =Speed!F13/Temperature!B12 -> 1177.5761
A14: 2031 | B14: =B13+$C$3 -> 1.22 | E14: 2031 | F14: =Case!$B$8/Speed!B14 -> 1119.6625 | J14: 2031 | K14: =Speed!F14/Temperature!B13 -> 1162.2794
A15: 2032 | B15: =B14+$C$3 -> 1.24 | E15: 2032 | F15: =Case!$B$8/Speed!B15 -> 1101.6034 | J15: 2032 | K15: =Speed!F15/Temperature!B14 -> 1147.5036
A16: 2033 | B16: =B15+$C$3 -> 1.26 | E16: 2033 | F16: =Case!$B$8/Speed!B16 -> 1084.1177 | J16: 2033 | K16: =Speed!F16/Temperature!B15 -> 1133.224
A17: 2034 | B17: =B16+$C$3 -> 1.28 | E17: 2034 | F17: =Case!$B$8/Speed!B17 -> 1067.1783 | J17: 2034 | K17: =Speed!F17/Temperature!B16 -> 1119.4178
A18: 2035 | B18: =B17+$C$3 -> 1.3 | E18: 2035 | F18: =Case!$B$8/Speed!B18 -> 1050.7602 | J18: 2035 | K18: =Speed!F18/Temperature!B17 -> 1106.0634
A19: 2036 | B19: =B18+$C$3 -> 1.32 | E19: 2036 | F19: =Case!$B$8/Speed!B19 -> 1034.8396 | J19: 2036 | K19: =Speed!F19/Temperature!B18 -> 1093.1404
A20: 2037 | B20: =B19+$C$3 -> 1.34 | E20: 2037 | F20: =Case!$B$8/Speed!B20 -> 1019.3942 | J20: 2037 | K20: =Speed!F20/Temperature!B19 -> 1080.6299
A21: 2038 | B21: =B20+$C$3 -> 1.36 | E21: 2038 | F21: =Case!$B$8/Speed!B21 -> 1004.4031 | J21: 2038 | K21: =Speed!F21/Temperature!B20 -> 1068.514
A22: 2039 | B22: =B21+$C$3 -> 1.38 | E22: 2039 | F22: =Case!$B$8/Speed!B22 -> 989.84656 | J22: 2039 | K22: =Speed!F22/Temperature!B21 -> 1056.7757
A23: 2040 | B23: =B22+$C$3 -> 1.4 | E23: 2040 | F23: =Case!$B$8/Speed!B23 -> 975.7059 | J23: 2040 | K23: =Speed!F23/Temperature!B22 -> 1045.3992
A24: 2041 | B24: =B23+$C$3 -> 1.42 | E24: 2041 | F24: =Case!$B$8/Speed!B24 -> 961.96356 | J24: 2041 | K24: =Speed!F24/Temperature!B23 -> 1034.3694
A25: 2042 | B25: =B24+$C$3 -> 1.44 | E25: 2042 | F25: =Case!$B$8/Speed!B25 -> 948.60296 | J25: 2042 | K25: =Speed!F25/Temperature!B24 -> 1023.6723
... A33: 2050 | B33: =B32+$C$3 -> 1.6 | E33: 2050 | F33: =Case!$B$8/Speed!B33 -> 853.74266 | J33: 2050 | K33: =Speed!F33/Temperature!B32 -> 948.60296

Sheet Infrastructure
I2: With CC
B3: rate of infrastructure in total CF | E3: mean | I3: mean
A4: 2020 | B4: 1 | C4: =(B34-B4)/(A34-A4) -> 0.016666667 | E4: =Case!$B$13/Infrastructure!B4+Case!$B$14 -> 1365.9883 | I4: =E4/Temperature!B2 -> 1365.9883
A5: 2021 | B5: =B4+$C$4 -> 1.0166667 | E5: =Case!$B$13/Infrastructure!B5+Case!$B$14 -> 1358.9659 | I5: =E5/Temperature!B3 -> 1363.5109
A6: 2022 | B6: =B5+$C$4 -> 1.0333333 | E6: =Case!$B$13/Infrastructure!B6+Case!$B$14 -> 1352.17 | I6: =E6/Temperature!B4 -> 1361.245
A7: 2023 | B7: =B6+$C$4 -> 1.05 | E7: =Case!$B$13/Infrastructure!B7+Case!$B$14 -> 1345.5899 | I7: =E7/Temperature!B5 -> 1359.1817
A8: 2024 | B8: =B7+$C$4 -> 1.0666667 | E8: =Case!$B$13/Infrastructure!B8+Case!$B$14 -> 1339.2154 | I8: =E8/Temperature!B6 -> 1357.3129
A9: 2025 | B9: =B8+$C$4 -> 1.0833333 | E9: =Case!$B$13/Infrastructure!B9+Case!$B$14 -> 1333.037 | I9: =E9/Temperature!B7 -> 1355.6309
A10: 2026 | B10: =B9+$C$4 -> 1.1 | E10: =Case!$B$13/Infrastructure!B10+Case!$B$14 -> 1327.0459 | I10: =E10/Temperature!B8 -> 1354.1284
A11: 2027 | B11: =B10+$C$4 -> 1.1166667 | E11: =Case!$B$13/Infrastructure!B11+Case!$B$14 -> 1321.2336 | I11: =E11/Temperature!B9 -> 1352.7989
A12: 2028 | B12: =B11+$C$4 -> 1.1333333 | E12: =Case!$B$13/Infrastructure!B12+Case!$B$14 -> 1315.5922 | I12: =E12/Temperature!B10 -> 1351.6359
A13: 2029 | B13: =B12+$C$4 -> 1.15 | E13: =Case!$B$13/Infrastructure!B13+Case!$B$14 -> 1310.1144 | I13: =E13/Temperature!B11 -> 1350.6334
A14: 2030 | B14: =B13+$C$4 -> 1.1666667 | E14: =Case!$B$13/Infrastructure!B14+Case!$B$14 -> 1304.7931 | I14: =E14/Temperature!B12 -> 1349.7859
A15: 2031 | B15: =B14+$C$4 -> 1.1833333 | E15: =Case!$B$13/Infrastructure!B15+Case!$B$14 -> 1299.6217 | I15: =E15/Temperature!B13 -> 1349.0882
A16: 2032 | B16: =B15+$C$4 -> 1.2 | E16: =Case!$B$13/Infrastructure!B16+Case!$B$14 -> 1294.5939 | I16: =E16/Temperature!B14 -> 1348.5353
... A33: 2049 | B33: =B32+$C$4 -> 1.4833333 | E33: =Case!$B$13/Infrastructure!B33+Case!$B$14 -> 1226.4082 | I33: =E33/Temperature!B31 -> 1357.6475
A34: 2050 | B34: 1.5 | E34: =Case!$B$13/Infrastructure!B34+Case!$B$14 -> 1223.1995 | I34: =E34/Temperature!B32 -> 1359.1106

Sheet Best
B4: Electricity | C4: Infrastructure | D4: Total | F4: With speed & CC | G4: mean | H4: Without CC
A5: 2020 | B5: =Case!$C$11*'Elec str'!H3 -> 523.05345 | C5: =Case!$B$13/Infrastructure!B4 -> 428.36624 | D5: =B5+C5+Case!$B$15 -> 1365.9883 | F5: 2020 | G5: =D5/Speed!B3/Temperature!B2 -> 1365.9883 | H5: =G5*Temperature!B2 -> 1365.9883
A6: 2021 | B6: =Case!$C$11*'Elec str'!H4 -> 508.24948 | C6: =Case!$B$13/Infrastructure!B5 -> 421.34384 | D6: =B6+C6+Case!$B$15 -> 1344.1619 | F6: 2021 | G6: =D6/Speed!B4/Temperature!B3 -> 1322.2132 | H6: =G6*Temperature!B3 -> 1317.8058
A7: 2022 | B7: =Case!$C$11*'Elec str'!H5 -> 493.44551 | C7: =Case!$B$13/Infrastructure!B6 -> 414.54797 | D7: =B7+C7+Case!$B$15 -> 1322.5621 | F7: 2022 | G7: =D7/Speed!B5/Temperature!B4 -> 1280.2291 | H7: =G7*Temperature!B4 -> 1271.6943
A8: 2023 | B8: =Case!$C$11*'Elec str'!H6 -> 478.64154 | C8: =Case!$B$13/Infrastructure!B7 -> 407.96785 | D8: =B8+C8+Case!$B$15 -> 1301.178 | F8: 2023 | G8: =D8/Speed!B6/Temperature!B5 -> 1239.9256 | H8: =G8*Temperature!B5 -> 1227.5264
A9: 2024 | B9: =Case!$C$11*'Elec str'!H7 -> 463.83757 | C9: =Case!$B$13/Infrastructure!B8 -> 401.59335 | D9: =B9+C9+Case!$B$15 -> 1279.9995 | F9: 2024 | G9: =D9/Speed!B7/Temperature!B6 -> 1201.2007 | H9: =G9*Temperature!B6 -> 1185.1847
A10: 2025 | B10: =Case!$C$11*'Elec str'!H8 -> 449.0336 | C10: =Case!$B$13/Infrastructure!B9 -> 395.41499 | D10: =B10+C10+Case!$B$15 -> 1259.0172 | F10: 2025 | G10: =D10/Speed!B8/Temperature!B7 -> 1163.9604 | H10: =G10*Temperature!B7 -> 1144.5611
A11: 2026 | B11: =Case!$C$11*'Elec str'!H9 -> 434.22963 | C11: =Case!$B$13/Infrastructure!B10 -> 389.42386 | D11: =B11+C11+Case!$B$15 -> 1238.2221 | F11: 2026 | G11: =D11/Speed!B9/Temperature!B8 -> 1128.1178 | H11: =G11*Temperature!B8 -> 1105.5554
A12: 2027 | B12: =Case!$C$11*'Elec str'!H10 -> 419.42566 | C12: =Case!$B$13/Infrastructure!B11 -> 383.61156 | D12: =B12+C12+Case!$B$15 -> 1217.6058 | F12: 2027 | G12: =D12/Speed!B10/Temperature!B9 -> 1093.5924 | H12: =G12*Temperature!B9 -> 1068.0753
A13: 2028 | B13: =Case!$C$11*'Elec str'!H11 -> 404.62169 | C13: =Case!$B$13/Infrastructure!B12 -> 377.97021 | D13: =B13+C13+Case!$B$15 -> 1197.1605 | F13: 2028 | G13: =D13/Speed!B11/Temperature!B10 -> 1060.3098 | H13: =G13*Temperature!B10 -> 1032.0349
A14: 2029 | B14: =Case!$C$11*'Elec str'!H12 -> 389.81772 | C14: =Case!$B$13/Infrastructure!B13 -> 372.49238 | D14: =B14+C14+Case!$B$15 -> 1176.8787 | F14: 2029 | G14: =D14/Speed!B12/Temperature!B11 -> 1028.2008 | H14: =G14*Temperature!B11 -> 997.35481
A15: 2030 | B15: =Case!$C$11*'Elec str'!H13 -> 375.01375 | C15: =Case!$B$13/Infrastructure!B14 -> 367.17106 | D15: =B15+C15+Case!$B$15 -> 1156.7534 | F15: 2030 | G15: =D15/Speed!B13/Temperature!B12 -> 997.20119 | H15: =G15*Temperature!B12 -> 963.96115
A16: 2031 | B16: =Case!$C$11*'Elec str'!H14 -> 360.20978 | C16: =Case!$B$13/Infrastructure!B15 -> 361.99964 | D16: =B16+C16+Case!$B$15 -> 1136.778 | F16: 2031 | G16: =D16/Speed!B14/Temperature!B13 -> 967.25111 | H16: =G16*Temperature!B13 -> 931.78524
... A23: 2038 | B23: =Case!$C$11*'Elec str'!H21 -> 256.58199 | C23: =Case!$B$13/Infrastructure!B22 -> 329.51249 | D23: =B23+C23+Case!$B$15 -> 1000.6631 | F23: 2038 | G23: =D23/Speed!B21/Temperature!B20 -> 782.74644 | H23: =G23*Temperature!B20 -> 735.78165
A24: 2039 | B24: =Case!$C$11*'Elec str'!H22 -> 241.77802 | C24: =Case!$B$13/Infrastructure!B23 -> 325.34145 | D24: =B24+C24+Case!$B$15 -> 981.68804 | F24: 2039 | G24: =D24/Speed!B22/Temperature!B21 -> 759.46777 | H24: =G24*Temperature!B21 -> 711.36814 | K24: =Case!A2 -> Feed | L24: =Case!B2 -> 312.00852 | M24: =L24/L31 -> 0.75261017
A25: 2040 | B25: =Case!$C$11*'Elec str'!H23 -> 226.97405 | C25: =Case!$B$13/Infrastructure!B24 -> 321.27468 | D25: =B25+C25+Case!$B$15 -> 962.8173 | F25: 2040 | G25: =D25/Speed!B23/Temperature!B22 -> 736.84997 | H25: =G25*Temperature!B22 -> 687.72664 | K25: =Case!A3 -> Energy | L25: =Case!B3 -> 523.05345
A26: 2041 | B26: =Case!$C$11*'Elec str'!H24 -> 212.17008 | C26: =Case!$B$13/Infrastructure!B25 -> 317.30833 | D26: =B26+C26+Case!$B$15 -> 944.04697 | F26: 2041 | G26: =D26/Speed!B24/Temperature!B23 -> 714.86216 | H26: =G26*Temperature!B23 -> 664.82181 | K26: =Case!A4 -> Infrastructure | L26: =Case!B4 -> 428.36624
A27: 2042 | B27: =Case!$C$11*'Elec str'!H25 -> 197.36611 | C27: =Case!$B$13/Infrastructure!B26 -> 313.43871 | D27: =B27+C27+Case!$B$15 -> 925.37339 | F27: 2042 | G27: =D27/Speed!B25/Temperature!B24 -> 693.47526 | H27: =G27*Temperature!B24 -> 642.62041 | K27: =Case!A5 -> Equipment | L27: =Case!B5 -> 10.110046 | M27: =L27/L31 -> 0.024386909
A28: 2043 | B28: =Case!$C$11*'Elec str'!H26 -> 182.56214 | C28: =Case!$B$13/Infrastructure!B27 -> 309.66234 | D28: =B28+C28+Case!$B$15 -> 906.79305 | F28: 2043 | G28: =D28/Speed!B26/Temperature!B25 -> 672.66187 | H28: =G28*Temperature!B25 -> 621.09113 | K28: =Case!A6 -> Transport | L28: =Case!B6 -> 92.45 | M28: =L28/L31 -> 0.22300292
A29: 2044 | B29: =Case!$C$11*'Elec str'!H27 -> 167.75817 | C29: =Case!$B$13/Infrastructure!B28 -> 305.97589 | D29: =B29+C29+Case!$B$15 -> 888.30262 | F29: 2044 | G29: =D29/Speed!B27/Temperature!B26 -> 652.39617 | H29: =G29*Temperature!B26 -> 600.20448 | K29: =Case!A8 -> CF (without macroalgae) | L29: =SUM(L24:L28) -> 1365.9883
A30: 2045 | B30: =Case!$C$11*'Elec str'!H28 -> 152.9542 | C30: =Case!$B$13/Infrastructure!B29 -> 302.37617 | D30: =B30+C30+Case!$B$15 -> 869.89894 | F30: 2045 | G30: =D30/Speed!B28/Temperature!B27 -> 632.65377 | H30: =G30*Temperature!B27 -> 579.93263
A31: 2046 | B31: =Case!$C$11*'Elec str'!H29 -> 138.15023 | C31: =Case!$B$13/Infrastructure!B30 -> 298.86017 | D31: =B31+C31+Case!$B$15 -> 851.57897 | F31: 2046 | G31: =D31/Speed!B29/Temperature!B28 -> 613.41166 | H31: =G31*Temperature!B28 -> 560.24932 | K31: CF (without infrastructure & electrcity & natural) | L31: =L24+L27+L28 -> 414.56857
A32: 2047 | B32: =Case!$C$11*'Elec str'!H30 -> 123.34626 | C32: =Case!$B$13/Infrastructure!B31 -> 295.42499 | D32: =B32+C32+Case!$B$15 -> 833.33982 | F32: 2047 | G32: =D32/Speed!B30/Temperature!B29 -> 594.64808 | H32: =G32*Temperature!B29 -> 541.12975
A33: 2048 | B33: =Case!$C$11*'Elec str'!H31 -> 108.54229 | C33: =Case!$B$13/Infrastructure!B32 -> 292.06789 | D33: =B33+C33+Case!$B$15 -> 815.17875 | F33: 2048 | G33: =D33/Speed!B31/Temperature!B30 -> 576.34244 | H33: =G33*Temperature!B30 -> 522.55048
A34: 2049 | B34: =Case!$C$11*'Elec str'!H32 -> 93.73832 | C34: =Case!$B$13/Infrastructure!B33 -> 288.78623 | D34: =B34+C34+Case!$B$15 -> 797.09312 | F34: 2049 | G34: =D34/Speed!B32/Temperature!B31 -> 558.47526 | H34: =G34*Temperature!B31 -> 504.48932
A35: 2050 | B35: =Case!$C$11*'Elec str'!H33 -> 78.93435 | C35: =Case!$B$13/Infrastructure!B34 -> 285.57749 | D35: =B35+C35+Case!$B$15 -> 779.08041 | F35: 2050 | G35: =D35/Speed!B33/Temperature!B32 -> 541.02806 | H35: =G35*Temperature!B32 -> 486.92526
A40: After transformation | B40: Electricity | C40: Infrastructure | D40: Others
A41: 2020 | B41: =B5/Speed!B3/Temperature!B2 -> 523.05345 | C41: =C5/Speed!B3/Temperature!B2 -> 428.36624 | D41: =G5-B41-C41 -> 414.56857
A42: 2021 | B42: =B6/Speed!B4/Temperature!B3 -> 499.9503 | C42: =C6/Speed!B4/Temperature!B3 -> 414.46375 | D42: =G6-B42-C42 -> 407.7991
A43: 2022 | B43: =B7/Speed!B5/Temperature!B4 -> 477.65117 | C43: =C7/Speed!B5/Temperature!B4 -> 401.27902 | D43: =G7-B43-C43 -> 401.29895
A44: 2023 | B44: =B8/Speed!B6/Temperature!B5 -> 456.10972 | C44: =C8/Speed!B6/Temperature!B5 -> 388.76296 | D44: =G8-B44-C44 -> 395.05295 | F44: Contribution breakdown | G44: 2020 | H44: 2025 | I44: 2030 | J44: 2035 | K44: 2040 | L44: 2045 | M44: 2050
A45: 2024 | B45: =B9/Speed!B7/Temperature!B6 -> 435.283 | C45: =C9/Speed!B7/Temperature!B6 -> 376.87064 | D45: =G9-B45-C45 -> 389.04708 | F45: Energy | G45: =B41 -> 523.05345 | H45: =B46 -> 415.13121 | I45: =B51 -> 323.28771 | J45: =B56 -> 243.71976 | K45: =B61 -> 173.70463 | L45: =B66 -> 111.23942 | M45: =B71 -> 54.815521
A46: 2025 | B46: =B10/Speed!B8/Temperature!B7 -> 415.13121 | C46: =C10/Speed!B8/Temperature!B7 -> 365.56085 | D46: =G10-B46-C46 -> 383.26832 | F46: Infra.&Equip | G46: =C41+D41*M27 -> 438.47629 | H46: =C46+D46*M27 -> 374.90758 | I46: =C51+D51*M27 -> 325.24234 | J46: =C56+D56*M27 -> 285.67048 | K46: =C61+D61*M27 -> 253.61076 | L46: =C66+D66*M27 -> 227.2627 | M46: =C71+D71*M27 -> 205.33857
A47: 2026 | B47: =B11/Speed!B9/Temperature!B8 -> 395.61737 | C47: =C11/Speed!B9/Temperature!B8 -> 354.79579 | D47: =G11-B47-C47 -> 377.7046 | F47: Transport | G47: =D41*M28 -> 92.45 | H47: =D46*M28 -> 85.469954 | I47: =D51*M28 -> 79.698276 | J47: =D56*M28 -> 74.8583 | K47: =D61*M28 -> 70.752551 | L47: =D66*M28 -> 67.236364 | M47: =D71*M28 -> 64.201389
A48: 2027 | B48: =B12/Speed!B10/Temperature!B9 -> 376.70707 | C48: =C12/Speed!B10/Temperature!B9 -> 344.54065 | D48: =G12-B48-C48 -> 372.34468 | F48: Feed | G48: =D41*M24 -> 312.00852 | H48: =D46*M24 -> 288.45164 | I48: =D51*M24 -> 268.97287 | J48: =D56*M24 -> 252.63848 | K48: =D61*M24 -> 238.78203 | L48: =D66*M24 -> 226.91529 | M48: =D71*M24 -> 216.67259
A49: 2028 | B49: =B13/Speed!B11/Temperature!B10 -> 358.36829 | C49: =C13/Speed!B11/Temperature!B10 -> 334.76341 | D49: =G13-B49-C49 -> 367.17811 | O49: Natural
A50: 2029 | B50: =B14/Speed!B12/Temperature!B11 -> 340.57113 | C50: =C14/Speed!B12/Temperature!B11 -> 325.43455 | D50: =G14-B50-C50 -> 362.19515 | G50: =SUM(G45:G48) -> 1365.9883 | H50: =SUM(H45:H48) -> 1163.9604 | I50: =SUM(I45:I48) -> 997.20119 | J50: =SUM(J45:J48) -> 856.88701 | K50: =SUM(K45:K48) -> 736.84997 | L50: =SUM(L45:L48) -> 632.65377 | M50: =SUM(M45:M48) -> 541.02806 | O50: -1161.7318
A51: 2030 | B51: =B15/Speed!B13/Temperature!B12 -> 323.28771 | C51: =C15/Speed!B13/Temperature!B12 -> 316.52678 | D51: =G15-B51-C51 -> 357.3867
A52: 2031 | B52: =B16/Speed!B14/Temperature!B13 -> 306.49195 | C52: =C16/Speed!B14/Temperature!B13 -> 308.0149 | D52: =G16-B52-C52 -> 352.74426
A53: 2032 | B53: =B17/Speed!B15/Temperature!B14 -> 290.15945 | C53: =C17/Speed!B15/Temperature!B14 -> 299.87556 | D53: =G17-B53-C53 -> 348.25989 | F53: Contribution breakdown (with natural) | G53: 2020 | H53: 2025 | I53: 2030 | J53: 2035 | K53: 2040 | L53: 2045 | M53: 2050
...

Sheet Unit carbon footprint
A1: Note: The benchmark takes into account the temperature, but other factors are not considered. | B1: Baseline | C1: Energy efficiency improvement | D1: Genetic selection | E1: Infrastructure upgrade | F1: Best (with BG) | G1: Best (without BG) | I1: With natural | J1: Baseline | K1: Energy efficiency improvement | L1: Genetic selection | M1: Infrastructure upgrade | N1: Best (with BG) | O1: Best (without BG)
A2: refer to sheet Temprature | B2: refer to sheet Baseline | C2: refer to sheet Elec str | D2: refer to sheet Speed | E2: refer to sheet Infrastructure | F2: refer to sheet Best | G2: refer to sheet Best | J2: refer to sheet Baseline | K2: refer to sheet Elec str | L2: refer to sheet Speed | M2: refer to sheet Infrastructure | N2: refer to sheet Best | O2: refer to sheet Best
A3: 年份 | B3: mean | C3: mean | D3: mean | E3: mean | F3: mean | G3: mean | H3: Natural | J3: mean | K3: mean | L3: mean | M3: mean | N3: mean | O3: mean
A4: 2020 | B4: =Case!$B$8/Temperature!B2 -> 1365.9883 | C4: ='Elec str'!B40 -> 1365.9883 | D4: =Speed!F3 -> 1365.9883 | E4: =Infrastructure!E4 -> 1365.9883 | F4: =Best!G5 -> 1365.9883 | G4: =Best!H5 -> 1365.9883 | H4: -1161.7318 | J4: =B4+$H$4 -> 204.25647 | K4: =C4+$H$4 -> 204.25647 | L4: =D4+$H$4 -> 204.25647 | M4: =E4+$H$4 -> 204.25647 | N4: =F4+$H$4 -> 204.25647 | O4: =G4+$H$4 -> 204.25647
A5: 2021 | B5: =Case!$B$8/Temperature!B3 -> 1370.5568 | C5: ='Elec str'!B41 -> 1351.1843 | D5: =Speed!F4 -> 1339.2042 | E5: =Infrastructure!E5 -> 1358.9659 | F5: =Best!G6 -> 1322.2132 | G5: =Best!H6 -> 1317.8058 | J5: =B5+$H$4 -> 208.82499 | K5: =C5+$H$4 -> 189.4525 | L5: =D5+$H$4 -> 177.47238 | M5: =E5+$H$4 -> 197.23407 | N5: =F5+$H$4 -> 160.48136 | O5: =G5+$H$4 -> 156.07398
A6: 2022 | B6: =Case!$B$8/Temperature!B4 -> 1375.156 | C6: ='Elec str'!B42 -> 1336.3803 | D6: =Speed!F5 -> 1313.4502 | E6: =Infrastructure!E6 -> 1352.17 | F6: =Best!G7 -> 1280.2291 | G6: =Best!H7 -> 1271.6943 | J6: =B6+$H$4 -> 213.42417 | K6: =C6+$H$4 -> 174.64853 | L6: =D6+$H$4 -> 151.71846 | M6: =E6+$H$4 -> 190.4382 | N6: =F6+$H$4 -> 118.49735 | O6: =G6+$H$4 -> 109.96249
A7: 2023 | B7: =Case!$B$8/Temperature!B5 -> 1379.7861 | C7: ='Elec str'!B43 -> 1321.5763 | D7: =Speed!F6 -> 1288.6682 | E7: =Infrastructure!E7 -> 1345.5899 | F7: =Best!G8 -> 1239.9256 | G7: =Best!H8 -> 1227.5264 | J7: =B7+$H$4 -> 218.05433 | K7: =C7+$H$4 -> 159.84456 | L7: =D7+$H$4 -> 126.93638 | M7: =E7+$H$4 -> 183.85807 | N7: =F7+$H$4 -> 78.193838 | O7: =G7+$H$4 -> 65.794582
A8: 2024 | B8: =Case!$B$8/Temperature!B6 -> 1384.4476 | C8: ='Elec str'!B44 -> 1306.7724 | D8: =Speed!F7 -> 1264.8039 | E8: =Infrastructure!E8 -> 1339.2154 | F8: =Best!G9 -> 1201.2007 | G8: =Best!H9 -> 1185.1847 | J8: =B8+$H$4 -> 222.71577 | K8: =C8+$H$4 -> 145.04059 | L8: =D8+$H$4 -> 103.07215 | M8: =E8+$H$4 -> 177.48358 | N8: =F8+$H$4 -> 39.46893 | O8: =G8+$H$4 -> 23.45292
A9: 2025 | B9: =Case!$B$8/Temperature!B7 -> 1389.1406 | C9: ='Elec str'!B45 -> 1291.9684 | D9: =Speed!F8 -> 1241.8075 | E9: =Infrastructure!E9 -> 1333.037 | F9: =Best!G10 -> 1163.9604 | G9: =Best!H10 -> 1144.5611 | J9: =B9+$H$4 -> 227.40881 | K9: =C9+$H$4 -> 130.23662 | L9: =D9+$H$4 -> 80.075716 | M9: =E9+$H$4 -> 171.30522 | N9: =F9+$H$4 -> 2.2286023 | O9: =G9+$H$4 -> -17.170738
A10: 2026 | B10: =Case!$B$8/Temperature!B8 -> 1393.8656 | C10: ='Elec str'!B46 -> 1277.1644 | D10: =Speed!F9 -> 1219.6324 | E10: =Infrastructure!E10 -> 1327.0459 | F10: =Best!G11 -> 1128.1178 | G10: =Best!H11 -> 1105.5554 | J10: =B10+$H$4 -> 232.13378 | K10: =C10+$H$4 -> 115.43265 | L10: =D10+$H$4 -> 57.900582 | M10: =E10+$H$4 -> 165.31408 | N10: =F10+$H$4 -> -33.614032 | O10: =G10+$H$4 -> -56.176387
A11: 2027 | B11: =Case!$B$8/Temperature!B9 -> 1398.6228 | C11: ='Elec str'!B47 -> 1262.3605 | D11: =Speed!F10 -> 1198.2353 | E11: =Infrastructure!E11 -> 1321.2336 | F11: =Best!G12 -> 1093.5924 | G11: =Best!H12 -> 1068.0753 | J11: =B11+$H$4 -> 236.891 | K11: =C11+$H$4 -> 100.62868 | L11: =D11+$H$4 -> 36.503523 | M11: =E11+$H$4 -> 159.50178 | N11: =F11+$H$4 -> -68.139384 | O11: =G11+$H$4 -> -93.65654
A12: 2028 | B12: =Case!$B$8/Temperature!B10 -> 1403.4126 | C12: ='Elec str'!B48 -> 1247.5565 | D12: =Speed!F11 -> 1177.5761 | E12: =Infrastructure!E12 -> 1315.5922 | F12: =Best!G13 -> 1060.3098 | G12: =Best!H13 -> 1032.0349 | J12: =B12+$H$4 -> 241.6808 | K12: =C12+$H$4 -> 85.824707 | L12: =D12+$H$4 -> 15.844293 | M12: =E12+$H$4 -> 153.86044 | N12: =F12+$H$4 -> -101.42197 | O12: =G12+$H$4 -> -129.6969
A13: 2029 | B13: =Case!$B$8/Temperature!B11 -> 1408.2353 | C13: ='Elec str'!B49 -> 1232.7525 | D13: =Speed!F12 -> 1157.6172 | E13: =Infrastructure!E13 -> 1310.1144 | F13: =Best!G14 -> 1028.2008 | G13: =Best!H14 -> 997.35481 | J13: =B13+$H$4 -> 246.50353 | K13: =C13+$H$4 -> 71.020737 | L13: =D13+$H$4 -> -4.1146236 | M13: =E13+$H$4 -> 148.38261 | N13: =F13+$H$4 -> -133.53096 | O13: =G13+$H$4 -> -164.37698
A14: 2030 | B14: =Case!$B$8/Temperature!B12 -> 1413.0913 | C14: ='Elec str'!B50 -> 1217.9486 | D14: =Speed!F13 -> 1138.3235 | E14: =Infrastructure!E14 -> 1304.7931 | F14: =Best!G15 -> 997.20119 | G14: =Best!H15 -> 963.96115 | J14: =B14+$H$4 -> 251.35951 | K14: =C14+$H$4 -> 56.216768 | L14: =D14+$H$4 -> -23.408243 | M14: =E14+$H$4 -> 143.06129 | N14: =F14+$H$4 -> -164.5306 | O14: =G14+$H$4 -> -197.77064
A15: 2031 | B15: =Case!$B$8/Temperature!B13 -> 1417.9809 | C15: ='Elec str'!B51 -> 1203.1446 | D15: =Speed!F14 -> 1119.6625 | E15: =Infrastructure!E15 -> 1299.6217 | F15: =Best!G16 -> 967.25111 | G15: =Best!H16 -> 931.78524 | J15: =B15+$H$4 -> 256.2491 | K15: =C15+$H$4 -> 41.412798 | L15: =D15+$H$4 -> -42.069285 | M15: =E15+$H$4 -> 137.88987 | N15: =F15+$H$4 -> -194.48068 | O15: =G15+$H$4 -> -229.94655
A16: 2032 | B16: =Case!$B$8/Temperature!B14 -> 1422.9044 | C16: ='Elec str'!B52 -> 1188.3406 | D16: =Speed!F15 -> 1101.6034 | E16: =Infrastructure!E16 -> 1294.5939 | F16: =Best!G17 -> 938.2949 | G16: =Best!H17 -> 900.7631 | J16: =B16+$H$4 -> 261.17264 | K16: =C16+$H$4 -> 26.608828 | L16: =D16+$H$4 -> -60.128357 | M16: =E16+$H$4 -> 132.86209 | N16: =F16+$H$4 -> -223.43689 | O16: =G16+$H$4 -> -260.96869
... A34: 2050 | B34: =Case!$B$8/Temperature!B32 -> 1517.7647 | C34: ='Elec str'!B70 -> 921.86916 | D34: =Speed!F33 -> 853.74266 | E34: =Infrastructure!E34 -> 1223.1995 | F34: =Best!G35 -> 541.02806 | G34: =Best!H35 -> 486.92526 | J34: =B34+$H$4 -> 356.03294 | K34: =C34+$H$4 -> -239.86263 | L34: =D34+$H$4 -> -307.98913 | M34: =E34+$H$4 -> 61.467719 | N34: =F34+$H$4 -> -620.70373 | O34: =G34+$H$4 -> -674.80653

Sheet Production
G1: year | H1: Production (10000 t)
A2: year | B2: future production of abalones in South Korea (t) | G2: 2000 | H2: 0.002
A3: 2020 | B3: =H22*10000 -> 20059 | G3: 2001 | H3: 0.0029
A4: 2021 | B4: =H23*10000 -> 23199.49 | G4: 2002 | H4: 0.0085
A5: 2022 | B5: =H24*10000 -> 22078.34 | G5: 2003 | H5: 0.1065
A6: 2023 | B6: =H25*10000 -> 25373.299 | G6: 2004 | H6: 0.126
A7: 2024 | B7: =H26*10000 -> 26935.156 | G7: 2005 | H7: 0.2062
A8: 2025 | B8: =H27*10000 -> 28399.048 | G8: 2006 | H8: 0.305
A9: 2026 | B9: =H28*10000 -> 29754.241 | G9: 2007 | H9: 0.435
A10: 2027 | B10: =H29*10000 -> 30994.525 | G10: 2008 | H10: 0.5146
A11: 2028 | B11: =H30*10000 -> 32117.822 | G11: 2009 | H11: 0.6207
A12: 2029 | B12: =H31*10000 -> 33125.574 | G12: 2010 | H12: 0.6228
A13: 2030 | B13: =H32*10000 -> 34022.025 | G13: 2011 | H13: 0.6779
A14: 2031 | B14: =H33*10000 -> 34813.476 | G14: 2012 | H14: 0.6564
... A33: 2050 | B33: =H52*10000 -> 39492.517 | G33: 2031 | H33: 3.4813476
G34: 2032 | H34: 3.5507597
G35: 2033 | H35: 3.6112826
G36: 2034 | H36: 3.6637882
G37: 2035 | H37: 3.7091395
G38: 2036 | H38: 3.748164
G39: 2037 | H39: 3.7816359
G40: 2038 | H40: 3.8102663
G41: 2039 | H41: 3.834698
G42: 2040 | H42: 3.8555053
G43: 2041 | H43: 3.8731961
G44: 2042 | H44: 3.888216
G45: 2043 | H45: 3.9009529
... G52: 2050 | H52: 3.9492517
H53: 3.9525749
H54: 3.9553798

Sheet Error
A1: year | B1: error
A2: 2020 | B2: 11158.393
A3: 2021 | B3: 11926.649
A4: 2022 | B4: 12694.906
A5: 2023 | B5: 13463.163
A6: 2024 | B6: 14231.42
A7: 2025 | B7: 14999.676
A8: 2026 | B8: 15431.755
A9: 2027 | B9: 15863.834
A10: 2028 | B10: 16295.913
A11: 2029 | B11: 16727.993
A12: 2030 | B12: 17160.072
A13: 2031 | B13: 17323.85
... A32: 2050 | B32: 17287.698

Sheet Industrial carbon footprint
B1: Baseline | E1: Energy efficiency improvement | H1: Genetic selection | K1: Infrastructure upgrade | N1: Best (with BG) | Q1: Best (without BG)
B2: mean | C2: max | D2: min | E2: mean | F2: max | G2: min | H2: mean | I2: max | J2: min | K2: mean | L2: max | M2: min | N2: mean | O2: max | P2: min | Q2: mean | R2: max | S2: min
A3: 2020 | B3: ='Unit carbon footprint'!J4*Production!$B3/1000 -> 4097.1805 | C3: =$B3+Error!$B2 -> 15255.573 | D3: =$B3-Error!$B2 -> -7061.2122 | E3: ='Unit carbon footprint'!K4*Production!$B3/1000 -> 4097.1805 | F3: =$E3+Error!$B2 -> 15255.573 | G3: =$E3-Error!$B2 -> -7061.2122 | H3: ='Unit carbon footprint'!L4*Production!$B3/1000 -> 4097.1805 | I3: =$H3+Error!$B2 -> 15255.573 | J3: =$H3-Error!$B2 -> -7061.2122 | K3: ='Unit carbon footprint'!M4*Production!$B3/1000 -> 4097.1805 | L3: =$K3+Error!$B2 -> 15255.573 | M3: =$K3-Error!$B2 -> -7061.2122 | N3: ='Unit carbon footprint'!N4*Production!$B3/1000 -> 4097.1805 | O3: =$N3+Error!$B2 -> 15255.573 | P3: =$N3-Error!$B2 -> -7061.2122 | Q3: ='Unit carbon footprint'!O4*Production!$B3/1000 -> 4097.1805 | R3: =$Q3+Error!$B2 -> 15255.573 | S3: =$Q3-Error!$B2 -> -7061.2122
A4: 2021 | B4: ='Unit carbon footprint'!J5*Production!$B4/1000 -> 4844.6332 | C4: =$B4+Error!$B3 -> 16771.283 | D4: =$B4-Error!$B3 -> -7082.0161 | E4: ='Unit carbon footprint'!K5*Production!$B4/1000 -> 4395.2013 | F4: =$E4+Error!$B3 -> 16321.851 | G4: =$E4-Error!$B3 -> -7531.448 | H4: ='Unit carbon footprint'!L5*Production!$B4/1000 -> 4117.2688 | I4: =$H4+Error!$B3 -> 16043.918 | J4: =$H4-Error!$B3 -> -7809.3806 | K4: ='Unit carbon footprint'!M5*Production!$B4/1000 -> 4575.7298 | L4: =$K4+Error!$B3 -> 16502.379 | M4: =$K4-Error!$B3 -> -7350.9195 | N4: ='Unit carbon footprint'!N5*Production!$B4/1000 -> 3723.0857 | O4: =$N4+Error!$B3 -> 15649.735 | P4: =$N4-Error!$B3 -> -8203.5636 | Q4: ='Unit carbon footprint'!O5*Production!$B4/1000 -> 3620.8368 | R4: =$Q4+Error!$B3 -> 15547.486 | S4: =$Q4-Error!$B3 -> -8305.8125
A5: 2022 | B5: ='Unit carbon footprint'!J6*Production!$B5/1000 -> 4712.0514 | C5: =$B5+Error!$B4 -> 17406.958 | D5: =$B5-Error!$B4 -> -7982.8546 | E5: ='Unit carbon footprint'!K6*Production!$B5/1000 -> 3855.9495 | F5: =$E5+Error!$B4 -> 16550.856 | G5: =$E5-Error!$B4 -> -8838.9565 | H5: ='Unit carbon footprint'!L6*Production!$B5/1000 -> 3349.6917 | I5: =$H5+Error!$B4 -> 16044.598 | J5: =$H5-Error!$B4 -> -9345.2144 | K5: ='Unit carbon footprint'!M6*Production!$B5/1000 -> 4204.5593 | L5: =$K5+Error!$B4 -> 16899.465 | M5: =$K5-Error!$B4 -> -8490.3467 | N5: ='Unit carbon footprint'!N6*Production!$B5/1000 -> 2616.2248 | O5: =$N5+Error!$B4 -> 15311.131 | P5: =$N5-Error!$B4 -> -10078.681 | Q5: ='Unit carbon footprint'!O6*Production!$B5/1000 -> 2427.7892 | R5: =$Q5+Error!$B4 -> 15122.695 | S5: =$Q5-Error!$B4 -> -10267.117
A6: 2023 | B6: ='Unit carbon footprint'!J7*Production!$B6/1000 -> 5532.7577 | C6: =$B6+Error!$B5 -> 18995.92 | D6: =$B6-Error!$B5 -> -7930.4051 | E6: ='Unit carbon footprint'!K7*Production!$B6/1000 -> 4055.7838 | F6: =$E6+Error!$B5 -> 17518.947 | G6: =$E6-Error!$B5 -> -9407.379 | H6: ='Unit carbon footprint'!L7*Production!$B6/1000 -> 3220.7947 | I6: =$H6+Error!$B5 -> 16683.957 | J6: =$H6-Error!$B5 -> -10242.368 | K6: ='Unit carbon footprint'!M7*Production!$B6/1000 -> 4665.0859 | L6: =$K6+Error!$B5 -> 18128.249 | M6: =$K6-Error!$B5 -> -8798.0769 | N6: ='Unit carbon footprint'!N7*Production!$B6/1000 -> 1984.0357 | O6: =$N6+Error!$B5 -> 15447.198 | P6: =$N6-Error!$B5 -> -11479.127 | Q6: ='Unit carbon footprint'!O7*Production!$B6/1000 -> 1669.4256 | R6: =$Q6+Error!$B5 -> 15132.588 | S6: =$Q6-Error!$B5 -> -11793.737
A7: 2024 | B7: ='Unit carbon footprint'!J8*Production!$B7/1000 -> 5998.884 | C7: =$B7+Error!$B6 -> 20230.303 | D7: =$B7-Error!$B6 -> -8232.5355 | E7: ='Unit carbon footprint'!K8*Production!$B7/1000 -> 3906.6909 | F7: =$E7+Error!$B6 -> 18138.11 | G7: =$E7-Error!$B6 -> -10324.729 | H7: ='Unit carbon footprint'!L8*Production!$B7/1000 -> 2776.2645 | I7: =$H7+Error!$B6 -> 17007.684 | J7: =$H7-Error!$B6 -> -11455.155 | K7: ='Unit carbon footprint'!M8*Production!$B7/1000 -> 4780.5479 | L7: =$K7+Error!$B6 -> 19011.967 | M7: =$K7-Error!$B6 -> -9450.8717 | N7: ='Unit carbon footprint'!N8*Production!$B7/1000 -> 1063.1018 | O7: =$N7+Error!$B6 -> 15294.521 | P7: =$N7-Error!$B6 -> -13168.318 | Q7: ='Unit carbon footprint'!O8*Production!$B7/1000 -> 631.70806 | R7: =$Q7+Error!$B6 -> 14863.128 | S7: =$Q7-Error!$B6 -> -13599.711
A8: 2025 | B8: ='Unit carbon footprint'!J9*Production!$B8/1000 -> 6458.1936 | C8: =$B8+Error!$B7 -> 21457.87 | D8: =$B8-Error!$B7 -> -8541.4826 | E8: ='Unit carbon footprint'!K9*Production!$B8/1000 -> 3698.5959 | F8: =$E8+Error!$B7 -> 18698.272 | G8: =$E8-Error!$B7 -> -11301.08 | H8: ='Unit carbon footprint'!L9*Production!$B8/1000 -> 2274.0741 | I8: =$H8+Error!$B7 -> 17273.75 | J8: =$H8-Error!$B7 -> -12725.602 | K8: ='Unit carbon footprint'!M9*Production!$B8/1000 -> 4864.905 | L8: =$K8+Error!$B7 -> 19864.581 | M8: =$K8-Error!$B7 -> -10134.771 | N8: ='Unit carbon footprint'!N9*Production!$B8/1000 -> 63.290182 | O8: =$N8+Error!$B7 -> 15062.966 | P8: =$N8-Error!$B7 -> -14936.386 | Q8: ='Unit carbon footprint'!O9*Production!$B8/1000 -> -487.6326 | R8: =$Q8+Error!$B7 -> 14512.044 | S8: =$Q8-Error!$B7 -> -15487.309
A9: 2026 | B9: ='Unit carbon footprint'!J10*Production!$B9/1000 -> 6906.9643 | C9: =$B9+Error!$B8 -> 22338.72 | D9: =$B9-Error!$B8 -> -8524.791 | E9: ='Unit carbon footprint'!K10*Production!$B9/1000 -> 3434.6108 | F9: =$E9+Error!$B8 -> 18866.366 | G9: =$E9-Error!$B8 -> -11997.145 | H9: ='Unit carbon footprint'!L10*Production!$B9/1000 -> 1722.7879 | I9: =$H9+Error!$B8 -> 17154.543 | J9: =$H9-Error!$B8 -> -13708.967 | K9: ='Unit carbon footprint'!M10*Production!$B9/1000 -> 4918.795 | L9: =$K9+Error!$B8 -> 20350.55 | M9: =$K9-Error!$B8 -> -10512.96 | N9: ='Unit carbon footprint'!N10*Production!$B9/1000 -> -1000.16 | O9: =$N9+Error!$B8 -> 14431.595 | P9: =$N9-Error!$B8 -> -16431.915 | Q9: ='Unit carbon footprint'!O10*Production!$B9/1000 -> -1671.4857 | R9: =$Q9+Error!$B8 -> 13760.27 | S9: =$Q9-Error!$B8 -> -17103.241
A10: 2027 | B10: ='Unit carbon footprint'!J11*Production!$B10/1000 -> 7342.324 | C10: =$B10+Error!$B9 -> 23206.158 | D10: =$B10-Error!$B9 -> -8521.5104 | E10: ='Unit carbon footprint'!K11*Production!$B10/1000 -> 3118.9381 | F10: =$E10+Error!$B9 -> 18982.772 | G10: =$E10-Error!$B9 -> -12744.896 | H10: ='Unit carbon footprint'!L11*Production!$B10/1000 -> 1131.4094 | I10: =$H10+Error!$B9 -> 16995.244 | J10: =$H10-Error!$B9 -> -14732.425 | K10: ='Unit carbon footprint'!M11*Production!$B10/1000 -> 4943.6821 | L10: =$K10+Error!$B9 -> 20807.516 | M10: =$K10-Error!$B9 -> -10920.152 | N10: ='Unit carbon footprint'!N11*Production!$B10/1000 -> -2111.9478 | O10: =$N10+Error!$B9 -> 13751.887 | P10: =$N10-Error!$B9 -> -17975.782 | Q10: ='Unit carbon footprint'!O11*Production!$B10/1000 -> -2902.84 | R10: =$Q10+Error!$B9 -> 12960.994 | S10: =$Q10-Error!$B9 -> -18766.674
A11: 2028 | B11: ='Unit carbon footprint'!J12*Production!$B11/1000 -> 7762.2609 | C11: =$B11+Error!$B10 -> 24058.174 | D11: =$B11-Error!$B10 -> -8533.6525 | E11: ='Unit carbon footprint'!K12*Production!$B11/1000 -> 2756.5027 | F11: =$E11+Error!$B10 -> 19052.416 | G11: =$E11-Error!$B10 -> -13539.411 | H11: ='Unit carbon footprint'!L12*Production!$B11/1000 -> 508.88418 | I11: =$H11+Error!$B10 -> 16804.798 | J11: =$H11-Error!$B10 -> -15787.029 | K11: ='Unit carbon footprint'!M12*Production!$B11/1000 -> 4941.6621 | L11: =$K11+Error!$B10 -> 21237.576 | M11: =$K11-Error!$B10 -> -11354.251 | N11: ='Unit carbon footprint'!N12*Production!$B11/1000 -> -3257.4529 | O11: =$N11+Error!$B10 -> 13038.461 | P11: =$N11-Error!$B10 -> -19553.366 | Q11: ='Unit carbon footprint'!O12*Production!$B11/1000 -> -4165.582 | R11: =$Q11+Error!$B10 -> 12130.331 | S11: =$Q11-Error!$B10 -> -20461.495
A12: 2029 | B12: ='Unit carbon footprint'!J13*Production!$B12/1000 -> 8165.5708 | C12: =$B12+Error!$B11 -> 24893.563 | D12: =$B12-Error!$B11 -> -8562.4217 | E12: ='Unit carbon footprint'!K13*Production!$B12/1000 -> 2352.6027 | F12: =$E12+Error!$B11 -> 19080.595 | G12: =$E12-Error!$B11 -> -14375.39 | H12: ='Unit carbon footprint'!L13*Production!$B12/1000 -> -136.29927 | I12: =$H12+Error!$B11 -> 16591.693 | J12: =$H12-Error!$B11 -> -16864.292 | K12: ='Unit carbon footprint'!M13*Production!$B12/1000 -> 4915.2591 | L12: =$K12+Error!$B11 -> 21643.252 | M12: =$K12-Error!$B11 -> -11812.733 | N12: ='Unit carbon footprint'!N13*Production!$B12/1000 -> -4423.2897 | O12: =$N12+Error!$B11 -> 12304.703 | P12: =$N12-Error!$B11 -> -21151.282 | Q12: ='Unit carbon footprint'!O13*Production!$B12/1000 -> -5445.082 | R12: =$Q12+Error!$B11 -> 11282.911 | S12: =$Q12-Error!$B11 -> -22173.074
A13: 2030 | B13: ='Unit carbon footprint'!J14*Production!$B13/1000 -> 8551.7594 | C13: =$B13+Error!$B12 -> 25711.831 | D13: =$B13-Error!$B12 -> -8608.3121 | E13: ='Unit carbon footprint'!K14*Production!$B13/1000 -> 1912.6083 | F13: =$E13+Error!$B12 -> 19072.68 | G13: =$E13-Error!$B12 -> -15247.463 | H13: ='Unit carbon footprint'!L14*Production!$B13/1000 -> -796.39582 | I13: =$H13+Error!$B12 -> 16363.676 | J13: =$H13-Error!$B12 -> -17956.467 | K13: ='Unit carbon footprint'!M14*Production!$B13/1000 -> 4867.2347 | L13: =$K13+Error!$B12 -> 22027.306 | M13: =$K13-Error!$B12 -> -12292.837 | N13: ='Unit carbon footprint'!N14*Production!$B13/1000 -> -5597.6641 | O13: =$N13+Error!$B12 -> 11562.407 | P13: =$N13-Error!$B12 -> -22757.736 | Q13: ='Unit carbon footprint'!O14*Production!$B13/1000 -> -6728.5576 | R13: =$Q13+Error!$B12 -> 10431.514 | S13: =$Q13-Error!$B12 -> -23888.629
A14: 2031 | B14: ='Unit carbon footprint'!J15*Production!$B14/1000 -> 8920.9218 | C14: =$B14+Error!$B13 -> 26244.772 | D14: =$B14-Error!$B13 -> -8402.9285 | E14: ='Unit carbon footprint'!K15*Production!$B14/1000 -> 1441.7234 | F14: =$E14+Error!$B13 -> 18765.574 | G14: =$E14-Error!$B13 -> -15882.127 | H14: ='Unit carbon footprint'!L15*Production!$B14/1000 -> -1464.578 | I14: =$H14+Error!$B13 -> 15859.272 | J14: =$H14-Error!$B13 -> -18788.428 | K14: ='Unit carbon footprint'!M15*Production!$B14/1000 -> 4800.4255 | L14: =$K14+Error!$B13 -> 22124.276 | M14: =$K14-Error!$B13 -> -12523.425 | N14: ='Unit carbon footprint'!N15*Production!$B14/1000 -> -6770.5485 | O14: =$N14+Error!$B13 -> 10553.302 | P14: =$N14-Error!$B13 -> -24094.399 | Q14: ='Unit carbon footprint'!O15*Production!$B14/1000 -> -8005.2389 | R14: =$Q14+Error!$B13 -> 9318.6115 | S14: =$Q14-Error!$B13 -> -25329.089
... A33: 2050 | B33: ='Unit carbon footprint'!J34*Production!$B33/1000 -> 14060.637 | C33: =$B33+Error!$B32 -> 31348.335 | D33: =$B33-Error!$B32 -> -3227.0615 | E33: ='Unit carbon footprint'!K34*Production!$B33/1000 -> -9472.7789 | F33: =$E33+Error!$B32 -> 7814.9194 | G33: =$E33-Error!$B32 -> -26760.477 | H33: ='Unit carbon footprint'!L34*Production!$B33/1000 -> -12163.266 | I33: =$H33+Error!$B32 -> 5124.4324 | J33: =$H33-Error!$B32 -> -29450.964 | K33: ='Unit carbon footprint'!M34*Production!$B33/1000 -> 2427.5149 | L33: =$K33+Error!$B32 -> 19715.213 | M33: =$K33-Error!$B32 -> -14860.183 | N33: ='Unit carbon footprint'!N34*Production!$B33/1000 -> -24513.152 | O33: =$N33+Error!$B32 -> -7225.4539 | P33: =$N33-Error!$B32 -> -41800.85 | Q33: ='Unit carbon footprint'!O34*Production!$B33/1000 -> -26649.808 | R33: =$Q33+Error!$B32 -> -9362.1099 | S33: =$Q33-Error!$B32 -> -43937.506

Sheet Fig 4b1
B1: BAU | E1: P1 | H1: P3 | K1: P5 | N1: Best (with BG) | Q1: Best (without BG)
B2: mean | C2: max | D2: min | E2: mean | F2: max | G2: min | H2: mean | I2: max | J2: min | K2: mean | L2: max | M2: min | N2: mean | O2: max | P2: min | Q2: mean | R2: max | S2: min
A3: 2020 | B3: ='Industrial carbon footprint'!B3 -> 4097.1805 | C3: ='Industrial carbon footprint'!C3 -> 15255.573 | D3: ='Industrial carbon footprint'!D3 -> -7061.2122 | E3: ='Industrial carbon footprint'!E3 -> 4097.1805 | F3: ='Industrial carbon footprint'!F3 -> 15255.573 | G3: ='Industrial carbon footprint'!G3 -> -7061.2122 | H3: ='Industrial carbon footprint'!H3 -> 4097.1805 | I3: ='Industrial carbon footprint'!I3 -> 15255.573 | ... S3: ='Industrial carbon footprint'!S3 -> -7061.2122
A4: 2021 | B4: ='Industrial carbon footprint'!B4 -> 4844.6332 | C4: ='Industrial carbon footprint'!C4 -> 16771.283 | D4: ='Industrial carbon footprint'!D4 -> -7082.0161 | E4: ='Industrial carbon footprint'!E4 -> 4395.2013 | F4: ='Industrial carbon footprint'!F4 -> 16321.851 | G4: ='Industrial carbon footprint'!G4 -> -7531.448 | H4: ='Industrial carbon footprint'!H4 -> 4117.2688 | I4: ='Industrial carbon footprint'!I4 -> 16043.918 | ... S4: ='Industrial carbon footprint'!S4 -> -8305.8125
A5: 2022 | B5: ='Industrial carbon footprint'!B5 -> 4712.0514 | C5: ='Industrial carbon footprint'!C5 -> 17406.958 | D5: ='Industrial carbon footprint'!D5 -> -7982.8546 | E5: ='Industrial carbon footprint'!E5 -> 3855.9495 | F5: ='Industrial carbon footprint'!F5 -> 16550.856 | G5: ='Industrial carbon footprint'!G5 -> -8838.9565 | H5: ='Industrial carbon footprint'!H5 -> 3349.6917 | I5: ='Industrial carbon footprint'!I5 -> 16044.598 | ... S5: ='Industrial carbon footprint'!S5 -> -10267.117
A6: 2023 | B6: ='Industrial carbon footprint'!B6 -> 5532.7577 | C6: ='Industrial carbon footprint'!C6 -> 18995.92 | D6: ='Industrial carbon footprint'!D6 -> -7930.4051 | E6: ='Industrial carbon footprint'!E6 -> 4055.7838 | F6: ='Industrial carbon footprint'!F6 -> 17518.947 | G6: ='Industrial carbon footprint'!G6 -> -9407.379 | H6: ='Industrial carbon footprint'!H6 -> 3220.7947 | I6: ='Industrial carbon footprint'!I6 -> 16683.957 | ... S6: ='Industrial carbon footprint'!S6 -> -11793.737
A7: 2024 | B7: ='Industrial carbon footprint'!B7 -> 5998.884 | C7: ='Industrial carbon footprint'!C7 -> 20230.303 | D7: ='Industrial carbon footprint'!D7 -> -8232.5355 | E7: ='Industrial carbon footprint'!E7 -> 3906.6909 | F7: ='Industrial carbon footprint'!F7 -> 18138.11 | G7: ='Industrial carbon footprint'!G7 -> -10324.729 | H7: ='Industrial carbon footprint'!H7 -> 2776.2645 | I7: ='Industrial carbon footprint'!I7 -> 17007.684 | ... S7: ='Industrial carbon footprint'!S7 -> -13599.711
A8: 2025 | B8: ='Industrial carbon footprint'!B8 -> 6458.1936 | C8: ='Industrial carbon footprint'!C8 -> 21457.87 | D8: ='Industrial carbon footprint'!D8 -> -8541.4826 | E8: ='Industrial carbon footprint'!E8 -> 3698.5959 | F8: ='Industrial carbon footprint'!F8 -> 18698.272 | G8: ='Industrial carbon footprint'!G8 -> -11301.08 | H8: ='Industrial carbon footprint'!H8 -> 2274.0741 | I8: ='Industrial carbon footprint'!I8 -> 17273.75 | ... S8: ='Industrial carbon footprint'!S8 -> -15487.309
A9: 2026 | B9: ='Industrial carbon footprint'!B9 -> 6906.9643 | C9: ='Industrial carbon footprint'!C9 -> 22338.72 | D9: ='Industrial carbon footprint'!D9 -> -8524.791 | E9: ='Industrial carbon footprint'!E9 -> 3434.6108 | F9: ='Industrial carbon footprint'!F9 -> 18866.366 | G9: ='Industrial carbon footprint'!G9 -> -11997.145 | H9: ='Industrial carbon footprint'!H9 -> 1722.7879 | I9: ='Industrial carbon footprint'!I9 -> 17154.543 | ... S9: ='Industrial carbon footprint'!S9 -> -17103.241
A10: 2027 | B10: ='Industrial carbon footprint'!B10 -> 7342.324 | C10: ='Industrial carbon footprint'!C10 -> 23206.158 | D10: ='Industrial carbon footprint'!D10 -> -8521.5104 | E10: ='Industrial carbon footprint'!E10 -> 3118.9381 | F10: ='Industrial carbon footprint'!F10 -> 18982.772 | G10: ='Industrial carbon footprint'!G10 -> -12744.896 | H10: ='Industrial carbon footprint'!H10 -> 1131.4094 | I10: ='Industrial carbon footprint'!I10 -> 16995.244 | ... S10: ='Industrial carbon footprint'!S10 -> -18766.674
A11: 2028 | B11: ='Industrial carbon footprint'!B11 -> 7762.2609 | C11: ='Industrial carbon footprint'!C11 -> 24058.174 | D11: ='Industrial carbon footprint'!D11 -> -8533.6525 | E11: ='Industrial carbon footprint'!E11 -> 2756.5027 | F11: ='Industrial carbon footprint'!F11 -> 19052.416 | G11: ='Industrial carbon footprint'!G11 -> -13539.411 | H11: ='Industrial carbon footprint'!H11 -> 508.88418 | I11: ='Industrial carbon footprint'!I11 -> 16804.798 | ... S11: ='Industrial carbon footprint'!S11 -> -20461.495
A12: 2029 | B12: ='Industrial carbon footprint'!B12 -> 8165.5708 | C12: ='Industrial carbon footprint'!C12 -> 24893.563 | D12: ='Industrial carbon footprint'!D12 -> -8562.4217 | E12: ='Industrial carbon footprint'!E12 -> 2352.6027 | F12: ='Industrial carbon footprint'!F12 -> 19080.595 | G12: ='Industrial carbon footprint'!G12 -> -14375.39 | H12: ='Industrial carbon footprint'!H12 -> -136.29927 | I12: ='Industrial carbon footprint'!I12 -> 16591.693 | ... S12: ='Industrial carbon footprint'!S12 -> -22173.074
A13: 2030 | B13: ='Industrial carbon footprint'!B13 -> 8551.7594 | C13: ='Industrial carbon footprint'!C13 -> 25711.831 | D13: ='Industrial carbon footprint'!D13 -> -8608.3121 | E13: ='Industrial carbon footprint'!E13 -> 1912.6083 | F13: ='Industrial carbon footprint'!F13 -> 19072.68 | G13: ='Industrial carbon footprint'!G13 -> -15247.463 | H13: ='Industrial carbon footprint'!H13 -> -796.39582 | I13: ='Industrial carbon footprint'!I13 -> 16363.676 | ... S13: ='Industrial carbon footprint'!S13 -> -23888.629
A14: 2031 | B14: ='Industrial carbon footprint'!B14 -> 8920.9218 | C14: ='Industrial carbon footprint'!C14 -> 26244.772 | D14: ='Industrial carbon footprint'!D14 -> -8402.9285 | E14: ='Industrial carbon footprint'!E14 -> 1441.7234 | F14: ='Industrial carbon footprint'!F14 -> 18765.574 | G14: ='Industrial carbon footprint'!G14 -> -15882.127 | H14: ='Industrial carbon footprint'!H14 -> -1464.578 | I14: ='Industrial carbon footprint'!I14 -> 15859.272 | ... S14: ='Industrial carbon footprint'!S14 -> -25329.089
... A33: 2050 | B33: ='Industrial carbon footprint'!B33 -> 14060.637 | C33: ='Industrial carbon footprint'!C33 -> 31348.335 | D33: ='Industrial carbon footprint'!D33 -> -3227.0615 | E33: ='Industrial carbon footprint'!E33 -> -9472.7789 | F33: ='Industrial carbon footprint'!F33 -> 7814.9194 | G33: ='Industrial carbon footprint'!G33 -> -26760.477 | H33: ='Industrial carbon footprint'!H33 -> -12163.266 | I33: ='Industrial carbon footprint'!I33 -> 5124.4324 | ... S33: ='Industrial carbon footprint'!S33 -> -43937.506
A44: Year | B44: mean | C44: max | D44: min | E44: scenario
A45: 2020 | B45: =B3 -> 4097.1805 | C45: =C3 -> 15255.573 | D45: =D3 -> -7061.2122 | E45: BAU
A46: 2021 | B46: =B4 -> 4844.6332 | C46: =C4 -> 16771.283 | D46: =D4 -> -7082.0161 | E46: BAU
A47: 2022 | B47: =B5 -> 4712.0514 | C47: =C5 -> 17406.958 | D47: =D5 -> -7982.8546 | E47: BAU
A48: 2023 | B48: =B6 -> 5532.7577 | C48: =C6 -> 18995.92 | D48: =D6 -> -7930.4051 | E48: BAU
A49: 2024 | B49: =B7 -> 5998.884 | C49: =C7 -> 20230.303 | D49: =D7 -> -8232.5355 | E49: BAU
A50: 2025 | B50: =B8 -> 6458.1936 | C50: =C8 -> 21457.87 | D50: =D8 -> -8541.4826 | E50: BAU
A51: 2026 | B51: =B9 -> 6906.9643 | C51: =C9 -> 22338.72 | D51: =D9 -> -8524.791 | E51: BAU
A52: 2027 | B52: =B10 -> 7342.324 | C52: =C10 -> 23206.158 | D52: =D10 -> -8521.5104 | E52: BAU
A53: 2028 | B53: =B11 -> 7762.2609 | C53: =C11 -> 24058.174 | D53: =D11 -> -8533.6525 | E53: BAU
A54: 2029 | B54: =B12 -> 8165.5708 | C54: =C12 -> 24893.563 | D54: =D12 -> -8562.4217 | E54: BAU
A55: 2030 | B55: =B13 -> 8551.7594 | C55: =C13 -> 25711.831 | D55: =D13 -> -8608.3121 | E55: BAU
A56: 2031 | B56: =B14 -> 8920.9218 | C56: =C14 -> 26244.772 | D56: =D14 -> -8402.9285 | E56: BAU
... A75: 2050 | B75: =B33 -> 14060.637 | C75: =C33 -> 31348.335 | D75: =D33 -> -3227.0615 | E75: BAU
A76: 2020 | B76: =E3 -> 4097.1805 | C76: =F3 -> 15255.573 | D76: =G3 -> -7061.2122 | E76: P1
A77: 2021 | B77: =E4 -> 4395.2013 | C77: =F4 -> 16321.851 | D77: =G4 -> -7531.448 | E77: P1
A78: 2022 | B78: =E5 -> 3855.9495 | C78: =F5 -> 16550.856 | D78: =G5 -> -8838.9565 | E78: P1
A79: 2023 | B79: =E6 -> 4055.7838 | C79: =F6 -> 17518.947 | D79: =G6 -> -9407.379 | E79: P1
A80: 2024 | B80: =E7 -> 3906.6909 | C80: =F7 -> 18138.11 | D80: =G7 -> -10324.729 | E80: P1
A81: 2025 | B81: =E8 -> 3698.5959 | C81: =F8 -> 18698.272 | D81: =G8 -> -11301.08 | E81: P1
A82: 2026 | B82: =E9 -> 3434.6108 | C82: =F9 -> 18866.366 | D82: =G9 -> -11997.145 | E82: P1
A83: 2027 | B83: =E10 -> 3118.9381 | C83: =F10 -> 18982.772 | D83: =G10 -> -12744.896 | E83: P1
A84: 2028 | B84: =E11 -> 2756.5027 | C84: =F11 -> 19052.416 | D84: =G11 -> -13539.411 | E84: P1
A85: 2029 | B85: =E12 -> 2352.6027 | C85: =F12 -> 19080.595 | D85: =G12 -> -14375.39 | E85: P1
A86: 2030 | B86: =E13 -> 1912.6083 | C86: =F13 -> 19072.68 | D86: =G13 -> -15247.463 | E86: P1
...

Sheet Fig 4b2
B1: 2020 | C1: 2025 | D1: 2030 | E1: 2035 | F1: 2040 | G1: 2045 | H1: 2050
A2: Energy | B2: =Best!G54*Production!$B$3/1000 -> 10491.929 | C2: =Best!H54*Production!$B$8/1000 -> 11789.331 | D2: =Best!I54*Production!$B$13/1000 -> 10998.903 | E2: =Best!J54*Production!$B$18/1000 -> 9039.9057 | F2: =Best!K54*Production!$B$23/1000 -> 6697.1912 | G2: =Best!L54*Production!$B$28/1000 -> 4361.5606 | H2: =Best!M54*Production!$B$33/1000 -> 2164.8029
A3: Infra.&Equip | B3: =Best!G55*Production!$B$3/1000 -> 8795.3958 | C3: =Best!H55*Production!$B$8/1000 -> 10647.018 | D3: =Best!I55*Production!$B$13/1000 -> 11065.403 | E3: =Best!J55*Production!$B$18/1000 -> 10595.916 | F3: =Best!K55*Production!$B$23/1000 -> 9777.9763 | G3: =Best!L55*Production!$B$28/1000 -> 8910.6906 | H3: =Best!M55*Production!$B$33/1000 -> 8109.3369
A4: Transport | B4: =Best!G56*Production!$B$3/1000 -> 1854.4546 | C4: =Best!H56*Production!$B$8/1000 -> 2427.2653 | D4: =Best!I56*Production!$B$13/1000 -> 2711.4967 | E4: =Best!J56*Production!$B$18/1000 -> 2776.5988 | F4: =Best!K56*Production!$B$23/1000 -> 2727.8684 | G4: =Best!L56*Production!$B$28/1000 -> 2636.255 | H4: =Best!M56*Production!$B$33/1000 -> 2535.4744
A5: Feed | B5: =Best!G57*Production!$B$3/1000 -> -17044.599 | C5: =Best!H57*Production!$B$8/1000 -> -24800.325 | D5: =Best!I57*Production!$B$13/1000 -> -30373.466 | E5: =Best!J57*Production!$B$18/1000 -> -33719.539 | F5: =Best!K57*Production!$B$23/1000 -> -35584.377 | G5: =Best!L57*Production!$B$28/1000 -> -36653.004 | H5: =Best!M57*Production!$B$33/1000 -> -37322.766
B10: t CO2 eq.
A11: Process | B11: CO2 | C11: Year
A12: Energy | B12: =B2 -> 10491.929 | C12: 2020
A13: Infra.&Equip. | B13: =B3 -> 8795.3958 | C13: 2020
A14: Transport | B14: =B4 -> 1854.4546 | C14: 2020
A15: Feed | B15: =B5 -> -17044.599 | C15: 2020
A16: Energy | B16: =C2 -> 11789.331 | C16: 2025
A17: Infra.&Equip. | B17: =C3 -> 10647.018 | C17: 2025
A18: Transport | B18: =C4 -> 2427.2653 | C18: 2025
A19: Feed | B19: =C5 -> -24800.325 | C19: 2025
A20: Energy | B20: =D2 -> 10998.903 | C20: 2030
A21: Infra.&Equip. | B21: =D3 -> 11065.403 | C21: 2030
A22: Transport | B22: =D4 -> 2711.4967 | C22: 2030
A23: Feed | B23: =D5 -> -30373.466 | C23: 2030
A24: Energy | B24: =E2 -> 9039.9057 | C24: 2035
A25: Infra.&Equip. | B25: =E3 -> 10595.916 | C25: 2035
A26: Transport | B26: =E4 -> 2776.5988 | C26: 2035
A27: Feed | B27: =E5 -> -33719.539 | C27: 2035
A28: Energy | B28: =F2 -> 6697.1912 | C28: 2040
A29: Infra.&Equip. | B29: =F3 -> 9777.9763 | C29: 2040
A30: Transport | B30: =F4 -> 2727.8684 | C30: 2040
A31: Feed | B31: =F5 -> -35584.377 | C31: 2040
A32: Energy | B32: =G2 -> 4361.5606 | C32: 2045
A33: Infra.&Equip. | B33: =G3 -> 8910.6906 | C33: 2045
A34: Transport | B34: =G4 -> 2636.255 | C34: 2045
A35: Feed | B35: =G5 -> -36653.004 | C35: 2045
A36: Energy | B36: =H2 -> 2164.8029 | C36: 2050
A37: Infra.&Equip. | B37: =H3 -> 8109.3369 | C37: 2050
A38: Transport | B38: =H4 -> 2535.4744 | C38: 2050
A39: Feed | B39: =H5 -> -37322.766 | C39: 2050
