Workbook

Sheet Case (Ave)
A1: 皱纹盘鲍mean | D1: input | E1: CF | G1: 皱纹盘鲍max | J1: input | K1: CF | M1: 皱纹盘鲍min | P1: input | Q1: CF
A2: 饲料 | B2: 龙须菜 | C2: t | D2: 20 | E2: 132.85667 | G2: 饲料 | H2: 龙须菜 | I2: t | J2: 20 | K2: 132.85667 | M2: 饲料 | N2: 龙须菜 | O2: t | P2: 20 | Q2: 132.85667
A3: 设备 | B3: 小型工作船（9m） | C3: item | D3: 0.0014566397 | E3: 7.3918056 | G3: 设备 | H3: 小型工作船（9m） | I3: item | J3: 0.0021929926 | K3: 11.128473 | M3: 设备 | N3: 小型工作船（9m） | O3: item | P3: 0.0010904825 | Q3: 5.5337191
A4: 能源 | B4: 柴油 | C4: kg | D4: 16.045789 | E4: 7.3350406 | G4: 能源 | H4: 柴油 | I4: kg | J4: 24.157173 | K4: 11.043012 | M4: 能源 | N4: 柴油 | O4: kg | P4: 12.012341 | Q4: 5.4912232
B5: 电 | C5: kwh | D5: 98.956994 | E5: 63.232685 | H5: 电 | I5: kwh | J5: 148.98121 | K5: 95.197741 | N5: 电 | O5: kwh | P5: 74.082063 | Q5: 47.337814
A6: 基建 | B6: 彩钢活动板房 | C6: kg | D6: 0.75327943 | E6: 1.4740884 | G6: 基建 | H6: 彩钢活动板房 | I6: kg | J6: 1.1340733 | K6: 2.2192618 | M6: 基建 | N6: 彩钢活动板房 | O6: kg | P6: 0.56392673 | Q6: 1.1035451
B7: 养殖笼 | C7: kg | D7: 131.39581 | E7: 313.30066 | H7: 养殖笼 | I7: kg | J7: 197.81833 | K7: 471.67877 | N7: 养殖笼 | O7: kg | P7: 98.366698 | Q7: 234.54592
B8: 渔排浮板 | C8: kg | D8: 3.3787135 | E8: 8.0562582 | H8: 渔排浮板 | I8: kg | J8: 5.086703 | K8: 12.128816 | N8: 渔排浮板 | O8: kg | P8: 2.5294025 | Q8: 6.0311475
B9: 尼龙6 | C9: kg | D9: 2.1303641 | E9: 21.027669 | H9: 尼龙6 | I9: kg | J9: 3.2072946 | K9: 31.657466 | N9: 尼龙6 | O9: kg | P9: 1.594852 | Q9: 15.74192
B10: 泡沫浮球 | C10: kg | D10: 26.096826 | E10: 62.225361 | H10: 泡沫浮球 | I10: kg | J10: 39.289157 | K10: 93.6812 | N10: 泡沫浮球 | O10: kg | P10: 19.536838 | Q10: 46.583702
B11: 木桩 | C11: m3 | D11: 0.027921125 | E11: 0 | H11: 木桩 | I11: m3 | J11: 0.042035666 | K11: 0 | N11: 木桩 | O11: m3 | P11: 0.02090256 | Q11: 0
B12: 基建电力 | C12: kwh | D12: 0.10994947 | E12: 0.070256782 | H12: 基建电力 | I12: kwh | J12: 0.16553054 | K12: 0.10577262 | N12: 基建电力 | O12: kwh | P12: 0.082311345 | Q12: 0.052596256
B13: 塑料管道 | C13: kg | D13: 0.079219724 | E13: 0.81306554 | H13: 塑料管道 | I13: kg | J13: 0.11926646 | K13: 1.2240822 | N13: 塑料管道 | O13: kg | P13: 0.059306173 | Q13: 0.60868434
B14: 混凝土 | C14: kg | D14: 0.0030357433 | E14: 0.86045946 | H14: 混凝土 | I14: kg | J14: 0.0045703563 | K14: 1.2954344 | N14: 混凝土 | O14: kg | P14: 0.0022726451 | Q14: 0.64416479
A15: 运输 | B15: 幼苗运输 | C15: tkm | D15: 9.0124343 | E15: 1.8609011 | G15: 运输 | H15: 幼苗运输 | I15: tkm | J15: 13.568353 | K15: 2.8016141 | M15: 运输 | N15: 幼苗运输 | O15: tkm | P15: 6.7469685 | Q15: 1.3931243
B16: 龙须菜运输 | C16: tkm | D16: 591.86565 | E16: 93.297344 | H16: 龙须菜运输 | I16: tkm | J16: 591.86565 | K16: 93.297344 | N16: 龙须菜运输 | O16: tkm | P16: 591.86565 | Q16: 93.297344
B17: 陆运 | C17: tkm | D17: 177.4907 | E17: 23.860415 | H17: 陆运 | I17: tkm | J17: 267.21487 | K17: 35.922208 | N17: 陆运 | O17: tkm | P17: 132.87466 | Q17: 17.862596
B18: 海运 | C18: tkm | D18: 153.11284 | E18: 1.4390579 | H18: 海运 | I18: tkm | J18: 230.51364 | K18: 2.1665229 | N18: 海运 | O18: tkm | P18: 114.62469 | Q18: 1.0773203
A19: 鲍鱼幼苗 | B19: 鲍鱼幼苗 | C19: item | D19: 34571.332 | E19: =D19*E23 -> 798.28538 | G19: 鲍鱼幼苗 | H19: 鲍鱼幼苗 | I19: item | J19: 52047.651 | K19: =J19*K23 -> 1201.8304 | M19: 鲍鱼幼苗 | N19: 鲍鱼幼苗 | O19: item | P19: 25881.098 | Q19: =P19*Q23 -> 597.61948
E20: =SUM(E2:E19) -> 1537.3871 | K20: =SUM(K2:K19) -> 2200.2348 | Q20: =SUM(Q2:Q19) -> 1207.781
A21: 1粒苗 | B21: 育苗用电 | C21: kwh | D21: 0.02043588 | E21: 0.013058355 | G21: 1粒苗 | H21: 育苗用电 | I21: kwh | J21: 0.02043588 | K21: 0.013058355 | M21: 1粒苗 | N21: 育苗用电 | O21: kwh | P21: 0.02043588 | Q21: 0.013058355
B22: 其他部分 | E22: =E23-E21 -> 0.010032608 | H22: 其他部分 | K22: =K23-K21 -> 0.010032608 | N22: 其他部分 | Q22: =Q23-Q21 -> 0.010032608
E23: 0.023090964 | K23: 0.023090964 | Q23: 0.023090964
A24: 1粒苗 | B24: 基建 | E24: 0.004902061 | G24: 1粒苗 | H24: 基建 | K24: 0.004902061 | M24: 1粒苗 | N24: 基建 | Q24: 0.004902061
B25: 其他部分 | E25: =E23-E24 -> 0.018188903 | H25: 其他部分 | K25: =K23-K24 -> 0.018188903 | N25: 其他部分 | Q25: =Q23-Q24 -> 0.018188903
C26: input | D26: CF | E26: 占比 | I26: input | J26: CF | K26: 占比 | O26: input | P26: CF | Q26: 占比
B27: 电力 | C27: =D5+D12+D19*D21 -> 805.56256 | D27: =E5+E12+E21*D19 -> 514.74769 | E27: =D27/E20 -> 0.33481983 | H27: 电力 | I27: =J5+J12+J19*J21 -> 1212.7863 | J27: =K5+K12+K21*J19 -> 774.96024 | K27: =J27/K20 -> 0.35221706 | N27: 电力 | O27: =P5+P12+P19*P21 -> 603.06739 | P27: =Q5+Q12+Q21*P19 -> 385.35498 | Q27: =P27/Q20 -> 0.31906032
B28: 其他 | D28: =E20-D27 -> 1022.6394 | H28: 其他 | J28: =K20-J27 -> 1425.2746 | N28: 其他 | P28: =Q20-P27 -> 822.42599
B29: 基建 | D29: =SUM(E6:E14)+D19*E24-E12 -> 577.22835 | H29: 基建 | J29: =SUM(K6:K14)+J19*K24-K12 -> 869.02579 | N29: 基建 | P29: =SUM(Q6:Q14)+P19*Q24-Q12 -> 432.1298
B30: 其他 | D30: =E20-D29 -> 960.15878 | H30: 其他 | J30: =K20-J29 -> 1331.209 | N30: 其他 | P30: =Q20-P29 -> 775.65117
A39: 绿盘鲍mean | D39: input | E39: CF | G39: 绿盘鲍max | J39: input | K39: CF | M39: 绿盘鲍min | P39: input | Q39: CF
A40: 饲料 | B40: 龙须菜 | C40: t | D40: 20 | E40: 132.85667 | G40: 饲料 | H40: 龙须菜 | I40: t | J40: 20 | K40: 132.85667 | M40: 饲料 | N40: 龙须菜 | O40: t | P40: 20 | Q40: 132.85667
A41: 设备 | B41: 小型工作船（9m） | C41: item | D41: 0.00069594008 | E41: 3.5311845 | G41: 设备 | H41: 小型工作船（9m） | I41: item | J41: 0.00084752074 | K41: 4.3003014 | M41: 设备 | N41: 小型工作船（9m） | O41: item | P41: 0.00059035415 | Q41: 2.9954439
A42: 能源 | B42: 柴油 | C42: kg | D42: 4.5951282 | E42: 1.9770848 | G42: 能源 | H42: 柴油 | I42: kg | J42: 5.5959795 | K42: 2.4077078 | M42: 能源 | N42: 柴油 | O42: kg | P42: 3.8979692 | Q42: 1.6771274
B43: 电 | C43: kwh | D43: 48.888344 | E43: 31.23924 | H43: 电 | I43: kwh | J43: 59.536571 | K43: 38.043367 | N43: 电 | O43: kwh | P43: 41.471152 | Q43: 26.499717
A44: 基建 | B44: 彩钢活动板房 | C44: kg | D44: 0.37214736 | E44: 0.72825312 | G44: 基建 | H44: 彩钢活动板房 | I44: kg | J44: 0.45320368 | K44: 0.88687178 | M44: 基建 | N44: 彩钢活动板房 | O44: kg | P44: 0.31568629 | Q44: 0.61776475
B45: 养殖笼 | C45: kg | D45: 52.090033 | E45: 124.20543 | H45: 养殖笼 | I45: kg | J45: 63.43561 | K45: 151.25825 | N45: 养殖笼 | O45: kg | P45: 44.18709 | Q45: 105.36136
B46: 渔排浮板 | C46: kg | D46: 2.5244981 | E46: 6.0194534 | H46: 渔排浮板 | I46: kg | J46: 3.0743516 | K46: 7.3305328 | N46: 渔排浮板 | O46: kg | P46: 2.1414888 | Q46: 5.1062001
B47: 泡沫浮球 | C47: kg | D47: 5.6441031 | E47: 13.456946 | H47: 泡沫浮球 | I47: kg | J47: 6.8734286 | K47: 16.387964 | N47: 泡沫浮球 | O47: kg | P47: 4.7877968 | Q47: 11.415299
B48: 木桩 | C48: m3 | D48: 0.00027365862 | E48: 0 | H48: 木桩 | I48: m3 | J48: 0.00033326339 | K48: 0 | N48: 木桩 | O48: m3 | P48: 0.00023213996 | Q48: 0
...

Sheet Temperature
B1: 皱纹盘鲍 | C1: 绿盘鲍 | H1: 市场售卖鲍鱼品种比例
A2: 2020 | B2: 1 | C2: 1 | E2: =(B32-B2)/($A$32-$A$2) -> -0.0033333333 | F2: =(C32-C2)/($A$32-$A$2) -> -0.0023333333 | H2: 数据时间 | I2: 皱纹盘鲍 | J2: 绿盘鲍
A3: 2021 | B3: =B2+E$2 -> 0.99666667 | C3: =C2+F$2 -> 0.99766667 | H3: 2020 | I3: 0.95 | J3: 0.05
A4: 2022 | B4: =B3+E$2 -> 0.99333333 | C4: =C3+F$2 -> 0.99533333 | H4: 2021 | I4: 0.95 | J4: 0.05
A5: 2023 | B5: =B4+E$2 -> 0.99 | C5: =C4+F$2 -> 0.993 | H5: 2022 | I5: 0.925 | J5: 0.075
A6: 2024 | B6: =B5+E$2 -> 0.98666667 | C6: =C5+F$2 -> 0.99066667 | H6: 2023 | I6: 0.7 | J6: 0.3
A7: 2025 | B7: =B6+E$2 -> 0.98333333 | C7: =C6+F$2 -> 0.98833333 | H7: 2024 | I7: 0.35 | J7: 0.65
A8: 2026 | B8: =B7+E$2 -> 0.98 | C8: =C7+F$2 -> 0.986
A9: 2027 | B9: =B8+E$2 -> 0.97666667 | C9: =C8+F$2 -> 0.98366667
A10: 2028 | B10: =B9+E$2 -> 0.97333333 | C10: =C9+F$2 -> 0.98133333
A11: 2029 | B11: =B10+E$2 -> 0.97 | C11: =C10+F$2 -> 0.979
A12: 2030 | B12: =B11+E$2 -> 0.96666667 | C12: =C11+F$2 -> 0.97666667
A13: 2031 | B13: =B12+E$2 -> 0.96333333 | C13: =C12+F$2 -> 0.97433333
A14: 2032 | B14: =B13+E$2 -> 0.96 | C14: =C13+F$2 -> 0.972 | G14: Both | N14: 新增冷却用电量 | P14: 新增冷却用电碳足迹（不考虑电力结构） | Q14: 新增冷却用电碳足迹（考虑电力结构） | S14: 都要*0.01（模式占比）
A15: 2033 | B15: =B14+E$2 -> 0.95666667 | C15: =C14+F$2 -> 0.96966667 | F15: 2020 | G15: =B2*I3+C2*J3 -> 1 | K15: 维持时间 | M15: 2020 | N15: 0 | O15: =(N45-N15)/(M45-M15) -> 159.04762 | P15: =N15*'[1]Elec str'!$G$3 -> 0 | Q15: =N15*'Elec str'!I3 -> 0
A16: 2034 | B16: =B15+E$2 -> 0.95333333 | C16: =C15+F$2 -> 0.96733333 | F16: 2021 | G16: =B3*I4+C3*J4 -> 0.99671667 | K16: day | L16: hour | M16: 2021 | N16: =N15+$O$15 -> 159.04762 | P16: =N16*'[1]Elec str'!$G$3 -> 157.00118 | Q16: =N16*'Elec str'!I4 -> 101.63009
A17: 2035 | B17: =B16+E$2 -> 0.95 | C17: =C16+F$2 -> 0.965 | F17: 2022 | G17: =B4*I5+C4*J5 -> 0.99348333 | K17: 100 | L17: 2400 | M17: 2022 | N17: =N16+$O$15 -> 318.09524 | P17: =N17*'[1]Elec str'!$G$3 -> 314.00235 | Q17: =N17*'Elec str'!I5 -> 203.26018
A18: 2036 | B18: =B17+E$2 -> 0.94666667 | C18: =C17+F$2 -> 0.96266667 | F18: 2023 | G18: =B5*I6+C5*J6 -> 0.9909 | M18: 2023 | N18: =N17+$O$15 -> 477.14286 | P18: =N18*'[1]Elec str'!$G$3 -> 471.00353 | Q18: =N18*'Elec str'!I6 -> 296.06714
A19: 2037 | B19: =B18+E$2 -> 0.94333333 | C19: =C18+F$2 -> 0.96033333 | F19: 2024 | G19: =B6*I$7+C6*J$7 -> 0.98926667 | J19: kwh | M19: 2024 | N19: =N18+$O$15 -> 636.19048 | P19: =N19*'[1]Elec str'!$G$3 -> 628.0047 | Q19: =N19*'Elec str'!I7 -> 376.85588
A20: 2038 | B20: =B19+E$2 -> 0.94 | C20: =C19+F$2 -> 0.958 | F20: 2025 | G20: =B7*I$7+C7*J$7 -> 0.98658333 | J20: 功率 | K20: 制冷机 | L20: 空调 | M20: 2025 | N20: =N19+$O$15 -> 795.2381 | P20: =N20*'[1]Elec str'!$G$3 -> 785.00588 | Q20: =N20*'Elec str'!I8 -> 449.25469
A21: 2039 | B21: =B20+E$2 -> 0.93666667 | C21: =C20+F$2 -> 0.95566667 | F21: 2026 | G21: =B8*I$7+C8*J$7 -> 0.9839 | J21: 原来 | K21: 2.25 | L21: 3.75 | M21: 2026 | N21: =N20+$O$15 -> 954.28571 | P21: =N21*'[1]Elec str'!$G$3 -> 942.00705 | Q21: =N21*'Elec str'!I9 -> 513.58559
A22: 2040 | B22: =B21+E$2 -> 0.93333333 | C22: =C21+F$2 -> 0.95333333 | F22: 2027 | G22: =B9*I$7+C9*J$7 -> 0.98121667 | J22: 增加值 | K22: 0.045 | L22: 0.7 | M22: 2027 | N22: =N21+$O$15 -> 1113.3333 | P22: =N22*'[1]Elec str'!$G$3 -> 1099.0082 | Q22: =N22*'Elec str'!I10 -> 570.16151
A23: 2041 | B23: =B22+E$2 -> 0.93 | C23: =C22+F$2 -> 0.951 | F23: 2028 | G23: =B10*I$7+C10*J$7 -> 0.97853333 | J23: 增加比例 | K23: =K22/K21 -> 0.02 | L23: =L22/L21 -> 0.18666667 | M23: 2028 | N23: =N22+$O$15 -> 1272.381 | P23: =N23*'[1]Elec str'!$G$3 -> 1256.0094 | Q23: =N23*'Elec str'!I11 -> 619.28647
A24: 2042 | B24: =B23+E$2 -> 0.92666667 | C24: =C23+F$2 -> 0.94866667 | F24: 2029 | G24: =B11*I$7+C11*J$7 -> 0.97585 | J24: 一个房间 | K24: 池子数 | L24: 3 | M24: 2029 | N24: =N23+$O$15 -> 1431.4286 | P24: =N24*'[1]Elec str'!$G$3 -> 1413.0106 | Q24: =N24*'Elec str'!I12 -> 661.25584
A25: 2043 | B25: =B24+E$2 -> 0.92333333 | C25: =C24+F$2 -> 0.94633333 | F25: 2030 | G25: =B12*I$7+C12*J$7 -> 0.97316667 | K25: 空调数 | L25: 1 | M25: 2030 | N25: =N24+$O$15 -> 1590.4762 | P25: =N25*'[1]Elec str'!$G$3 -> 1570.0118 | Q25: =N25*'Elec str'!I13 -> 696.35654
A26: 2044 | B26: =B25+E$2 -> 0.92 | C26: =C25+F$2 -> 0.944 | F26: 2031 | G26: =B13*I$7+C13*J$7 -> 0.97048333 | M26: 2031 | N26: =N25+$O$15 -> 1749.5238 | P26: =N26*'[1]Elec str'!$G$3 -> 1727.0129 | Q26: =N26*'Elec str'!I14 -> 724.86725
A27: 2045 | B27: =B26+E$2 -> 0.91666667 | C27: =C26+F$2 -> 0.94166667 | F27: 2032 | G27: =B14*I$7+C14*J$7 -> 0.9678 | J27: 每小时总增加值 | K27: =3*K22+L25*L22 -> 0.835 | M27: 2032 | N27: =N26+$O$15 -> 1908.5714 | P27: =N27*'[1]Elec str'!$G$3 -> 1884.0141 | Q27: =N27*'Elec str'!I15 -> 747.05859
A28: 2046 | B28: =B27+E$2 -> 0.91333333 | C28: =C27+F$2 -> 0.93933333 | F28: 2033 | G28: =B15*I$7+C15*J$7 -> 0.96511667 | M28: 2033 | N28: =N27+$O$15 -> 2067.619 | P28: =N28*'[1]Elec str'!$G$3 -> 2041.0153 | Q28: =N28*'Elec str'!I16 -> 763.19333
A29: 2047 | B29: =B28+E$2 -> 0.91 | C29: =C28+F$2 -> 0.937 | F29: 2034 | G29: =B16*I$7+C16*J$7 -> 0.96243333 | M29: 2034 | N29: =N28+$O$15 -> 2226.6667 | P29: =N29*'[1]Elec str'!$G$3 -> 2198.0165 | Q29: =N29*'Elec str'!I17 -> 773.5266
A30: 2048 | B30: =B29+E$2 -> 0.90666667 | C30: =C29+F$2 -> 0.93466667 | F30: 2035 | G30: =B17*I$7+C17*J$7 -> 0.95975 | J30: 养殖周期总增加值 | K30: =K27*L17 -> 2004 | M30: 2035 | N30: =N29+$O$15 -> 2385.7143 | P30: =N30*'[1]Elec str'!$G$3 -> 2355.0176 | Q30: =N30*'Elec str'!I18 -> 778.30604
A31: 2049 | B31: =B30+E$2 -> 0.90333333 | C31: =C30+F$2 -> 0.93233333 | F31: 2036 | G31: =B18*I$7+C18*J$7 -> 0.95706667 | J31: 产量（吨） | K31: 0.42 | M31: 2036 | N31: =N30+$O$15 -> 2544.7619 | P31: =N31*'[1]Elec str'!$G$3 -> 2512.0188 | Q31: =N31*'Elec str'!I19 -> 777.77204
A32: 2050 | B32: 0.9 | C32: 0.93 | F32: 2037 | G32: =B19*I$7+C19*J$7 -> 0.95438333 | J32: 折算到每吨 | K32: =K30/K31 -> 4771.4286 | M32: 2037 | N32: =N31+$O$15 -> 2703.8095 | P32: =N32*'[1]Elec str'!$G$3 -> 2669.02 | Q32: =N32*'Elec str'!I20 -> 772.15786
F33: 2038 | G33: =B20*I$7+C20*J$7 -> 0.9517 | M33: 2038 | N33: =N32+$O$15 -> 2862.8571 | P33: =N33*'[1]Elec str'!$G$3 -> 2826.0212 | Q33: =N33*'Elec str'!I21 -> 761.68984
F34: 2039 | G34: =B21*I$7+C21*J$7 -> 0.94901667 | M34: 2039 | N34: =N33+$O$15 -> 3021.9048 | P34: =N34*'[1]Elec str'!$G$3 -> 2983.0223 | Q34: =N34*'Elec str'!I22 -> 746.58757
F35: 2040 | G35: =B22*I$7+C22*J$7 -> 0.94633333 | M35: 2040 | N35: =N34+$O$15 -> 3180.9524 | P35: =N35*'[1]Elec str'!$G$3 -> 3140.0235 | Q35: =N35*'Elec str'!I23 -> 727.06405
F36: 2041 | G36: =B23*I$7+C23*J$7 -> 0.94365 | M36: 2041 | N36: =N35+$O$15 -> 3340 | P36: =N36*'[1]Elec str'!$G$3 -> 3297.0247 | Q36: =N36*'Elec str'!I24 -> 703.32586
F37: 2042 | G37: =B24*I$7+C24*J$7 -> 0.94096667 | M37: 2042 | N37: =N36+$O$15 -> 3499.0476 | P37: =N37*'[1]Elec str'!$G$3 -> 3454.0259 | Q37: =N37*'Elec str'!I25 -> 675.57331
F38: 2043 | G38: =B25*I$7+C25*J$7 -> 0.93828333 | M38: 2043 | N38: =N37+$O$15 -> 3658.0952 | P38: =N38*'[1]Elec str'!$G$3 -> 3611.027 | Q38: =N38*'Elec str'!I26 -> 644.00063
F39: 2044 | G39: =B26*I$7+C26*J$7 -> 0.9356 | M39: 2044 | N39: =N38+$O$15 -> 3817.1429 | P39: =N39*'[1]Elec str'!$G$3 -> 3768.0282 | Q39: =N39*'Elec str'!I27 -> 608.79608
F40: 2045 | G40: =B27*I$7+C27*J$7 -> 0.93291667 | M40: 2045 | N40: =N39+$O$15 -> 3976.1905 | P40: =N40*'[1]Elec str'!$G$3 -> 3925.0294 | Q40: =N40*'Elec str'!I28 -> 570.14213
...

Sheet Baseline
D1: 1t鲍鱼碳足迹 | G1: 产业碳足迹(kgCO2) | N1: mean | Q1: max | T1: min
B2: 总产量(t) | C2: 产量增长率 | D2: mean | E2: max | F2: min | G2: mean | H2: max | I2: min | K2: 市场售卖鲍鱼品种比例 | N2: 碳足迹（各种模式比例） | P2: 1t碳足迹 | Q2: 碳足迹（各种模式比例） | S2: 1t碳足迹 | T2: 碳足迹（各种模式比例） | V2: 1t碳足迹
A3: 2020 | B3: 203485 | C3: 0.12879784 | D3: =P4 -> 1500.6999 | E3: =S4 -> 2137.0304 | F3: =V4 -> 1182.9525 | G3: =D3*B3 -> 3.0536993e+08 | H3: =E3*B3 -> 4.3485363e+08 | I3: =B3*F3 -> 2.4071309e+08 | K3: 数据时间 | L3: 皱纹盘鲍 | M3: 绿盘鲍 | N3: 皱纹盘鲍 | O3: 绿盘鲍 | Q3: 皱纹盘鲍 | R3: 绿盘鲍 | T3: 皱纹盘鲍 | U3: 绿盘鲍
A4: 2021 | B4: 217831 | C4: =(B4-B3)/B3 -> 0.070501511 | D4: =P5 -> 1500.6999 | E4: =S5 -> 2137.0304 | F4: =V5 -> 1182.9525 | G4: =D4*B4 -> 3.2689897e+08 | H4: =E4*B4 -> 4.6551146e+08 | I4: =B4*F4 -> 2.5768372e+08 | K4: 2020 | L4: 0.95 | M4: 0.05 | N4: 1537.3871 | O4: 803.64328 | P4: =N4*L4+O4*M4 -> 1500.6999 | Q4: 2200.2348 | R4: 936.14604 | S4: =Q4*L4+R4*M4 -> 2137.0304 | T4: 1207.781 | U4: 711.21127 | V4: =T4*L4+M4*U4 -> 1182.9525
A5: 2022 | B5: 228190 | C5: =(B5-B4)/B4 -> 0.047555215 | D5: =P6 -> 1482.3563 | E5: =S6 -> 2105.4282 | F5: =V6 -> 1170.5382 | G5: =D5*B5 -> 3.3825889e+08 | H5: =E5*B5 -> 4.8043765e+08 | I5: =B5*F5 -> 2.6710512e+08 | K5: 2021 | L5: 0.95 | M5: 0.05 | N5: 1537.3871 | O5: 803.64328 | P5: =N5*L5+O5*M5 -> 1500.6999 | Q5: 2200.2348 | R5: 936.14604 | S5: =Q5*L5+R5*M5 -> 2137.0304 | T5: 1207.781 | U5: 711.21127 | V5: =T5*L5+M5*U5 -> 1182.9525
A6: 2023 | B6: 244991 | C6: =(B6-B5)/B5 -> 0.07362724 | D6: =P7 -> 1317.264 | E6: =S7 -> 1821.0082 | F6: =V7 -> 1058.8101 | G6: =D6*B6 -> 3.2271782e+08 | H6: =E6*B6 -> 4.4613062e+08 | I6: =B6*F6 -> 2.5939894e+08 | K6: 2022 | L6: 0.925 | M6: 0.075 | N6: 1537.3871 | O6: 803.64328 | P6: =N6*L6+O6*M6 -> 1482.3563 | Q6: 2200.2348 | R6: 936.14604 | S6: =Q6*L6+R6*M6 -> 2105.4282 | T6: 1207.781 | U6: 711.21127 | V6: =T6*L6+M6*U6 -> 1170.5382
A7: 2024 | B7: 255239.19 | C7: 0.0521 | D7: =P8 -> 1060.4536 | E7: =S8 -> 1378.5771 | F7: =V8 -> 885.01066 | G7: =D7*B7 -> 2.7066932e+08 | H7: =E7*B7 -> 3.5186691e+08 | I7: =B7*F7 -> 2.2588941e+08 | K7: 2023 | L7: 0.7 | M7: 0.3 | N7: 1537.3871 | O7: 803.64328 | P7: =N7*L7+O7*M7 -> 1317.264 | Q7: 2200.2348 | R7: 936.14604 | S7: =Q7*L7+R7*M7 -> 1821.0082 | T7: 1207.781 | U7: 711.21127 | V7: =T7*L7+M7*U7 -> 1058.8101
A8: 2025 | B8: 267061.53 | C8: 0.0463 | D8: =$D$7 -> 1060.4536 | E8: =$E$7 -> 1378.5771 | F8: =$F$7 -> 885.01066 | G8: =D8*B8 -> 2.8320637e+08 | H8: =E8*B8 -> 3.6816491e+08 | I8: =B8*F8 -> 2.363523e+08 | K8: 2024 | L8: 0.35 | M8: 0.65 | N8: 1537.3871 | O8: 803.64328 | P8: =N8*L8+O8*M8 -> 1060.4536 | Q8: 2200.2348 | R8: 936.14604 | S8: =Q8*L8+R8*M8 -> 1378.5771 | T8: 1207.781 | U8: 711.21127 | V8: =T8*L8+M8*U8 -> 885.01066
A9: 2026 | B9: 278014.11 | C9: 0.041 | D9: =$D$7 -> 1060.4536 | E9: =$E$7 -> 1378.5771 | F9: =$F$7 -> 885.01066 | G9: =D9*B9 -> 2.9482107e+08 | H9: =E9*B9 -> 3.8326389e+08 | I9: =B9*F9 -> 2.4604545e+08
A10: 2027 | B10: 288076.87 | C10: 0.0362 | D10: =$D$7 -> 1060.4536 | E10: =$E$7 -> 1378.5771 | F10: =$F$7 -> 885.01066 | G10: =D10*B10 -> 3.0549216e+08 | H10: =E10*B10 -> 3.9713618e+08 | I10: =B10*F10 -> 2.549511e+08
A11: 2028 | B11: 297251.76 | C11: 0.0318 | D11: =$D$7 -> 1060.4536 | E11: =$E$7 -> 1378.5771 | F11: =$F$7 -> 885.01066 | G11: =D11*B11 -> 3.1522171e+08 | H11: =E11*B11 -> 4.0978447e+08 | I11: =B11*F11 -> 2.6307098e+08 | M11: MEAN | N11: MAX | O11: MIN
A12: 2029 | B12: 305559.15 | C12: 0.0279 | D12: =$D$7 -> 1060.4536 | E12: =$E$7 -> 1378.5771 | F12: =$F$7 -> 885.01066 | G12: =D12*B12 -> 3.2403131e+08 | H12: =E12*B12 -> 4.2123685e+08 | I12: =B12*F12 -> 2.7042311e+08 | L12: Z | M12: 1537.3871 | N12: 2200.2348 | O12: 1207.781
A13: 2030 | B13: 313033.93 | C13: 0.0245 | D13: =$D$7 -> 1060.4536 | E13: =$E$7 -> 1378.5771 | F13: =$F$7 -> 885.01066 | G13: =D13*B13 -> 3.3195797e+08 | H13: =E13*B13 -> 4.3154141e+08 | I13: =B13*F13 -> 2.7703837e+08 | L13: L | M13: 803.64328 | N13: 936.14604 | O13: 711.21127
A14: 2031 | B14: 319721.66 | C14: 0.0214 | D14: =$D$7 -> 1060.4536 | E14: =$E$7 -> 1378.5771 | F14: =$F$7 -> 885.01066 | G14: =D14*B14 -> 3.3904999e+08 | H14: =E14*B14 -> 4.4076096e+08 | I14: =B14*F14 -> 2.8295708e+08
A15: 2032 | B15: 325675.11 | C15: 0.0186 | D15: =$D$7 -> 1060.4536 | E15: =$E$7 -> 1378.5771 | F15: =$F$7 -> 885.01066 | G15: =D15*B15 -> 3.4536335e+08 | H15: =E15*B15 -> 4.4896825e+08 | I15: =B15*F15 -> 2.8822595e+08
A16: 2033 | B16: 330951.2 | C16: 0.0162 | D16: =$D$7 -> 1060.4536 | E16: =$E$7 -> 1378.5771 | F16: =$F$7 -> 885.01066 | G16: =D16*B16 -> 3.509584e+08 | H16: =E16*B16 -> 4.5624175e+08 | I16: =B16*F16 -> 2.9289534e+08
A17: 2034 | B17: 335608.52 | C17: 0.0141 | D17: =$D$7 -> 1060.4536 | E17: =$E$7 -> 1378.5771 | F17: =$F$7 -> 885.01066 | G17: =D17*B17 -> 3.5589727e+08 | H17: =E17*B17 -> 4.6266222e+08 | I17: =B17*F17 -> 2.9701712e+08
A18: 2035 | B18: 339705.32 | C18: 0.0122 | D18: =$D$7 -> 1060.4536 | E18: =$E$7 -> 1378.5771 | F18: =$F$7 -> 885.01066 | G18: =D18*B18 -> 3.6024174e+08 | H18: =E18*B18 -> 4.6830998e+08 | I18: =B18*F18 -> 3.0064283e+08
A19: 2036 | B19: 343298.05 | C19: 0.0106 | D19: =$D$7 -> 1060.4536 | E19: =$E$7 -> 1378.5771 | F19: =$F$7 -> 885.01066 | G19: =D19*B19 -> 3.6405166e+08 | H19: =E19*B19 -> 4.7326283e+08 | I19: =B19*F19 -> 3.0382244e+08
A20: 2037 | B20: 346440.35 | C20: 0.0092 | D20: =$D$7 -> 1060.4536 | E20: =$E$7 -> 1378.5771 | F20: =$F$7 -> 885.01066 | G20: =D20*B20 -> 3.6738392e+08 | H20: =E20*B20 -> 4.7759474e+08 | I20: =B20*F20 -> 3.066034e+08 | T20: 模式比例
A21: 2038 | B21: 349182.28 | C21: 0.0079 | D21: =$D$7 -> 1060.4536 | E21: =$E$7 -> 1378.5771 | F21: =$F$7 -> 885.01066 | G21: =D21*B21 -> 3.7029161e+08 | H21: =E21*B21 -> 4.813747e+08 | I21: =B21*F21 -> 3.0903004e+08 | U21: 工厂化 | V21: 南北 | X21: 本地
A22: 2039 | B22: 351570.04 | C22: 0.0068 | D22: =$D$7 -> 1060.4536 | E22: =$E$7 -> 1378.5771 | F22: =$F$7 -> 885.01066 | G22: =D22*B22 -> 3.7282372e+08 | H22: =E22*B22 -> 4.8466641e+08 | I22: =B22*F22 -> 3.1114323e+08 | V22: 陆运 | W22: 海运 | X22: 渔排（筏式） | Y22: 延绳
A23: 2040 | B23: 353645.74 | C23: 0.0059 | D23: =$D$7 -> 1060.4536 | E23: =$E$7 -> 1378.5771 | F23: =$F$7 -> 885.01066 | G23: =D23*B23 -> 3.7502491e+08 | H23: =E23*B23 -> 4.8752792e+08 | I23: =B23*F23 -> 3.1298025e+08 | T23: 2020 | U23: 0.01 | V23: 0.165 | W23: 0.165 | X23: 0.54600548 | Y23: 0.11399452
A24: 2041 | B24: 355447.44 | C24: 0.0051 | D24: =$D$7 -> 1060.4536 | E24: =$E$7 -> 1378.5771 | F24: =$F$7 -> 885.01066 | G24: =D24*B24 -> 3.7693553e+08 | H24: =E24*B24 -> 4.9001171e+08 | I24: =B24*F24 -> 3.1457477e+08 | T24: 2021 | U24: 0.01 | V24: 0.165 | W24: 0.165 | X24: 0.54600548 | Y24: 0.11399452
A25: 2042 | B25: 357009.28 | C25: 0.0044 | D25: =$D$7 -> 1060.4536 | E25: =$E$7 -> 1378.5771 | F25: =$F$7 -> 885.01066 | G25: =D25*B25 -> 3.7859178e+08 | H25: =E25*B25 -> 4.9216482e+08 | I25: =B25*F25 -> 3.1595702e+08 | T25: 2022 | U25: 0.01 | V25: 0.165 | W25: 0.165 | X25: 0.54600548 | Y25: 0.11399452
A26: 2043 | B26: 358361.69 | C26: 0.0038 | D26: =$D$7 -> 1060.4536 | E26: =$E$7 -> 1378.5771 | F26: =$F$7 -> 885.01066 | G26: =D26*B26 -> 3.8002595e+08 | H26: =E26*B26 -> 4.9402922e+08 | I26: =B26*F26 -> 3.1715392e+08 | T26: 2023 | U26: 0.01 | V26: 0.165 | W26: 0.165 | X26: 0.54600548 | Y26: 0.11399452
A27: 2044 | B27: 359531.61 | C27: 0.0033 | D27: =$D$7 -> 1060.4536 | E27: =$E$7 -> 1378.5771 | F27: =$F$7 -> 885.01066 | G27: =D27*B27 -> 3.812666e+08 | H27: =E27*B27 -> 4.9564205e+08 | I27: =B27*F27 -> 3.1818931e+08 | T27: 2024 | U27: 0.01 | V27: 0.165 | W27: 0.165 | X27: 0.54600548 | Y27: 0.11399452
A28: 2045 | B28: 360542.86 | C28: 0.0028 | D28: =$D$7 -> 1060.4536 | E28: =$E$7 -> 1378.5771 | F28: =$F$7 -> 885.01066 | G28: =D28*B28 -> 3.8233898e+08 | H28: =E28*B28 -> 4.9703613e+08 | I28: =B28*F28 -> 3.1908428e+08
A29: 2046 | B29: 361416.34 | C29: 0.0024 | D29: =$D$7 -> 1060.4536 | E29: =$E$7 -> 1378.5771 | F29: =$F$7 -> 885.01066 | G29: =D29*B29 -> 3.8326527e+08 | H29: =E29*B29 -> 4.9824029e+08 | I29: =B29*F29 -> 3.1985732e+08
A30: 2047 | B30: 362170.38 | C30: 0.0021 | D30: =$D$7 -> 1060.4536 | E30: =$E$7 -> 1378.5771 | F30: =$F$7 -> 885.01066 | G30: =D30*B30 -> 3.8406489e+08 | H30: =E30*B30 -> 4.992798e+08 | I30: =B30*F30 -> 3.2052465e+08
A31: 2048 | B31: 362820.98 | C31: 0.0018 | D31: =$D$7 -> 1060.4536 | E31: =$E$7 -> 1378.5771 | F31: =$F$7 -> 885.01066 | G31: =D31*B31 -> 3.8475482e+08 | H31: =E31*B31 -> 5.001767e+08 | I31: =B31*F31 -> 3.2110044e+08 | K31: 加温度
A32: 2049 | B32: 363382.1 | C32: 0.0015 | D32: =$D$7 -> 1060.4536 | E32: =$E$7 -> 1378.5771 | F32: =$F$7 -> 885.01066 | G32: =D32*B32 -> 3.8534986e+08 | H32: =E32*B32 -> 5.0095025e+08 | I32: =B32*F32 -> 3.2159703e+08 | K32: mean | L32: max | M32: min
A33: 2050 | B33: 363865.87 | C33: 0.0013 | D33: =$D$7 -> 1060.4536 | E33: =$E$7 -> 1378.5771 | F33: =$F$7 -> 885.01066 | G33: =D33*B33 -> 3.8586288e+08 | H33: =E33*B33 -> 5.0161716e+08 | I33: =B33*F33 -> 3.2202518e+08 | J33: 2020 | K33: =D3/Temperature!$G15 -> 1500.6999 | L33: =E3/Temperature!$G15 -> 2137.0304 | M33: =F3/Temperature!$G15 -> 1182.9525
J34: 2021 | K34: =D4/Temperature!$G16 -> 1505.6435 | L34: =E4/Temperature!$G16 -> 2144.0701 | M34: =F4/Temperature!$G16 -> 1186.8493
J35: 2022 | K35: =D5/Temperature!$G17 -> 1492.0797 | L35: =E5/Temperature!$G17 -> 2119.2385 | M35: =F5/Temperature!$G17 -> 1178.2163
J36: 2023 | K36: =D6/Temperature!$G18 -> 1329.3612 | L36: =E6/Temperature!$G18 -> 1837.7315 | M36: =F6/Temperature!$G18 -> 1068.5337
J37: 2024 | K37: =D7/Temperature!$G19 -> 1071.9593 | L37: =E7/Temperature!$G19 -> 1393.5344 | M37: =F7/Temperature!$G19 -> 894.61284
J38: 2025 | K38: =D8/Temperature!$G20 -> 1074.8749 | L38: =E8/Temperature!$G20 -> 1397.3246 | M38: =F8/Temperature!$G20 -> 897.04603
J39: 2026 | K39: =D9/Temperature!$G21 -> 1077.8063 | L39: =E9/Temperature!$G21 -> 1401.1354 | M39: =F9/Temperature!$G21 -> 899.49249
J40: 2027 | K40: =D10/Temperature!$G22 -> 1080.7538 | L40: =E10/Temperature!$G22 -> 1404.9671 | M40: =F10/Temperature!$G22 -> 901.95234
...

Sheet Elec str
A1: 排放系数 | B1: 0.0065 | C1: 0.0545 | D1: 0.0336 | E1: 0.0143 | F1: 0.944
B2: 核能 | C2: 光伏 | D2: 风力 | E2: 水力 | F2: 煤炭 | G2: 1kwh排放（无k、t） | H2: t转换系数 | I2: 1kwh排放（调整后）
A3: 2020 | B3: 0.2886 | C3: 0.0012 | D3: 0.0739 | E3: 0.0842 | F3: 0.5521 | G3: / | H3: / | I3: 0.63899158 | K3: 核电 | L3: 光伏 | M3: 风电 | N3: 水力 | O3: 煤电
A4: 2021 | B4: / | C4: / | D4: / | E4: / | F4: / | G4: / | H4: / | I4: 0.63899158 | K4: =(B33-B6)/($A$33-$A$6) -> 3.5307511e-05 | L4: =(C33-C6)/($A$33-$A$6) -> 0.0094613785 | M4: =(D33-D6)/($A$33-$A$6) -> 0.011122249 | N4: =(E33-E6)/($A$33-$A$6) -> 0.0008367787 | O4: =(F33-F6)/($A$33-$A$6) -> -0.021455714
A5: 2022 | B5: / | C5: / | D5: / | E5: / | F5: / | G5: / | H5: / | I5: 0.63899158
A6: 2023 | B6: 0.047 | C6: 0.063 | D6: 0.095 | E6: 0.139 | F6: 0.656 | G6: =B6*$B$1+C6*$C$1+D6*$D$1+E6*$E$1+F6*$F$1 -> 0.6281827 | H6: 1 | I6: =G6*$L$9*H6 -> 0.6205
A7: 2024 | B7: =B6+K$4 -> 0.047035308 | C7: =C6+L$4 -> 0.072461378 | D7: =D6+M$4 -> 0.10612225 | E7: =E6+N$4 -> 0.13983678 | F7: =F6+O$4 -> 0.63454429 | G7: =B7*$B$1+C7*$C$1+D7*$D$1+E7*$E$1+F7*$F$1 -> 0.60883005 | H7: =H6*(1-$L$14) -> 0.985 | I7: =G7*$L$9*H7 -> 0.59236328
A8: 2025 | B8: =B7+K$4 -> 0.047070615 | C8: =C7+L$4 -> 0.081922757 | D8: =D7+M$4 -> 0.1172445 | E8: =E7+N$4 -> 0.14067356 | F8: =F7+O$4 -> 0.61308857 | G8: =B8*$B$1+C8*$C$1+D8*$D$1+E8*$E$1+F8*$F$1 -> 0.58947741 | H8: =H7*(1-$L$14) -> 0.970225 | I8: =G8*$L$9*H8 -> 0.56493104 | K8: 2023官方 | L8: 0.6205
A9: 2026 | B9: =B8+K$4 -> 0.047105923 | C9: =C8+L$4 -> 0.091384135 | D9: =D8+M$4 -> 0.12836675 | E9: =E8+N$4 -> 0.14151034 | F9: =F8+O$4 -> 0.59163286 | G9: =B9*$B$1+C9*$C$1+D9*$D$1+E9*$E$1+F9*$F$1 -> 0.57012476 | H9: =H8*(1-$L$14) -> 0.95567163 | I9: =G9*$L$9*H9 -> 0.5381885 | K9: k | L9: =L8/G6 -> 0.98776996 | M9: 整体转换系数
A10: 2027 | B10: =B9+K$4 -> 0.04714123 | C10: =C9+L$4 -> 0.10084551 | D10: =D9+M$4 -> 0.139489 | E10: =E9+N$4 -> 0.14234711 | F10: =F9+O$4 -> 0.57017715 | G10: =B10*$B$1+C10*$C$1+D10*$D$1+E10*$E$1+F10*$F$1 -> 0.55077212 | H10: =H9*(1-$L$14) -> 0.94133655 | I10: =G10*$L$9*H10 -> 0.51212111
A11: 2028 | B11: =B10+K$4 -> 0.047176538 | C11: =C10+L$4 -> 0.11030689 | D11: =D10+M$4 -> 0.15061125 | E11: =E10+N$4 -> 0.14318389 | F11: =F10+O$4 -> 0.54872143 | G11: =B11*$B$1+C11*$C$1+D11*$D$1+E11*$E$1+F11*$F$1 -> 0.53141947 | H11: =H10*(1-$L$14) -> 0.9272165 | I11: =G11*$L$9*H11 -> 0.48671466
A12: 2029 | B12: =B11+K$4 -> 0.047211845 | C12: =C11+L$4 -> 0.11976827 | D12: =D11+M$4 -> 0.16173349 | E12: =E11+N$4 -> 0.14402067 | F12: =F11+O$4 -> 0.52726572 | G12: =B12*$B$1+C12*$C$1+D12*$D$1+E12*$E$1+F12*$F$1 -> 0.51206683 | H12: =H11*(1-$L$14) -> 0.91330825 | I12: =G12*$L$9*H12 -> 0.46195518 | K12: 2021官方 | L12: 0.5568 | M12: kg CO2/ kWh
A13: 2030 | B13: =B12+K$4 -> 0.047247153 | C13: =C12+L$4 -> 0.12922965 | D13: =D12+M$4 -> 0.17285574 | E13: =E12+N$4 -> 0.14485745 | F13: =F12+O$4 -> 0.50581 | G13: =B13*$B$1+C13*$C$1+D13*$D$1+E13*$E$1+F13*$F$1 -> 0.49271418 | H13: =H12*(1-$L$14) -> 0.89960863 | I13: =G13*$L$9*H13 -> 0.43782896 | K13: 2022官方 | L13: 0.5366 | M13: kg CO2/ kWh
A14: 2031 | B14: =B13+K$4 -> 0.04728246 | C14: =C13+L$4 -> 0.13869103 | D14: =D13+M$4 -> 0.18397799 | E14: =E13+N$4 -> 0.14569423 | F14: =F13+O$4 -> 0.48435429 | G14: =B14*$B$1+C14*$C$1+D14*$D$1+E14*$E$1+F14*$F$1 -> 0.47336153 | H14: =H13*(1-$L$14) -> 0.8861145 | I14: =G14*$L$9*H14 -> 0.4143226 | K14: t | L14: 0.015 | M14: 技术效率系数
A15: 2032 | B15: =B14+K$4 -> 0.047317768 | C15: =C14+L$4 -> 0.14815241 | D15: =D14+M$4 -> 0.19510024 | E15: =E14+N$4 -> 0.14653101 | F15: =F14+O$4 -> 0.46289858 | G15: =B15*$B$1+C15*$C$1+D15*$D$1+E15*$E$1+F15*$F$1 -> 0.45400889 | H15: =H14*(1-$L$14) -> 0.87282278 | I15: =G15*$L$9*H15 -> 0.39142291
A16: 2033 | B16: =B15+K$4 -> 0.047353075 | C16: =C15+L$4 -> 0.15761378 | D16: =D15+M$4 -> 0.20622249 | E16: =E15+N$4 -> 0.14736779 | F16: =F15+O$4 -> 0.44144286 | G16: =B16*$B$1+C16*$C$1+D16*$D$1+E16*$E$1+F16*$F$1 -> 0.43465624 | H16: =H15*(1-$L$14) -> 0.85973044 | I16: =G16*$L$9*H16 -> 0.36911699
A17: 2034 | B17: =B16+K$4 -> 0.047388383 | C17: =C16+L$4 -> 0.16707516 | D17: =D16+M$4 -> 0.21734474 | E17: =E16+N$4 -> 0.14820457 | F17: =F16+O$4 -> 0.41998715 | G17: =B17*$B$1+C17*$C$1+D17*$D$1+E17*$E$1+F17*$F$1 -> 0.4153036 | H17: =H16*(1-$L$14) -> 0.84683449 | I17: =G17*$L$9*H17 -> 0.34739218
A18: 2035 | B18: =B17+K$4 -> 0.04742369 | C18: =C17+L$4 -> 0.17653654 | D18: =D17+M$4 -> 0.22846699 | E18: =E17+N$4 -> 0.14904134 | F18: =F17+O$4 -> 0.39853144 | G18: =B18*$B$1+C18*$C$1+D18*$D$1+E18*$E$1+F18*$F$1 -> 0.39595095 | H18: =H17*(1-$L$14) -> 0.83413197 | I18: =G18*$L$9*H18 -> 0.32623607
A19: 2036 | B19: =B18+K$4 -> 0.047458998 | C19: =C18+L$4 -> 0.18599792 | D19: =D18+M$4 -> 0.23958924 | E19: =E18+N$4 -> 0.14987812 | F19: =F18+O$4 -> 0.37707572 | G19: =B19*$B$1+C19*$C$1+D19*$D$1+E19*$E$1+F19*$F$1 -> 0.37659831 | H19: =H18*(1-$L$14) -> 0.82161999 | I19: =G19*$L$9*H19 -> 0.30563647
A20: 2037 | B20: =B19+K$4 -> 0.047494305 | C20: =C19+L$4 -> 0.1954593 | D20: =D19+M$4 -> 0.25071149 | E20: =E19+N$4 -> 0.1507149 | F20: =F19+O$4 -> 0.35562001 | G20: =B20*$B$1+C20*$C$1+D20*$D$1+E20*$E$1+F20*$F$1 -> 0.35724566 | H20: =H19*(1-$L$14) -> 0.80929569 | I20: =G20*$L$9*H20 -> 0.28558146
A21: 2038 | B21: =B20+K$4 -> 0.047529613 | C21: =C20+L$4 -> 0.20492068 | D21: =D20+M$4 -> 0.26183374 | E21: =E20+N$4 -> 0.15155168 | F21: =F20+O$4 -> 0.33416429 | G21: =B21*$B$1+C21*$C$1+D21*$D$1+E21*$E$1+F21*$F$1 -> 0.33789302 | H21: =H20*(1-$L$14) -> 0.79715625 | I21: =G21*$L$9*H21 -> 0.26605933
A22: 2039 | B22: =B21+K$4 -> 0.04756492 | C22: =C21+L$4 -> 0.21438206 | D22: =D21+M$4 -> 0.27295598 | E22: =E21+N$4 -> 0.15238846 | F22: =F21+O$4 -> 0.31270858 | G22: =B22*$B$1+C22*$C$1+D22*$D$1+E22*$E$1+F22*$F$1 -> 0.31854037 | H22: =H21*(1-$L$14) -> 0.78519891 | I22: =G22*$L$9*H22 -> 0.2470586
A23: 2040 | B23: =B22+K$4 -> 0.047600228 | C23: =C22+L$4 -> 0.22384343 | D23: =D22+M$4 -> 0.28407823 | E23: =E22+N$4 -> 0.15322524 | F23: =F22+O$4 -> 0.29125287 | G23: =B23*$B$1+C23*$C$1+D23*$D$1+E23*$E$1+F23*$F$1 -> 0.29918772 | H23: =H22*(1-$L$14) -> 0.77342093 | I23: =G23*$L$9*H23 -> 0.22856804
A24: 2041 | B24: =B23+K$4 -> 0.047635535 | C24: =C23+L$4 -> 0.23330481 | D24: =D23+M$4 -> 0.29520048 | E24: =E23+N$4 -> 0.15406202 | F24: =F23+O$4 -> 0.26979715 | G24: =B24*$B$1+C24*$C$1+D24*$D$1+E24*$E$1+F24*$F$1 -> 0.27983508 | H24: =H23*(1-$L$14) -> 0.76181961 | I24: =G24*$L$9*H24 -> 0.2105766
A25: 2042 | B25: =B24+K$4 -> 0.047670843 | C25: =C24+L$4 -> 0.24276619 | D25: =D24+M$4 -> 0.30632273 | E25: =E24+N$4 -> 0.1548988 | F25: =F24+O$4 -> 0.24834144 | G25: =B25*$B$1+C25*$C$1+D25*$D$1+E25*$E$1+F25*$F$1 -> 0.26048243 | H25: =H24*(1-$L$14) -> 0.75039232 | I25: =G25*$L$9*H25 -> 0.19307348
A26: 2043 | B26: =B25+K$4 -> 0.04770615 | C26: =C25+L$4 -> 0.25222757 | D26: =D25+M$4 -> 0.31744498 | E26: =E25+N$4 -> 0.15573557 | F26: =F25+O$4 -> 0.22688573 | G26: =B26*$B$1+C26*$C$1+D26*$D$1+E26*$E$1+F26*$F$1 -> 0.24112979 | H26: =H25*(1-$L$14) -> 0.73913643 | I26: =G26*$L$9*H26 -> 0.17604808
... A32: 2049 | B32: =B31+K$4 -> 0.047917995 | C32: =C31+L$4 -> 0.30899584 | D32: =D31+M$4 -> 0.38417848 | E32: =E31+N$4 -> 0.16075625 | F32: =F31+O$4 -> 0.098151443 | G32: =B32*$B$1+C32*$C$1+D32*$D$1+E32*$E$1+F32*$F$1 -> 0.12501391 | H32: =H31*(1-$L$14) -> 0.67505941 | I32: =G32*$L$9*H32 -> 0.083359703
A33: 2050 | B33: 0.047953303 | C33: 0.31845722 | D33: 0.39530072 | E33: 0.16159302 | F33: 0.076695729 | G33: =B33*$B$1+C33*$C$1+D33*$D$1+E33*$E$1+F33*$F$1 -> 0.10566127 | H33: =H32*(1-$L$14) -> 0.66493351 | I33: =G33*$L$9*H33 -> 0.069398464
B37: 皱纹盘鲍 | E37: 绿盘鲍
B38: mean | C38: max | D38: min | E38: mean | F38: max | G38: min | J38: 市场售卖鲍鱼品种比例
A39: 电力input | B39: ='Case (Ave)'!C27 -> 805.56256 | C39: ='Case (Ave)'!I27 -> 1212.7863 | D39: ='Case (Ave)'!O27 -> 603.06739 | E39: ='Case (Ave)'!C67 -> 397.97713 | F39: ='Case (Ave)'!I67 -> 484.65935 | G39: ='Case (Ave)'!O67 -> 337.59723 | J39: 数据时间 | K39: 皱纹盘鲍 | L39: 绿盘鲍
A40: 其他CF | B40: ='Case (Ave)'!D28 -> 1022.6394 | C40: ='Case (Ave)'!J28 -> 1425.2746 | D40: ='Case (Ave)'!P28 -> 822.42599 | E40: ='Case (Ave)'!D68 -> 549.33925 | F40: ='Case (Ave)'!J68 -> 626.4528 | G40: ='Case (Ave)'!P68 -> 495.48948 | J40: 2020 | K40: 0.95 | L40: 0.05
J41: 2021 | K41: 0.95 | L41: 0.05
J42: 2022 | K42: 0.925 | L42: 0.075
J43: 2023 | K43: 0.7 | L43: 0.3
J44: 2024 | K44: 0.35 | L44: 0.65
B46: 皱纹盘鲍 | E46: 绿盘鲍 | J46: 一吨鲍鱼碳足迹 | O46: 加温度
B47: mean | C47: max | D47: min | E47: mean | F47: max | G47: min | J47: mean | K47: max | L47: min | O47: mean | P47: max | Q47: min
A48: 2020 | B48: =B$39*$I3+B$40 -> 1537.3871 | C48: =C$39*$I3+C$40 -> 2200.2348 | D48: =D$39*$I3+D$40 -> 1207.781 | E48: =E$39*$I3+E$40 -> 803.64328 | F48: =F$39*$I3+F$40 -> 936.14604 | G48: =G$39*$I3+G$40 -> 711.21127 | I48: 2020 | J48: =B48*$K40+E48*$L40 -> 1500.6999 | K48: =C48*$K40+F48*$L40 -> 2137.0304 | L48: =D48*$K40+G48*$L40 -> 1182.9525 | N48: 2020 | O48: =J48/Temperature!$G15 -> 1500.6999 | P48: =K48/Temperature!$G15 -> 2137.0304 | Q48: =L48/Temperature!$G15 -> 1182.9525
A49: 2021 | B49: =B$39*$I4+B$40 -> 1537.3871 | C49: =C$39*$I4+C$40 -> 2200.2348 | D49: =D$39*$I4+D$40 -> 1207.781 | E49: =E$39*$I4+E$40 -> 803.64328 | F49: =F$39*$I4+F$40 -> 936.14604 | G49: =G$39*$I4+G$40 -> 711.21127 | I49: 2021 | J49: =B49*$K41+E49*$L41 -> 1500.6999 | K49: =C49*$K41+F49*$L41 -> 2137.0304 | L49: =D49*$K41+G49*$L41 -> 1182.9525 | N49: 2021 | O49: =J49/Temperature!$G16 -> 1505.6435 | P49: =K49/Temperature!$G16 -> 2144.0701 | Q49: =L49/Temperature!$G16 -> 1186.8493
...

Sheet Case(Mode_Orl_Gene)
B1: 工厂化 | C1: 南北 | E1: 本地 | P1: input | Q1: CF
C2: 陆运 | D2: 海运 | E2: 渔排（筏式） | F2: 延绳 | H2: 1t | I2: FRCM-Raft | M2: 饲料 | N2: 龙须菜 | O2: t | P2: =J3 -> 20 | Q2: =K3 -> 132.85667
A3: 2020 | B3: 0.01 | C3: 0.165 | D3: 0.165 | E3: 0.54600548 | F3: 0.11399452 | H3: 饲料 | I3: 龙须菜 | J3: 20 | K3: 132.85667 | M3: 设备 | N3: 小型工作船（9m） | O3: item | P3: =J4*$E$9+J17*$F$9+J37*$C$9+J61*$D$9+J45*$C$9+J69*$D$9 -> 0.00059459859 | Q3: =K4*$E$9+K17*$F$9+K37*$C$9+K61*$D$9+K45*$C$9+K69*$D$9 -> 3.0167123
A4: 2021 | B4: 0.01 | C4: 0.165 | D4: 0.165 | E4: 0.54600548 | F4: 0.11399452 | H4: 设备 | I4: 小型工作船（9m） | J4: 0.00097776688 | K4: 4.9617367 | M4: 能源 | N4: 柴油 | O4: kg | P4: =J5*$E$9+J18*$F$9+J36*$C$9+J44*$C$9+J60*$D$9+J68*$D$9 -> 3.5411241 | Q4: =K5*$E$9+K18*$F$9+K36*$C$9+K44*$C$9+K60*$D$9+K68*$D$9 -> 1.5319003
A5: 2022 | B5: 0.01 | C5: 0.165 | D5: 0.165 | E5: 0.54600548 | F5: 0.11399452 | H5: 能源 | I5: 柴油 | J5: 7.2607991 | K5: 3.0500856 | N5: 电 | O5: kwh | P5: =J79*$B$9 -> 48.888344 | Q5: =K79*$B$9 -> 31.23924
A6: 2023 | B6: 0.01 | C6: 0.165 | D6: 0.165 | E6: 0.54600548 | F6: 0.11399452 | H6: 基建 | I6: 彩钢活动板房 | J6: 0.68158174 | K6: 1.3337835 | M6: 基建 | N6: 彩钢活动板房 | O6: kg | P6: =J6*$E$9 -> 0.27629122 | Q6: =K6*$E$9 -> 0.54067277
A7: 2024 | B7: 0.01 | C7: 0.165 | D7: 0.165 | E7: 0.54600548 | F7: 0.11399452 | I7: 养殖笼 | J7: 44.93535 | K7: 107.14456 | N7: 养殖笼 | O7: kg | P7: =J7*$E$9+J20*$F$9+J48*$C$9+J72*$D$9+J82*$B$9 -> 41.648421 | Q7: =K7*$E$9+K20*$F$9+K48*$C$9+K72*$D$9+K82*$B$9 -> 99.308877
I8: 渔排浮板 | J8: 3.0571251 | K8: 7.2894576 | N8: 渔排浮板 | O8: kg | P8: =J8*$E$9+J39*$C$9+J63*$D$9 -> 2.5351553 | Q8: =K8*$E$9+K39*$C$9+K63*$D$9 -> 6.0448647
A9: 2050 | B9: 0.01 | C9: 0.25 | D9: 0.25 | E9: 0.4053677 | F9: 0.084632298 | H9: 运输 | I9: 龙须菜运输 | J9: 300 | K9: 65.478973 | N9: 泡沫浮球 | O9: kg | P9: =J41*$C$9+J47*$C$9+J65*$D$9+J71*$D$9 -> 8.5516714 | Q9: =K41*$C$9+K47*$C$9+K65*$D$9+K71*$D$9 -> 20.389313
I10: 幼苗运输 | J10: 7.0418771 | K10: 1.5370388 | N10: 木桩 | O10: m3 | P10: =J40*$C$9+J64*$D$9 -> 0.00041463427 | Q10: =K40*$C$9+K64*$D$9 -> 0
H11: 其他 | I11: 鲍鱼幼苗 | J11: 19555.338 | K11: 451.55159 | N11: 基建电力 | O11: kwh | P11: =J80*$B$9 -> 0.054319024 | Q11: =K80*$B$9 -> 0.034709399
K12: 775.2039 | N12: 塑料管道 | O12: kg | P12: =J81*$B$9 -> 0.039137417 | Q12: =K81*$B$9 -> 0.40168387
N13: 混凝土 | O13: kg | P13: =J83*$B$9 -> 0.0014997673 | Q13: =K83*$B$9 -> 0.42509818
I14: FRCM-longline | N14: 聚乙烯绳 | O14: kg | P14: =J19*$F$9+J38*$C$9+J46*$C$9+J62*$D$9+J70*$D$9 -> 2.1731974 | Q14: =K19*$F$9+K38*$C$9+K46*$C$9+K62*$D$9+K70*$D$9 -> 5.1816145
H15: 1t | J15: input | K15: CF | N15: 养殖扣盆 | O15: kg | P15: =J42*$C$9+J66*$D$9 -> 1.5839824 | Q15: =K42*$C$9+K66*$D$9 -> 3.7766644
H16: 饲料 | I16: 龙须菜 | J16: 20 | K16: 132.85667 | M16: 运输 | N16: 幼苗运输 | O16: tkm | P16: =J10*$E$9+J22*$F$9+J33*$C$9+J57*$D$9+J85*$B$9 -> 3.6226626 | Q16: =K10*$E$9+K22*$F$9+K33*$C$9+K57*$D$9+K85*$B$9 -> 0.78977696
H17: 设备 | I17: 小型工作船（9m） | J17: 0.00053723455 | K17: 2.726229 | N17: 龙须菜运输 | O17: tkm | P17: =J9*$E$9+J21*$F$9+J32*$C$9+J56*$D$9+J84*$B$9 -> 276.2 | Q17: =K9*$E$9+K21*$F$9+K32*$C$9+K56*$D$9+K84*$B$9 -> 57.836433
H18: 能源 | I18: 柴油 | J18: 4.0614932 | K18: 2.0072376 | N18: 陆运 | O18: tkm | P18: =J30*$C$9 -> 151.3134 | Q18: =K30*$C$9 -> 33.026154
H19: 基建 | I19: 主绳（聚乙烯） | J19: 23.079229 | K19: 55.030481 | N19: 海运 | O19: tkm | P19: =J55*$D$9 -> 143.542 | Q19: =K55*$D$9 -> 1.3491047
I20: 养殖笼 | J20: 197.87941 | K20: 471.82683 | M20: 鲍鱼幼苗 | N20: 鲍鱼幼苗 | O20: item | P20: =J11*$E$9+J23*$F$9+J34*$C$9+J58*$D$9+J86*$B$9 -> 15832.839 | Q20: =K11*$E$9+K23*$F$9+K34*$C$9+K58*$D$9+K86*$B$9 -> 366.16008
H21: 运输 | I21: 龙须菜运输 | J21: 300 | K21: 65.478973 | P21: 1粒苗 | Q21: =SUM(Q2:Q20) -> 763.90957
I22: 幼苗运输 | J22: 7.0418771 | K22: 1.5370388 | M22: 1粒苗 | N22: 育苗设备用电 | O22: kwh | P22: =[2]皱纹盘鲍1tinput!W21 -> 0.021119647 | Q22: =[2]皱纹盘鲍1tinput!X21 -> 0.013495277
H23: 幼苗 | I23: 鲍鱼幼苗 | J23: 19555.338 | K23: 451.55159 | N23: 其他部分 | Q23: =[2]皱纹盘鲍1tinput!X22 -> 0.009595687
Q24: =SUM(Q22:Q23) -> 0.023090964
K26: 1183.015 | M26: 1粒苗 | N26: 基建 | Q26: 0.0048985818
N27: 其他部分 | Q27: 0.018192382
G28: SNCM-陆运
G29: 饲料 | H29: 龙须菜 | I29: t | J29: 20 | K29: 132.85667
G30: 运输 | H30: 陆运 | I30: tkm | J30: 605.25361 | K30: 132.10461
H31: 海运 | I31: tkm | J31: 0 | K31: 0
H32: 龙须菜运输 | I32: tkm | J32: 200 | K32: 43.652648
H33: 幼苗运输 | I33: tkm | J33: 0.31777424 | K33: 0.069691927
G34: 苗 | H34: 鲍鱼幼苗 | I34: item | J34: 12222.086 | K34: 282.21974
G35: 南方养殖（晋江市）
G36: 能源 | H36: 柴油 | I36: kg | J36: 0.36959588 | K36: 0.18271563
G37: 设备 | H37: 小型工作船（9m） | I37: item | J37: 0.00020370143 | K37: 1.0319291
G38: 基建 | H38: 聚乙烯绳 | I38: kg | J38: 0.10853212 | K38: 0.26045961
H39: 渔排浮板 | I39: kg | J39: 2.5917911 | K39: 6.179908
H40: 木桩 | I40: kg | J40: 0.00082926854 | K40: 0
H41: 浮球 | I41: kg | J41: 5.5967376 | K41: 13.343546
...

Sheet Case(Mode_Orl_NoGe)
B1: 工厂化 | C1: 南北 | E1: 本地 | I1: 1t | J1: FRCM-Raft | K1: 的皱纹盘鲍 | T1: input | U1: CF
C2: 陆运 | D2: 海运 | E2: 渔排（筏式） | F2: 延绳 | I2: 饲料 | J2: 龙须菜 | K2: 20 | L2: 132.85667 | N2: t | Q2: 饲料 | R2: 龙须菜 | S2: t | T2: 20 | U2: =L2 -> 132.85667
A3: 2020 | B3: 0.01 | C3: 0.165 | D3: 0.165 | E3: 0.54600548 | F3: 0.11399452 | I3: 设备 | J3: 小型工作船（9m） | K3: 0.0019791399 | L3: 10.043264 | N3: item | Q3: 设备 | R3: 小型工作船（9m） | S3: item | T3: =K3*E3+K15*F3 -> 0.0014566397 | U3: =L3*E9+L15*F9 -> 5.4878557
A4: 2021 | B4: 0.01 | C4: 0.165 | D4: 0.165 | E4: 0.54600548 | F4: 0.11399452 | I4: 能源 | J4: 柴油 | K4: 14.696895 | L4: 6.173809 | N4: kg | Q4: 能源 | R4: 柴油 | S4: kg | T4: =K4*E9+K16*F9+L35*C9+L41*C9+L56*D9+L62*D9 -> 16.145215 | U4: =L4*E9+L16*F9+M35*C9+M41*C9+M56*D9+M62*D9 -> 7.5373945
A5: 2022 | B5: 0.01 | C5: 0.165 | D5: 0.165 | E5: 0.54600548 | F5: 0.11399452 | I5: 基建 | J5: 彩钢活动板房 | K5: 1.3796188 | L5: 2.6997684 | N5: kg | R5: 电 | S5: kwh | T5: =M71*B3 -> 98.956994 | U5: =N71*B9 -> 63.232685
A6: 2023 | B6: 0.01 | C6: 0.165 | D6: 0.165 | E6: 0.54600548 | F6: 0.11399452 | J6: 养殖笼 | K6: 90.955568 | L6: 216.8759 | N6: kg | Q6: 基建 | R6: 彩钢活动板房 | S6: kg | T6: =K5*E3 -> 0.75327943 | U6: =L5*E9 -> 1.0943989
A7: 2024 | J7: 渔排浮板 | K7: 6.1880579 | L7: 14.754904 | N7: kg | R7: 养殖笼 | S7: kg | T7: =K6*E9+K19*F9+L38*C9+L44*C9+L59*D9+L65*D9+M74*B9 -> 139.73783 | U7: =T7/L38*M38 -> 333.19141
I8: 运输 | J8: 龙须菜运输 | K8: 300 | L8: 65.478973 | N8: tkm | R8: 渔排浮板 | S8: kg | T8: =K7*E9 -> 2.5084388 | U8: =L7*E9 -> 5.9811614
A9: 2050 | B9: 0.01 | C9: 0.25 | D9: 0.25 | E9: 0.4053677 | F9: 0.084632298 | J9: 幼苗运输 | K9: 14.253765 | L9: 3.1111861 | N9: tkm | R9: 尼龙6 | S9: kg | T9: =K18*F9+L37*C9+L43*C9+L58*D9+L64*D9 -> 2.705732 | U9: =L18*F9+M37*C9+M43*C9+M58*D9+M64*D9 -> 26.706815
I10: 其他 | J10: 鲍鱼幼苗 | K10: 39582.797 | L10: 914.00493 | N10: p（成活率50%） | R10: 泡沫浮球 | S10: kg | T10: =K20*F9+L39*C9+L45*C9+L60*D9+L66*D9 -> 33.145048 | U10: =L20*F9+M39*C9+M45*C9+M60*D9+M66*D9 -> 79.031165
L11: 1365.9994 | R11: 木桩 | S11: m3 | T11: =K17*F9+L36*C9+L42*C9+L57*D9+L63*D9 -> 0.035462053 | U11: 0
R12: 基建电力 | S12: kwh | T12: =M72*B9 -> 0.10994947 | U12: =N72*B9 -> 0.070256782
J13: FRCM-ll | K13: 的皱纹盘鲍 | R13: 塑料管道 | S13: kg | T13: =M73*B9 -> 0.079219724 | U13: =N73*B9 -> 0.81306554
I14: 1t | J14: 龙须菜 | K14: 20 | L14: 132.85667 | N14: t | R14: 混凝土 | S14: kg | T14: =M75*B9 -> 0.0030357433 | U14: =N75*B9 -> 0.86045946
I15: 饲料 | J15: 小型工作船（9m） | K15: 0.0032985664 | L15: 16.738773 | N15: item | Q15: 运输 | R15: 幼苗运输 | S15: tkm | T15: =K9*E9+K22*F9+L32*C9+L53*D9+M77*B9 -> 7.2966383 | U15: =L9*E9+L22*F9+M32*C9+M53*D9+N77*B9 -> 1.4629885
I16: 设备 | J16: 柴油 | K16: 22.316332 | L16: 11.028809 | N16: kg | R16: 龙须菜运输 | S16: tkm | T16: =K8*E9+K21*F9+L31*C9+L52*D9+M76*B9 -> 497.93662 | U16: =L8*E9+L21*F9+M31*C9+M52*D9+N76*B9 -> 77.133328
I17: 能源 | J17: 木桩 | K17: 0.07768124 | L17: 0 | N17: m3 | R17: 陆运 | S17: tkm | T17: =L29*C9 -> 268.92531 | U17: =M29*C9 -> 36.152145
I18: 基建 | J18: 尼龙6 | K18: 5.9270291 | L18: 58.502493 | N18: kg | R18: 海运 | S18: tkm | T18: =L51*D9 -> 231.98915 | U18: =M51*D9 -> 2.1803907
J19: 养殖笼 | K19: 217.70539 | L19: 519.09753 | N19: kg | Q19: 鲍鱼幼苗 | R19: 鲍鱼幼苗 | S19: item | T19: =K10*E9+K23*F9+C9*L33+D9*L54+M78*B9 -> 32047.929 | U19: =L10*E9+L23*F9+C9*M33+D9*M54+N78*B9 -> 743.38509
J20: 泡沫浮球 | K20: 72.605736 | L20: 173.12136 | N20: kg | U20: =SUM(U2:U19) -> 1517.1773
J21: 龙须菜运输 | K21: 2920 | L21: 392.5412 | N21: tkm | Q21: 1粒苗 | R21: 育苗用电 | S21: kwh | T21: 0.021119647 | U21: 0.013495277
I22: 运输 | J22: 幼苗运输 | K22: 3.7564075 | L22: 0.47736606 | N22: tkm | R22: 其他部分 | U22: 0.009595687
J23: 鲍鱼幼苗 | K23: 39582.797 | L23: 914.00493 | N23: p（成活率50%） | U23: =U21+U22 -> 0.023090964
I24: 其他 | Q24: 1粒苗 | R24: 基建 | U24: 0.0048985818
L25: 2218.3691 | R25: 其他部分 | U25: =U23-U24 -> 0.018192382
I27: SNCM-陆运 | L27: input | M27: CF
I28: 饲料 | J28: 龙须菜 | K28: t | L28: 20 | M28: 132.85667
I29: 运输 | J29: 陆运 | K29: tkm | L29: 1075.7012 | M29: 144.60858
J30: 海运 | K30: tkm | L30: 0 | M30: 0
J31: 龙须菜运输 | K31: tkm | L31: 200 | M31: 26.886384
J32: 幼苗运输 | K32: tkm | L32: 2.3477547 | M32: 0.31561316
I33: 苗 | J33: 鲍鱼幼苗 | K33: item | L33: 24739.248 | M33: 571.25308
I34: 南方养殖（晋江市）
I35: 能源 | J35: 柴油 | K35: kg | L35: 9.2984718 | M35: 4.595337
I36: 基建 | J36: 木桩 | K36: m3 | L36: 0.032367183 | M36: 0
J37: 尼龙6 | K37: kg | L37: 2.4695955 | M37: 24.376039
J38: 养殖笼 | K38: kg | L38: 90.710577 | M38: 216.29064
J39: 泡沫浮球 | K39: kg | L39: 30.25239 | M39: 72.133901
I40: 北方养殖（荣成市）
I41: 能源 | J41: 柴油 | K41: kg | L41: 7.2993003 | M41: 3.6073395
...

Sheet Case (Mode2050)
A1: 皱纹盘鲍mean | D1: input | E1: CF
A2: 饲料 | B2: 龙须菜 | C2: t | D2: ='Case(Mode_Orl_NoGe)'!T2 -> 20 | E2: ='Case(Mode_Orl_NoGe)'!U2 -> 132.85667
A3: 设备 | B3: 小型工作船（9m） | C3: item | D3: ='Case(Mode_Orl_NoGe)'!T3 -> 0.0014566397 | E3: ='Case(Mode_Orl_NoGe)'!U3 -> 5.4878557
A4: 能源 | B4: 柴油 | C4: kg | D4: ='Case(Mode_Orl_NoGe)'!T4 -> 16.145215 | E4: ='Case(Mode_Orl_NoGe)'!U4 -> 7.5373945
B5: 电 | C5: kwh | D5: ='Case(Mode_Orl_NoGe)'!T5 -> 98.956994 | E5: ='Case(Mode_Orl_NoGe)'!U5 -> 63.232685
A6: 基建 | B6: 彩钢活动板房 | C6: kg | D6: ='Case(Mode_Orl_NoGe)'!T6 -> 0.75327943 | E6: ='Case(Mode_Orl_NoGe)'!U6 -> 1.0943989
B7: 养殖笼 | C7: kg | D7: ='Case(Mode_Orl_NoGe)'!T7 -> 139.73783 | E7: ='Case(Mode_Orl_NoGe)'!U7 -> 333.19141
B8: 渔排浮板 | C8: kg | D8: ='Case(Mode_Orl_NoGe)'!T8 -> 2.5084388 | E8: ='Case(Mode_Orl_NoGe)'!U8 -> 5.9811614
B9: 尼龙6 | C9: kg | D9: ='Case(Mode_Orl_NoGe)'!T9 -> 2.705732 | E9: ='Case(Mode_Orl_NoGe)'!U9 -> 26.706815
B10: 泡沫浮球 | C10: kg | D10: ='Case(Mode_Orl_NoGe)'!T10 -> 33.145048 | E10: ='Case(Mode_Orl_NoGe)'!U10 -> 79.031165
B11: 木桩 | C11: m3 | D11: ='Case(Mode_Orl_NoGe)'!T11 -> 0.035462053 | E11: ='Case(Mode_Orl_NoGe)'!U11 -> 0
B12: 基建电力 | C12: kwh | D12: ='Case(Mode_Orl_NoGe)'!T12 -> 0.10994947 | E12: ='Case(Mode_Orl_NoGe)'!U12 -> 0.070256782
B13: 塑料管道 | C13: kg | D13: ='Case(Mode_Orl_NoGe)'!T13 -> 0.079219724 | E13: ='Case(Mode_Orl_NoGe)'!U13 -> 0.81306554
B14: 混凝土 | C14: kg | D14: ='Case(Mode_Orl_NoGe)'!T14 -> 0.0030357433 | E14: ='Case(Mode_Orl_NoGe)'!U14 -> 0.86045946
A15: 运输 | B15: 幼苗运输 | C15: tkm | D15: ='Case(Mode_Orl_NoGe)'!T15 -> 7.2966383 | E15: ='Case(Mode_Orl_NoGe)'!U15 -> 1.4629885
B16: 龙须菜运输 | C16: tkm | D16: ='Case(Mode_Orl_NoGe)'!T16 -> 497.93662 | E16: ='Case(Mode_Orl_NoGe)'!U16 -> 77.133328
B17: 陆运 | C17: tkm | D17: ='Case(Mode_Orl_NoGe)'!T17 -> 268.92531 | E17: ='Case(Mode_Orl_NoGe)'!U17 -> 36.152145
B18: 海运 | C18: tkm | D18: ='Case(Mode_Orl_NoGe)'!T18 -> 231.98915 | E18: ='Case(Mode_Orl_NoGe)'!U18 -> 2.1803907
A19: 鲍鱼幼苗 | B19: 鲍鱼幼苗 | C19: item | D19: ='Case(Mode_Orl_NoGe)'!T19 -> 32047.929 | E19: ='Case(Mode_Orl_NoGe)'!U19 -> 743.38509
E20: ='Case(Mode_Orl_NoGe)'!U20 -> 1517.1773
A21: 1粒苗 | B21: 育苗用电 | C21: kwh | D21: ='Case(Mode_Orl_NoGe)'!T21 -> 0.021119647 | E21: ='Case(Mode_Orl_NoGe)'!U21 -> 0.013495277
B22: 其他部分 | E22: ='Case(Mode_Orl_NoGe)'!U22 -> 0.009595687
E23: ='Case(Mode_Orl_NoGe)'!U23 -> 0.023090964
A24: 1粒苗 | B24: 基建 | E24: ='Case(Mode_Orl_NoGe)'!U24 -> 0.0048985818
B25: 其他部分 | E25: ='Case(Mode_Orl_NoGe)'!U25 -> 0.018192382
C26: input | D26: CF | E26: 占比
B27: 电力 | C27: =D5+D12+D19*D21 -> 775.9079 | D27: =E5+E12+E21*D19 -> 495.79861 | E27: =D27/E20 -> 0.32679016
B28: 其他 | D28: =E20-D27 -> 1021.3787
B29: 基建 | D29: =SUM(E6:E14)+D19*E24 -> 604.73813
B30: 其他 | D30: =E20-D29 -> 912.43915
A39: 绿盘鲍mean | D39: input | E39: CF
A40: 饲料 | B40: 龙须菜 | C40: t | D40: ='Case(Mode_Orl_Gene)'!P2 -> 20 | E40: ='Case(Mode_Orl_Gene)'!Q2 -> 132.85667
A41: 设备 | B41: 小型工作船（9m） | C41: item | D41: ='Case(Mode_Orl_Gene)'!P3 -> 0.00059459859 | E41: ='Case(Mode_Orl_Gene)'!Q3 -> 3.0167123
A42: 能源 | B42: 柴油 | C42: kg | D42: ='Case(Mode_Orl_Gene)'!P4 -> 3.5411241 | E42: ='Case(Mode_Orl_Gene)'!Q4 -> 1.5319003
B43: 电 | C43: kwh | D43: ='Case(Mode_Orl_Gene)'!P5 -> 48.888344 | E43: ='Case(Mode_Orl_Gene)'!Q5 -> 31.23924
A44: 基建 | B44: 彩钢活动板房 | C44: kg | D44: ='Case(Mode_Orl_Gene)'!P6 -> 0.27629122 | E44: ='Case(Mode_Orl_Gene)'!Q6 -> 0.54067277
B45: 养殖笼 | C45: kg | D45: ='Case(Mode_Orl_Gene)'!P7 -> 41.648421 | E45: ='Case(Mode_Orl_Gene)'!Q7 -> 99.308877
B46: 渔排浮板 | C46: kg | D46: ='Case(Mode_Orl_Gene)'!P8 -> 2.5351553 | E46: ='Case(Mode_Orl_Gene)'!Q8 -> 6.0448647
B47: 泡沫浮球 | C47: kg | D47: ='Case(Mode_Orl_Gene)'!P9 -> 8.5516714 | E47: ='Case(Mode_Orl_Gene)'!Q9 -> 20.389313
B48: 木桩 | C48: m3 | D48: ='Case(Mode_Orl_Gene)'!P10 -> 0.00041463427 | E48: ='Case(Mode_Orl_Gene)'!Q10 -> 0
...

Sheet Mode
B1: 皱纹盘鲍 | C1: 绿盘鲍 | K1: 1t鲍鱼碳足迹 | U1: max | X1: min
B2: mean | C2: mean | K2: mean | M2: 加温度 | N2: mean
A3: 2020 | B3: =E16 -> 1537.3871 | C3: =E17 -> 803.64328 | J3: 2020 | K3: =B3*$F27+C3*$G27 -> 1500.6999 | M3: 2020 | N3: =K3/Temperature!$G15 -> 1500.6999
A4: 2021 | B4: =B3+D$5 -> 1536.7135 | C4: =C3+E$5 -> 802.31882 | J4: 2021 | K4: =B4*$F28+C4*$G28 -> 1499.9937 | M4: 2021 | N4: =K4/Temperature!$G16 -> 1504.9349
A5: 2022 | B5: =B4+D$5 -> 1536.0398 | C5: =C4+E$5 -> 800.99437 | D5: =(B33-B3)/($A$33-$A$3) -> -0.67366154 | E5: =(C33-C3)/($A$33-$A$3) -> -1.3244569 | J5: 2022 | K5: =B5*$F29+C5*$G29 -> 1480.9114 | M5: 2022 | N5: =K5/Temperature!$G17 -> 1490.6253
A6: 2023 | B6: =B5+D$5 -> 1535.3661 | C6: =C5+E$5 -> 799.66991 | J6: 2023 | K6: =B6*$F30+C6*$G30 -> 1314.6573 | M6: 2023 | N6: =K6/Temperature!$G18 -> 1326.7305
A7: 2024 | B7: =B6+D$5 -> 1534.6925 | C7: =C6+E$5 -> 798.34545 | J7: 2024 | K7: =B7*$F$31+C7*$G$31 -> 1056.0669 | M7: 2024 | N7: =K7/Temperature!$G19 -> 1067.525
A8: 2025 | B8: =B7+D$5 -> 1534.0188 | C8: =C7+E$5 -> 797.02099 | J8: 2025 | K8: =B8*$F$31+C8*$G$31 -> 1054.9702 | M8: 2025 | N8: =K8/Temperature!$G20 -> 1069.3169
A9: 2026 | B9: =B8+D$5 -> 1533.3452 | C9: =C8+E$5 -> 795.69654 | J9: 2026 | K9: =B9*$F$31+C9*$G$31 -> 1053.8736 | M9: 2026 | N9: =K9/Temperature!$G21 -> 1071.1186
A10: 2027 | B10: =B9+D$5 -> 1532.6715 | C10: =C9+E$5 -> 794.37208 | J10: 2027 | K10: =B10*$F$31+C10*$G$31 -> 1052.7769 | M10: 2027 | N10: =K10/Temperature!$G22 -> 1072.9301
A11: 2028 | B11: =B10+D$5 -> 1531.9978 | C11: =C10+E$5 -> 793.04762 | J11: 2028 | K11: =B11*$F$31+C11*$G$31 -> 1051.6802 | M11: 2028 | N11: =K11/Temperature!$G23 -> 1074.7515
A12: 2029 | B12: =B11+D$5 -> 1531.3242 | C12: =C11+E$5 -> 791.72317 | J12: 2029 | K12: =B12*$F$31+C12*$G$31 -> 1050.5835 | M12: 2029 | N12: =K12/Temperature!$G24 -> 1076.583
A13: 2030 | B13: =B12+D$5 -> 1530.6505 | C13: =C12+E$5 -> 790.39871 | J13: 2030 | K13: =B13*$F$31+C13*$G$31 -> 1049.4868 | M13: 2030 | N13: =K13/Temperature!$G25 -> 1078.4246
A14: 2031 | B14: =B13+D$5 -> 1529.9768 | C14: =C13+E$5 -> 789.07425 | J14: 2031 | K14: =B14*$F$31+C14*$G$31 -> 1048.3902 | M14: 2031 | N14: =K14/Temperature!$G26 -> 1080.2763
A15: 2032 | B15: =B14+D$5 -> 1529.3032 | C15: =C14+E$5 -> 787.7498 | D15: 原始 | E15: mean | J15: 2032 | K15: =B15*$F$31+C15*$G$31 -> 1047.2935 | M15: 2032 | N15: =K15/Temperature!$G27 -> 1082.1383
A16: 2033 | B16: =B15+D$5 -> 1528.6295 | C16: =C15+E$5 -> 786.42534 | D16: 皱纹盘鲍 | E16: 1537.3871 | J16: 2033 | K16: =B16*$F$31+C16*$G$31 -> 1046.1968 | M16: 2033 | N16: =K16/Temperature!$G28 -> 1084.0107
A17: 2034 | B17: =B16+D$5 -> 1527.9559 | C17: =C16+E$5 -> 785.10088 | D17: 绿盘鲍 | E17: 803.64328 | J17: 2034 | K17: =B17*$F$31+C17*$G$31 -> 1045.1001 | M17: 2034 | N17: =K17/Temperature!$G29 -> 1085.8935
A18: 2035 | B18: =B17+D$5 -> 1527.2822 | C18: =C17+E$5 -> 783.77643 | J18: 2035 | K18: =B18*$F$31+C18*$G$31 -> 1044.0034 | M18: 2035 | N18: =K18/Temperature!$G30 -> 1087.7869
A19: 2036 | B19: =B18+D$5 -> 1526.6085 | C19: =C18+E$5 -> 782.45197 | J19: 2036 | K19: =B19*$F$31+C19*$G$31 -> 1042.9068 | M19: 2036 | N19: =K19/Temperature!$G31 -> 1089.6908
A20: 2037 | B20: =B19+D$5 -> 1525.9349 | C20: =C19+E$5 -> 781.12751 | D20: 未来 | E20: mean | J20: 2037 | K20: =B20*$F$31+C20*$G$31 -> 1041.8101 | M20: 2037 | N20: =K20/Temperature!$G32 -> 1091.6055
A21: 2038 | B21: =B20+D$5 -> 1525.2612 | C21: =C20+E$5 -> 779.80306 | D21: 皱纹盘鲍 | E21: ='Case (Mode2050)'!E20 -> 1517.1773 | J21: 2038 | K21: =B21*$F$31+C21*$G$31 -> 1040.7134 | M21: 2038 | N21: =K21/Temperature!$G33 -> 1093.531
A22: 2039 | B22: =B21+D$5 -> 1524.5876 | C22: =C21+E$5 -> 778.4786 | D22: 绿盘鲍 | E22: ='Case (Mode2050)'!E59 -> 763.90957 | J22: 2039 | K22: =B22*$F$31+C22*$G$31 -> 1039.6167 | M22: 2039 | N22: =K22/Temperature!$G34 -> 1095.4673
A23: 2040 | B23: =B22+D$5 -> 1523.9139 | C23: =C22+E$5 -> 777.15414 | J23: 2040 | K23: =B23*$F$31+C23*$G$31 -> 1038.5201 | M23: 2040 | N23: =K23/Temperature!$G35 -> 1097.4146
A24: 2041 | B24: =B23+D$5 -> 1523.2402 | C24: =C23+E$5 -> 775.82968 | J24: 2041 | K24: =B24*$F$31+C24*$G$31 -> 1037.4234 | M24: 2041 | N24: =K24/Temperature!$G36 -> 1099.373
A25: 2042 | B25: =B24+D$5 -> 1522.5666 | C25: =C24+E$5 -> 774.50523 | E25: 市场售卖鲍鱼品种比例 | J25: 2042 | K25: =B25*$F$31+C25*$G$31 -> 1036.3267 | M25: 2042 | N25: =K25/Temperature!$G37 -> 1101.3426
A26: 2043 | B26: =B25+D$5 -> 1521.8929 | C26: =C25+E$5 -> 773.18077 | E26: 数据时间 | F26: 皱纹盘鲍 | G26: 绿盘鲍 | J26: 2043 | K26: =B26*$F$31+C26*$G$31 -> 1035.23 | M26: 2043 | N26: =K26/Temperature!$G38 -> 1103.3235
A27: 2044 | B27: =B26+D$5 -> 1521.2192 | C27: =C26+E$5 -> 771.85631 | E27: 2020 | F27: 0.95 | G27: 0.05 | J27: 2044 | K27: =B27*$F$31+C27*$G$31 -> 1034.1333 | M27: 2044 | N27: =K27/Temperature!$G39 -> 1105.3157
A28: 2045 | B28: =B27+D$5 -> 1520.5456 | C28: =C27+E$5 -> 770.53186 | E28: 2021 | F28: 0.95 | G28: 0.05 | J28: 2045 | K28: =B28*$F$31+C28*$G$31 -> 1033.0367 | M28: 2045 | N28: =K28/Temperature!$G40 -> 1107.3193
A29: 2046 | B29: =B28+D$5 -> 1519.8719 | C29: =C28+E$5 -> 769.2074 | E29: 2022 | F29: 0.925 | G29: 0.075 | J29: 2046 | K29: =B29*$F$31+C29*$G$31 -> 1031.94 | M29: 2046 | N29: =K29/Temperature!$G41 -> 1109.3346
A30: 2047 | B30: =B29+D$5 -> 1519.1983 | C30: =C29+E$5 -> 767.88294 | E30: 2023 | F30: 0.7 | G30: 0.3 | J30: 2047 | K30: =B30*$F$31+C30*$G$31 -> 1030.8433 | M30: 2047 | N30: =K30/Temperature!$G42 -> 1111.3614
A31: 2048 | B31: =B30+D$5 -> 1518.5246 | C31: =C30+E$5 -> 766.55849 | E31: 2024 | F31: 0.35 | G31: 0.65 | J31: 2048 | K31: =B31*$F$31+C31*$G$31 -> 1029.7466 | M31: 2048 | N31: =K31/Temperature!$G43 -> 1113.4001
A32: 2049 | B32: =B31+D$5 -> 1517.8509 | C32: =C31+E$5 -> 765.23403 | J32: 2049 | K32: =B32*$F$31+C32*$G$31 -> 1028.6499 | M32: 2049 | N32: =K32/Temperature!$G44 -> 1115.4506
A33: 2050 | B33: =E21 -> 1517.1773 | C33: =E22 -> 763.90957 | J33: 2050 | K33: =B33*$F$31+C33*$G$31 -> 1027.5533 | M33: 2050 | N33: =K33/Temperature!$G45 -> 1117.5131

Sheet Speed
K1: 加温度
F2: mean | G2: max | H2: min | K2: mean | L2: max | M2: min
A3: 2020 | B3: 1 | C3: =(B13-B3)/(A13-A3) -> 0.02 | E3: 2020 | F3: =Baseline!D3/Speed!$B3 -> 1500.6999 | G3: =Baseline!E3/Speed!$B3 -> 2137.0304 | H3: =Baseline!F3/Speed!$B3 -> 1182.9525 | J3: 2020 | K3: =Speed!F3/Temperature!$G15 -> 1500.6999 | L3: =Speed!G3/Temperature!$G15 -> 2137.0304 | M3: =Speed!H3/Temperature!$G15 -> 1182.9525
A4: 2021 | B4: =B3+$C$3 -> 1.02 | E4: 2021 | F4: =Baseline!D4/Speed!$B4 -> 1471.2744 | G4: =Baseline!E4/Speed!$B4 -> 2095.1278 | H4: =Baseline!F4/Speed!$B4 -> 1159.7573 | J4: 2021 | K4: =Speed!F4/Temperature!$G16 -> 1476.121 | L4: =Speed!G4/Temperature!$G16 -> 2102.0295 | M4: =Speed!H4/Temperature!$G16 -> 1163.5778
A5: 2022 | B5: =B4+$C$3 -> 1.04 | E5: 2022 | F5: =Baseline!D5/Speed!$B5 -> 1425.3426 | G5: =Baseline!E5/Speed!$B5 -> 2024.4502 | H5: =Baseline!F5/Speed!$B5 -> 1125.5175 | J5: 2022 | K5: =Speed!F5/Temperature!$G17 -> 1434.692 | L5: =Speed!G5/Temperature!$G17 -> 2037.7294 | M5: =Speed!H5/Temperature!$G17 -> 1132.9003
A6: 2023 | B6: =B5+$C$3 -> 1.06 | E6: 2023 | F6: =Baseline!D6/Speed!$B6 -> 1242.7019 | G6: =Baseline!E6/Speed!$B6 -> 1717.9322 | H6: =Baseline!F6/Speed!$B6 -> 998.87742 | J6: 2023 | K6: =Speed!F6/Temperature!$G18 -> 1254.1143 | L6: =Speed!G6/Temperature!$G18 -> 1733.709 | M6: =Speed!H6/Temperature!$G18 -> 1008.0507
A7: 2024 | B7: =B6+$C$3 -> 1.08 | E7: 2024 | F7: =Baseline!D7/Speed!$B7 -> 981.9015 | G7: =Baseline!E7/Speed!$B7 -> 1276.4603 | H7: =Baseline!F7/Speed!$B7 -> 819.45432 | J7: 2024 | K7: =Speed!F7/Temperature!$G19 -> 992.55493 | L7: =Speed!G7/Temperature!$G19 -> 1290.3096 | M7: =Speed!H7/Temperature!$G19 -> 828.34522
A8: 2025 | B8: =B7+$C$3 -> 1.1 | E8: 2025 | F8: =Baseline!D8/Speed!$B8 -> 964.04875 | G8: =Baseline!E8/Speed!$B8 -> 1253.2519 | H8: =Baseline!F8/Speed!$B8 -> 804.55515 | J8: 2025 | K8: =Speed!F8/Temperature!$G20 -> 977.15897 | L8: =Speed!G8/Temperature!$G20 -> 1270.295 | M8: =Speed!H8/Temperature!$G20 -> 815.49639
A9: 2026 | B9: =B8+$C$3 -> 1.12 | E9: 2026 | F9: =Baseline!D9/Speed!$B9 -> 946.83359 | G9: =Baseline!E9/Speed!$B9 -> 1230.8724 | H9: =Baseline!F9/Speed!$B9 -> 790.18809 | J9: 2026 | K9: =Speed!F9/Temperature!$G21 -> 962.32706 | L9: =Speed!G9/Temperature!$G21 -> 1251.0137 | M9: =Speed!H9/Temperature!$G21 -> 803.1183
A10: 2027 | B10: =B9+$C$3 -> 1.14 | E10: 2027 | F10: =Baseline!D10/Speed!$B10 -> 930.22248 | G10: =Baseline!E10/Speed!$B10 -> 1209.2782 | H10: =Baseline!F10/Speed!$B10 -> 776.32514 | J10: 2027 | K10: =Speed!F10/Temperature!$G22 -> 948.02963 | L10: =Speed!G10/Temperature!$G22 -> 1232.4273 | M10: =Speed!H10/Temperature!$G22 -> 791.18626
A11: 2028 | B11: =B10+$C$3 -> 1.16 | E11: 2028 | F11: =Baseline!D11/Speed!$B11 -> 914.18416 | G11: =Baseline!E11/Speed!$B11 -> 1188.4285 | H11: =Baseline!F11/Speed!$B11 -> 762.94023 | J11: 2028 | K11: =Speed!F11/Temperature!$G23 -> 934.23916 | L11: =Speed!G11/Temperature!$G23 -> 1214.4998 | M11: =Speed!H11/Temperature!$G23 -> 779.6773
A12: 2029 | B12: =B11+$C$3 -> 1.18 | E12: 2029 | F12: =Baseline!D12/Speed!$B12 -> 898.68951 | G12: =Baseline!E12/Speed!$B12 -> 1168.2857 | H12: =Baseline!F12/Speed!$B12 -> 750.00904 | J12: 2029 | K12: =Speed!F12/Temperature!$G24 -> 920.92997 | L12: =Speed!G12/Temperature!$G24 -> 1197.198 | M12: =Speed!H12/Temperature!$G24 -> 768.57
A13: 2030 | B13: 1.2 | E13: 2030 | F13: =Baseline!D13/Speed!$B13 -> 883.71135 | G13: =Baseline!E13/Speed!$B13 -> 1148.8143 | H13: =Baseline!F13/Speed!$B13 -> 737.50889 | J13: 2030 | K13: =Speed!F13/Temperature!$G25 -> 908.07812 | L13: =Speed!G13/Temperature!$G25 -> 1180.4908 | M13: =Speed!H13/Temperature!$G25 -> 757.84438
A14: 2031 | B14: =B13+$C$3 -> 1.22 | E14: 2031 | F14: =Baseline!D14/Speed!$B14 -> 869.22428 | G14: =Baseline!E14/Speed!$B14 -> 1129.9812 | H14: =Baseline!F14/Speed!$B14 -> 725.41858 | J14: 2031 | K14: =Speed!F14/Temperature!$G26 -> 895.66122 | L14: =Speed!G14/Temperature!$G26 -> 1164.3489 | M14: =Speed!H14/Temperature!$G26 -> 747.48175
A15: 2032 | B15: =B14+$C$3 -> 1.24 | E15: 2032 | F15: =Baseline!D15/Speed!$B15 -> 855.20454 | G15: =Baseline!E15/Speed!$B15 -> 1111.7557 | H15: =Baseline!F15/Speed!$B15 -> 713.71828 | J15: 2032 | K15: =Speed!F15/Temperature!$G27 -> 883.65833 | L15: =Speed!G15/Temperature!$G27 -> 1148.7453 | M15: =Speed!H15/Temperature!$G27 -> 737.46464
A16: 2033 | B16: =B15+$C$3 -> 1.26 | E16: 2033 | F16: =Baseline!D16/Speed!$B16 -> 841.62986 | G16: =Baseline!E16/Speed!$B16 -> 1094.1088 | H16: =Baseline!F16/Speed!$B16 -> 702.38942 | J16: 2033 | K16: =Speed!F16/Temperature!$G28 -> 872.04987 | L16: =Speed!G16/Temperature!$G28 -> 1133.6545 | M16: =Speed!H16/Temperature!$G28 -> 727.77669
A17: 2034 | B17: =B16+$C$3 -> 1.28 | E17: 2034 | F17: =Baseline!D17/Speed!$B17 -> 828.47939 | G17: =Baseline!E17/Speed!$B17 -> 1077.0134 | H17: =Baseline!F17/Speed!$B17 -> 691.41458 | J17: 2034 | K17: =Speed!F17/Temperature!$G29 -> 860.81744 | L17: =Speed!G17/Temperature!$G29 -> 1119.0524 | M17: =Speed!H17/Temperature!$G29 -> 718.40257
A18: 2035 | B18: =B17+$C$3 -> 1.3 | E18: 2035 | F18: =Baseline!D18/Speed!$B18 -> 815.73356 | G18: =Baseline!E18/Speed!$B18 -> 1060.4439 | H18: =Baseline!F18/Speed!$B18 -> 680.77743 | J18: 2035 | K18: =Speed!F18/Temperature!$G30 -> 849.94379 | L18: =Speed!G18/Temperature!$G30 -> 1104.9168 | M18: =Speed!H18/Temperature!$G30 -> 709.32788
A19: 2036 | B19: =B18+$C$3 -> 1.32 | E19: 2036 | F19: =Baseline!D19/Speed!$B19 -> 803.37396 | G19: =Baseline!E19/Speed!$B19 -> 1044.3766 | H19: =Baseline!F19/Speed!$B19 -> 670.46262 | J19: 2036 | K19: =Speed!F19/Temperature!$G31 -> 839.41274 | L19: =Speed!G19/Temperature!$G31 -> 1091.2266 | M19: =Speed!H19/Temperature!$G31 -> 700.5391
A20: 2037 | B20: =B19+$C$3 -> 1.34 | E20: 2037 | F20: =Baseline!D20/Speed!$B20 -> 791.3833 | G20: =Baseline!E20/Speed!$B20 -> 1028.7889 | H20: =Baseline!F20/Speed!$B20 -> 660.45572 | J20: 2037 | K20: =Speed!F20/Temperature!$G32 -> 829.20905 | L20: =Speed!G20/Temperature!$G32 -> 1077.9619 | M20: =Speed!H20/Temperature!$G32 -> 692.02353
A21: 2038 | B21: =B20+$C$3 -> 1.36 | E21: 2038 | F21: =Baseline!D21/Speed!$B21 -> 779.74531 | G21: =Baseline!E21/Speed!$B21 -> 1013.6596 | H21: =Baseline!F21/Speed!$B21 -> 650.74314 | J21: 2038 | K21: =Speed!F21/Temperature!$G33 -> 819.31839 | L21: =Speed!G21/Temperature!$G33 -> 1065.1042 | M21: =Speed!H21/Temperature!$G33 -> 683.76919
A22: 2039 | B22: =B21+$C$3 -> 1.38 | E22: 2039 | F22: =Baseline!D22/Speed!$B22 -> 768.44466 | G22: =Baseline!E22/Speed!$B22 -> 998.96892 | H22: =Baseline!F22/Speed!$B22 -> 641.31208 | J22: 2039 | K22: =Speed!F22/Temperature!$G34 -> 809.72725 | L22: =Speed!G22/Temperature!$G34 -> 1052.6358 | M22: =Speed!H22/Temperature!$G34 -> 675.76482
A23: 2040 | B23: =B22+$C$3 -> 1.4 | E23: 2040 | F23: =Baseline!D23/Speed!$B23 -> 757.46687 | G23: =Baseline!E23/Speed!$B23 -> 984.69794 | H23: =Baseline!F23/Speed!$B23 -> 632.15047 | J23: 2040 | K23: =Speed!F23/Temperature!$G35 -> 800.4229 | L23: =Speed!G23/Temperature!$G35 -> 1040.5403 | M23: =Speed!H23/Temperature!$G35 -> 667.9998
A24: 2041 | B24: =B23+$C$3 -> 1.42 | E24: 2041 | F24: =Baseline!D24/Speed!$B24 -> 746.79833 | G24: =Baseline!E24/Speed!$B24 -> 970.82895 | H24: =Baseline!F24/Speed!$B24 -> 623.24695 | J24: 2041 | K24: =Speed!F24/Temperature!$G36 -> 791.39334 | L24: =Speed!G24/Temperature!$G36 -> 1028.8019 | M24: =Speed!H24/Temperature!$G36 -> 660.4641
