Workbook

Sheet Production
A1: year | B1: China | C1: South Korea | D1: South Africa | E1: 10000 t
A2: 2000 | B2: 0.2458 | C2: 0.002 | D2: 0.0181
A3: 2001 | B3: 0.2496 | C3: 0.0029 | D3: 0.0373
A4: 2002 | B4: 0.2325 | C4: 0.0085 | D4: 0.0429
A5: 2003 | B5: 1.1206 | C5: 0.1065 | D5: 0.0515
A6: 2004 | B6: 1.5446 | C6: 0.126 | D6: 0.076
A7: 2005 | B7: 1.7674 | C7: 0.2062 | D7: 0.083
A8: 2006 | B8: 2.1637 | C8: 0.305 | D8: 0.0833
A9: 2007 | B9: 2.5374 | C9: 0.435 | D9: 0.0783
A10: 2008 | B10: 3.301 | C10: 0.5146 | D10: 0.1037
A11: 2009 | B11: 4.2373 | C11: 0.6207 | D11: 0.0914
A12: 2010 | B12: 5.6511 | C12: 0.6228 | D12: 0.1015
A13: 2011 | B13: 7.6786 | C13: 0.6779 | D13: 0.1036
... A24: 2022 | B24: 22.819 | C24: 2.20783 | D24: 0.22547

Sheet Unit carbon footprint
A1: year | B1: China | C1: Korea | D1: South Africa | E1: kg/t
A2: 2000 | B2: =M38 -> 7681.8423 | C2: =$C$42 -> 204.25488 | D2: =$C$41 -> 42278.498
A3: 2001 | B3: =M39 -> 7681.8423 | C3: =$C$42 -> 204.25488 | D3: =$C$41 -> 42278.498 | K3: =(K26-K11)/(J26-J11) -> -0.066 | L3: =(L26-L20)/(J26-J20) -> 0.0275 | M3: =L3 -> 0.0275 | N3: =(N26+N11)/(J26-J11) -> 0.036400365 | O3: =(O26-O11)/(J26-J11) -> 0.0075996349
A4: 2002 | B4: =M40 -> 7681.8423 | C4: =$C$42 -> 204.25488 | D4: =$C$41 -> 42278.498
A5: 2003 | B5: =M41 -> 7681.8423 | C5: =$C$42 -> 204.25488 | D5: =$C$41 -> 42278.498 | K5: Int | L5: Ext-3 | M5: Ext-4 | N5: Ext-1 | O5: Ext-2
A6: 2004 | B6: =M42 -> 7681.8423 | C6: =$C$42 -> 204.25488 | D6: =$C$41 -> 42278.498 | J6: 2000 | K6: 1 | L6: 0 | M6: 0 | N6: 0 | O6: 0
A7: 2005 | B7: =M43 -> 7681.8423 | C7: =$C$42 -> 204.25488 | D7: =$C$41 -> 42278.498 | J7: 2001 | K7: 1 | L7: 0 | M7: 0 | N7: 0 | O7: 0
A8: 2006 | B8: =M44 -> 7190.3061 | C8: =$C$42 -> 204.25488 | D8: =$C$41 -> 42278.498 | J8: 2002 | K8: 1 | L8: 0 | M8: 0 | N8: 0 | O8: 0
A9: 2007 | B9: =M45 -> 6698.77 | C9: =$C$42 -> 204.25488 | D9: =$C$41 -> 42278.498 | J9: 2003 | K9: 1 | L9: 0 | M9: 0 | N9: 0 | O9: 0
A10: 2008 | B10: =M46 -> 6207.2339 | C10: =$C$42 -> 204.25488 | D10: =$C$41 -> 42278.498 | J10: 2004 | K10: 1 | L10: 0 | M10: 0 | N10: 0 | O10: 0
A11: 2009 | B11: =M47 -> 5715.6978 | C11: =$C$42 -> 204.25488 | D11: =$C$41 -> 42278.498 | J11: 2005 | K11: 1 | L11: 0 | M11: 0 | N11: 0 | O11: 0
A12: 2010 | B12: =M48 -> 5224.1617 | C12: =$C$42 -> 204.25488 | D12: =$C$41 -> 42278.498 | J12: 2006 | K12: =K11+$K$3 -> 0.934 | L12: 0 | M12: 0 | N12: =N11+$N$3 -> 0.036400365 | O12: =O11+$O$3 -> 0.0075996349
A13: 2011 | B13: =M49 -> 4732.6256 | C13: =$C$42 -> 204.25488 | D13: =$C$41 -> 42278.498 | J13: 2007 | K13: =K12+$K$3 -> 0.868 | L13: 0 | M13: 0 | N13: =N12+$N$3 -> 0.07280073 | O13: =O12+$O$3 -> 0.01519927
A14: 2012 | B14: =M50 -> 4241.0895 | C14: =$C$42 -> 204.25488 | D14: =$C$41 -> 42278.498 | J14: 2008 | K14: =K13+$K$3 -> 0.802 | L14: 0 | M14: 0 | N14: =N13+$N$3 -> 0.1092011 | O14: =O13+$O$3 -> 0.022798905
A15: 2013 | B15: =M51 -> 3749.5533 | C15: =$C$42 -> 204.25488 | D15: =$C$41 -> 42278.498 | J15: 2009 | K15: =K14+$K$3 -> 0.736 | L15: 0 | M15: 0 | N15: =N14+$N$3 -> 0.14560146 | O15: =O14+$O$3 -> 0.03039854
A16: 2014 | B16: =M52 -> 3258.0172 | C16: =$C$42 -> 204.25488 | D16: =$C$41 -> 42278.498 | J16: 2010 | K16: =K15+$K$3 -> 0.67 | L16: 0 | M16: 0 | N16: =N15+$N$3 -> 0.18200183 | O16: =O15+$O$3 -> 0.037998174
A17: 2015 | B17: =M53 -> 2778.1849 | C17: =$C$42 -> 204.25488 | D17: =$C$41 -> 42278.498 | J17: 2011 | K17: =K16+$K$3 -> 0.604 | L17: 0 | M17: 0 | N17: =N16+$N$3 -> 0.21840219 | O17: =O16+$O$3 -> 0.045597809
A18: 2016 | B18: =M54 -> 2298.3526 | C18: =$C$42 -> 204.25488 | D18: =$C$41 -> 42278.498 | J18: 2012 | K18: =K17+$K$3 -> 0.538 | L18: 0 | M18: 0 | N18: =N17+$N$3 -> 0.25480256 | O18: =O17+$O$3 -> 0.053197444
A19: 2017 | B19: =M55 -> 1818.5203 | C19: =$C$42 -> 204.25488 | D19: =$C$41 -> 42278.498 | J19: 2013 | K19: =K18+$K$3 -> 0.472 | L19: 0 | M19: 0 | N19: =N18+$N$3 -> 0.29120292 | O19: =O18+$O$3 -> 0.060797079
A20: 2018 | B20: =M56 -> 1338.688 | C20: =$C$42 -> 204.25488 | D20: =$C$41 -> 42278.498 | J20: 2014 | K20: =K19+$K$3 -> 0.406 | L20: 0 | M20: 0 | N20: =N19+$N$3 -> 0.32760329 | O20: =O19+$O$3 -> 0.068396714
A21: 2019 | B21: =M57 -> 858.85575 | C21: =$C$42 -> 204.25488 | D21: =$C$41 -> 42278.498 | J21: 2015 | K21: =K20+$K$3 -> 0.34 | L21: =L20+$L$3 -> 0.0275 | M21: =M20+$L$3 -> 0.0275 | N21: =N20+$N$3 -> 0.36400365 | O21: =O20+$O$3 -> 0.075996349
A22: 2020 | B22: =M58 -> 342.19609 | C22: =$C$42 -> 204.25488 | D22: =$C$41 -> 42278.498 | J22: 2016 | K22: =K21+$K$3 -> 0.274 | L22: =L21+$L$3 -> 0.055 | M22: =M21+$L$3 -> 0.055 | N22: =N21+$N$3 -> 0.40040402 | O22: =O21+$O$3 -> 0.083595984
A23: 2021 | B23: =M59 -> 342.19609 | C23: =$C$42 -> 204.25488 | D23: =$C$41 -> 42278.498 | J23: 2017 | K23: =K22+$K$3 -> 0.208 | L23: =L22+$L$3 -> 0.0825 | M23: =M22+$L$3 -> 0.0825 | N23: =N22+$N$3 -> 0.43680438 | O23: =O22+$O$3 -> 0.091195619
A24: 2022 | B24: =M60 -> 323.7824 | C24: =$C$42 -> 204.25488 | D24: =$C$41 -> 42278.498 | J24: 2018 | K24: =K23+$K$3 -> 0.142 | L24: =L23+$L$3 -> 0.11 | M24: =M23+$L$3 -> 0.11 | N24: =N23+$N$3 -> 0.47320475 | O24: =O23+$O$3 -> 0.098795254
J25: 2019 | K25: =K24+$K$3 -> 0.076 | L25: =L24+$L$3 -> 0.1375 | M25: =M24+$L$3 -> 0.1375 | N25: =N24+$N$3 -> 0.50960511 | O25: =O24+$O$3 -> 0.10639489
J26: 2020 | K26: 0.01 | L26: 0.165 | M26: 0.165 | N26: 0.54600548 | O26: 0.11399452
J27: 2021 | K27: 0.01 | L27: 0.165 | M27: 0.165 | N27: 0.54600548 | O27: 0.11399452
J28: 2022 | K28: 0.01 | L28: 0.165 | M28: 0.165 | N28: 0.54600548 | O28: 0.11399452
K30: No genetic improvement | L30: Genetic improvement
B31: Int | C31: Ext-1 | D31: Ext-2 | E31: Ext-3 | F31: Ext-4 | G31: Int (South Africa) | H31: Ext-1 (South Korea) | J31: Before 2020 | K31: 1 | L31: 0
B32: 7681.8423 | C32: 204.26762 | D32: 1056.6373 | E32: 280.74025 | F32: 144.85323 | G32: 42278.498 | H32: 204.25488 | J32: 2020 | K32: 0.95 | L32: 0.05
J33: 2021 | K33: 0.95 | L33: 0.05
J34: 2022 | K34: 0.925 | L34: 0.075
B35: No genetic improvement
B36: Int | C36: 7681.8423
B37: Ext-1 | C37: 204.26762 | K37: No genetic improvement | L37: Genetic improvement | M37: both
B38: Ext-2 | C38: 1056.6373 | J38: 2000 | K38: =B$32*K6+C$32*N6+D$32*O6+E$32*L6+F$32*M6 -> 7681.8423 | L38: 0 | M38: =K38 -> 7681.8423
B39: Ext-3 | C39: 280.74025 | J39: 2001 | K39: =B$32*K7+C$32*N7+D$32*O7+E$32*L7+F$32*M7 -> 7681.8423 | L39: 0 | M39: =K39 -> 7681.8423
B40: Ext-4 | C40: 144.85323 | J40: 2002 | K40: =B$32*K8+C$32*N8+D$32*O8+E$32*L8+F$32*M8 -> 7681.8423 | L40: 0 | M40: =K40 -> 7681.8423
B41: Int (South Africa) | C41: 42278.498 | J41: 2003 | K41: =B$32*K9+C$32*N9+D$32*O9+E$32*L9+F$32*M9 -> 7681.8423 | L41: 0 | M41: =K41 -> 7681.8423
...

Sheet Carbon Footprint
A1: year | B1: China | C1: Korea | D1: South Africa | E1: 100 kt CO2 eq.
A2: 2000 | B2: =Production!B2*'Unit carbon footprint'!B2/10000 -> 0.18881968 | C2: =Production!C2*'Unit carbon footprint'!C2/10000 -> 4.0850976e-05 | D2: =Production!D2*'Unit carbon footprint'!D2/10000 -> 0.076524082
A3: 2001 | B3: =Production!B3*'Unit carbon footprint'!B3/10000 -> 0.19173878 | C3: =Production!C3*'Unit carbon footprint'!C3/10000 -> 5.9233916e-05 | D3: =Production!D3*'Unit carbon footprint'!D3/10000 -> 0.1576988
A4: 2002 | B4: =Production!B4*'Unit carbon footprint'!B4/10000 -> 0.17860283 | C4: =Production!C4*'Unit carbon footprint'!C4/10000 -> 0.00017361665 | D4: =Production!D4*'Unit carbon footprint'!D4/10000 -> 0.18137476
A5: 2003 | B5: =Production!B5*'Unit carbon footprint'!B5/10000 -> 0.86082724 | C5: =Production!C5*'Unit carbon footprint'!C5/10000 -> 0.0021753145 | D5: =Production!D5*'Unit carbon footprint'!D5/10000 -> 0.21773427
A6: 2004 | B6: =Production!B6*'Unit carbon footprint'!B6/10000 -> 1.1865374 | C6: =Production!C6*'Unit carbon footprint'!C6/10000 -> 0.0025736115 | D6: =Production!D6*'Unit carbon footprint'!D6/10000 -> 0.32131659
A7: 2005 | B7: =Production!B7*'Unit carbon footprint'!B7/10000 -> 1.3576888 | C7: =Production!C7*'Unit carbon footprint'!C7/10000 -> 0.0042117357 | D7: =Production!D7*'Unit carbon footprint'!D7/10000 -> 0.35091154
A8: 2006 | B8: =Production!B8*'Unit carbon footprint'!B8/10000 -> 1.5557665 | C8: =Production!C8*'Unit carbon footprint'!C8/10000 -> 0.0062297739 | D8: =Production!D8*'Unit carbon footprint'!D8/10000 -> 0.35217989
A9: 2007 | B9: =Production!B9*'Unit carbon footprint'!B9/10000 -> 1.6997459 | C9: =Production!C9*'Unit carbon footprint'!C9/10000 -> 0.0088850874 | D9: =Production!D9*'Unit carbon footprint'!D9/10000 -> 0.33104064
A10: 2008 | B10: =Production!B10*'Unit carbon footprint'!B10/10000 -> 2.0490079 | C10: =Production!C10*'Unit carbon footprint'!C10/10000 -> 0.010510956 | D10: =Production!D10*'Unit carbon footprint'!D10/10000 -> 0.43842803
A11: 2009 | B11: =Production!B11*'Unit carbon footprint'!B11/10000 -> 2.4219126 | C11: =Production!C11*'Unit carbon footprint'!C11/10000 -> 0.012678101 | D11: =Production!D11*'Unit carbon footprint'!D11/10000 -> 0.38642547
A12: 2010 | B12: =Production!B12*'Unit carbon footprint'!B12/10000 -> 2.952226 | C12: =Production!C12*'Unit carbon footprint'!C12/10000 -> 0.012720994 | D12: =Production!D12*'Unit carbon footprint'!D12/10000 -> 0.42912676
A13: 2011 | B13: =Production!B13*'Unit carbon footprint'!B13/10000 -> 3.6339939 | C13: =Production!C13*'Unit carbon footprint'!C13/10000 -> 0.013846438 | D13: =Production!D13*'Unit carbon footprint'!D13/10000 -> 0.43800524
... A24: 2022 | B24: =Production!B24*'Unit carbon footprint'!B24/10000 -> 0.73883907 | C24: =Production!C24*'Unit carbon footprint'!C24/10000 -> 0.045096006 | D24: =Production!D24*'Unit carbon footprint'!D24/10000 -> 0.9532533
